Workbook

Sheet CLIENTE
A1: FACTOR DE RIESGO CLIENTES
A3: SUB FACTOR | C3: VARIABLE | E3: INDICADOR | F3: PROBABILIDAD | H3: IMPACTO | J3: RIESGO INHERENTE | L3: PESO | M3: MITIGANTES IMPLEMENTADOS | N3: NIVEL DE EFICACIA | P3: RIESGO RESIDUAL | R3: PESO
A4: 1. Persona Natural | B4: 0.7 | C4: 1.1 Edad | D4: 0.1 | E4: ≥ 18 ≤ 25 años | F4: =LOOKUP(G4,RANGOS!$A$2:$B$6) -> Muy alta | G4: 5 | H4: =LOOKUP(I4,RANGOS!$A$9:$B$13) -> Bajo | I4: ='Data cliente'!G6 -> 2 | J4: =LOOKUP(K4,RANGOS!$F$2:$G$26) -> MEDIO | K4: =G4*I4 -> 10 | L4: =$B$4*$D$4*AVERAGE(K4:K7) -> 0.7 | M4: KYC - Formato de conocimiento del cliente | N4: =LOOKUP(O4,RANGOS!$A$16:$B$20) -> Medio | O4: 3 | P4: =LOOKUP(Q4,RANGOS!$F$2:$G$26) -> BAJO | Q4: =K4/$O$4 -> 3.3333333 | R4: =$B$4*$D$4*AVERAGE(Q4:Q7) -> 0.23333333
E5: > 25 ≤ 40 años | F5: =LOOKUP(G5,RANGOS!$A$2:$B$6) -> Alta | G5: 4 | H5: =LOOKUP(I5,RANGOS!$A$9:$B$13) -> Medio | I5: ='Data cliente'!G7 -> 3 | J5: =LOOKUP(K5,RANGOS!$F$2:$G$26) -> ALTO | K5: =G5*I5 -> 12 | P5: =LOOKUP(Q5,RANGOS!$F$2:$G$26) -> BAJO | Q5: =K5/$O$4 -> 4
E6: > 40 ≤ 65 años | F6: =LOOKUP(G6,RANGOS!$A$2:$B$6) -> Alta | G6: 4 | H6: =LOOKUP(I6,RANGOS!$A$9:$B$13) -> Medio | I6: ='Data cliente'!G8 -> 3 | J6: =LOOKUP(K6,RANGOS!$F$2:$G$26) -> ALTO | K6: =G6*I6 -> 12 | P6: =LOOKUP(Q6,RANGOS!$F$2:$G$26) -> BAJO | Q6: =K6/$O$4 -> 4
E7: > 65 años | F7: =LOOKUP(G7,RANGOS!$A$2:$B$6) -> Baja | G7: 2 | H7: =LOOKUP(I7,RANGOS!$A$9:$B$13) -> Medio | I7: ='Data cliente'!G9 -> 3 | J7: =LOOKUP(K7,RANGOS!$F$2:$G$26) -> MEDIO | K7: =G7*I7 -> 6 | P7: =LOOKUP(Q7,RANGOS!$F$2:$G$26) -> BAJO | Q7: =K7/$O$4 -> 2
C8: 1.2 Tipo de D.O.I. | D8: 0.05 | E8: DNI | F8: =LOOKUP(G8,RANGOS!$A$2:$B$6) -> Media | G8: 3 | H8: =LOOKUP(I8,RANGOS!$A$9:$B$13) -> Alto | I8: ='Data cliente'!G10 -> 4 | J8: =LOOKUP(K8,RANGOS!$F$2:$G$26) -> ALTO | K8: =G8*I8 -> 12 | L8: =$B$4*$D$8*AVERAGE(K8:K10) -> 0.32666667 | M8: KYC - Formato de conocimiento del cliente | N8: =LOOKUP(O8,RANGOS!$A$16:$B$20) -> Muy alto | O8: 5 | P8: =LOOKUP(Q8,RANGOS!$F$2:$G$26) -> BAJO | Q8: =K8/$O$8 -> 2.4 | R8: =$B$4*$D$8*AVERAGE(Q8:Q10) -> 0.065333333
E9: Carnet de extranjería | F9: =LOOKUP(G9,RANGOS!$A$2:$B$6) -> Media | G9: 3 | H9: =LOOKUP(I9,RANGOS!$A$9:$B$13) -> Bajo | I9: ='Data cliente'!G11 -> 2 | J9: =LOOKUP(K9,RANGOS!$F$2:$G$26) -> MEDIO | K9: =G9*I9 -> 6 | P9: =LOOKUP(Q9,RANGOS!$F$2:$G$26) -> MUY BAJO | Q9: =K9/$O$8 -> 1.2
E10: Pasaporte | F10: =LOOKUP(G10,RANGOS!$A$2:$B$6) -> Muy alta | G10: 5 | H10: =LOOKUP(I10,RANGOS!$A$9:$B$13) -> Bajo | I10: ='Data cliente'!G12 -> 2 | J10: =LOOKUP(K10,RANGOS!$F$2:$G$26) -> MEDIO | K10: =G10*I10 -> 10 | P10: =LOOKUP(Q10,RANGOS!$F$2:$G$26) -> BAJO | Q10: =K10/$O$8 -> 2
C11: 1.3 Antigüedad | D11: 0.15 | E11: ≤ 1 año | F11: =LOOKUP(G11,RANGOS!$A$2:$B$6) -> Muy alta | G11: 5 | H11: =LOOKUP(I11,RANGOS!$A$9:$B$13) -> Bajo | I11: ='Data cliente'!G13 -> 2 | J11: =LOOKUP(K11,RANGOS!$F$2:$G$26) -> MEDIO | K11: =G11*I11 -> 10 | L11: =$B$4*$D$11*AVERAGE(K11:K14) -> 0.86625 | M11: KYC - Formato de conocimiento del cliente | N11: =LOOKUP(O11,RANGOS!$A$16:$B$20) -> Muy alto | O11: 5 | P11: =LOOKUP(Q11,RANGOS!$F$2:$G$26) -> BAJO | Q11: =K11/$O$11 -> 2 | R11: =$B$4*$D$11*AVERAGE(Q11:Q14) -> 0.17325
E12: > 1 ≤ 5 años | F12: =LOOKUP(G12,RANGOS!$A$2:$B$6) -> Alta | G12: 4 | H12: =LOOKUP(I12,RANGOS!$A$9:$B$13) -> Bajo | I12: ='Data cliente'!G14 -> 2 | J12: =LOOKUP(K12,RANGOS!$F$2:$G$26) -> MEDIO | K12: =G12*I12 -> 8 | P12: =LOOKUP(Q12,RANGOS!$F$2:$G$26) -> MUY BAJO | Q12: =K12/$O$11 -> 1.6
E13: > 5 ≤ 10 años | F13: =LOOKUP(G13,RANGOS!$A$2:$B$6) -> Media | G13: 3 | H13: =LOOKUP(I13,RANGOS!$A$9:$B$13) -> Medio | I13: ='Data cliente'!G15 -> 3 | J13: =LOOKUP(K13,RANGOS!$F$2:$G$26) -> MEDIO | K13: =G13*I13 -> 9 | P13: =LOOKUP(Q13,RANGOS!$F$2:$G$26) -> MUY BAJO | Q13: =K13/$O$11 -> 1.8
E14: > 10 años | F14: =LOOKUP(G14,RANGOS!$A$2:$B$6) -> Baja | G14: 2 | H14: =LOOKUP(I14,RANGOS!$A$9:$B$13) -> Medio | I14: ='Data cliente'!G16 -> 3 | J14: =LOOKUP(K14,RANGOS!$F$2:$G$26) -> MEDIO | K14: =G14*I14 -> 6 | P14: =LOOKUP(Q14,RANGOS!$F$2:$G$26) -> MUY BAJO | Q14: =K14/$O$11 -> 1.2
C15: 1.4 Actividad | D15: 0.15 | E15: Dependiente | F15: =LOOKUP(G15,RANGOS!$A$2:$B$6) -> Baja | G15: 2 | H15: =LOOKUP(I15,RANGOS!$A$9:$B$13) -> Bajo | I15: ='Data cliente'!G17 -> 2 | J15: =LOOKUP(K15,RANGOS!$F$2:$G$26) -> BAJO | K15: =G15*I15 -> 4 | L15: =$B$4*$D$8*AVERAGE(K15:K18) -> 0.35 | N15: =LOOKUP(O15,RANGOS!$A$16:$B$20) -> Alto | O15: 4 | P15: =LOOKUP(Q15,RANGOS!$F$2:$G$26) -> MUY BAJO | Q15: =K15/$O$15 -> 1 | R15: =$B$4*$D$15*AVERAGE(Q15:Q18) -> 0.2625
E16: Independiente formal | F16: =LOOKUP(G16,RANGOS!$A$2:$B$6) -> Media | G16: 3 | H16: =LOOKUP(I16,RANGOS!$A$9:$B$13) -> Medio | I16: ='Data cliente'!G18 -> 3 | J16: =LOOKUP(K16,RANGOS!$F$2:$G$26) -> MEDIO | K16: =G16*I16 -> 9 | P16: =LOOKUP(Q16,RANGOS!$F$2:$G$26) -> BAJO | Q16: =K16/$O$15 -> 2.25
E17: Independiente informal | F17: =LOOKUP(G17,RANGOS!$A$2:$B$6) -> Alta | G17: 4 | H17: =LOOKUP(I17,RANGOS!$A$9:$B$13) -> Medio | I17: ='Data cliente'!G19 -> 3 | J17: =LOOKUP(K17,RANGOS!$F$2:$G$26) -> ALTO | K17: =G17*I17 -> 12 | P17: =LOOKUP(Q17,RANGOS!$F$2:$G$26) -> BAJO | Q17: =K17/$O$15 -> 3
E18: Desconocida | F18: =LOOKUP(G18,RANGOS!$A$2:$B$6) -> Muy alta | G18: 5 | H18: =LOOKUP(I18,RANGOS!$A$9:$B$13) -> Medio | I18: ='Data cliente'!G20 -> 3 | J18: =LOOKUP(K18,RANGOS!$F$2:$G$26) -> ALTO | K18: =G18*I18 -> 15 | P18: =LOOKUP(Q18,RANGOS!$F$2:$G$26) -> BAJO | Q18: =K18/$O$15 -> 3.75
C19: 1.5 Condición SUNAT | D19: 0.05 | E19: Activo | F19: =LOOKUP(G19,RANGOS!$A$2:$B$6) -> Baja | G19: 2 | H19: =LOOKUP(I19,RANGOS!$A$9:$B$13) -> Alto | I19: ='Data cliente'!G21 -> 4 | J19: =LOOKUP(K19,RANGOS!$F$2:$G$26) -> MEDIO | K19: =G19*I19 -> 8 | L19: =$B$4*$D$19*AVERAGE(K19:K22) -> 0.28 | M19: Bantotal | N19: =LOOKUP(O19,RANGOS!$A$16:$B$20) -> Muy bajo | O19: 1 | P19: =LOOKUP(Q19,RANGOS!$F$2:$G$26) -> MEDIO | Q19: =K19/$O$19 -> 8 | R19: =$B$4*$D$19*AVERAGE(Q19:Q22) -> 0.28
E20: Suspensión temporal | F20: =LOOKUP(G20,RANGOS!$A$2:$B$6) -> Media | G20: 3 | H20: =LOOKUP(I20,RANGOS!$A$9:$B$13) -> Bajo | I20: ='Data cliente'!G22 -> 2 | J20: =LOOKUP(K20,RANGOS!$F$2:$G$26) -> MEDIO | K20: =G20*I20 -> 6 | P20: =LOOKUP(Q20,RANGOS!$F$2:$G$26) -> MEDIO | Q20: =K20/$O$19 -> 6
E21: Baja de oficio | F21: =LOOKUP(G21,RANGOS!$A$2:$B$6) -> Alta | G21: 4 | H21: =LOOKUP(I21,RANGOS!$A$9:$B$13) -> Bajo | I21: ='Data cliente'!G23 -> 2 | J21: =LOOKUP(K21,RANGOS!$F$2:$G$26) -> MEDIO | K21: =G21*I21 -> 8 | P21: =LOOKUP(Q21,RANGOS!$F$2:$G$26) -> MEDIO | Q21: =K21/$O$19 -> 8
E22: Desconocido | F22: =LOOKUP(G22,RANGOS!$A$2:$B$6) -> Muy alta | G22: 5 | H22: =LOOKUP(I22,RANGOS!$A$9:$B$13) -> Bajo | I22: ='Data cliente'!G24 -> 2 | J22: =LOOKUP(K22,RANGOS!$F$2:$G$26) -> MEDIO | K22: =G22*I22 -> 10 | P22: =LOOKUP(Q22,RANGOS!$F$2:$G$26) -> MEDIO | Q22: =K22/$O$19 -> 10
C23: 1.6 Cliente Sensible | D23: 0.15 | E23: Extranjero no residente | F23: =LOOKUP(G23,RANGOS!$A$2:$B$6) -> Alta | G23: 4 | H23: =LOOKUP(I23,RANGOS!$A$9:$B$13) -> Bajo | I23: ='Data cliente'!G25 -> 2 | J23: =LOOKUP(K23,RANGOS!$F$2:$G$26) -> MEDIO | K23: =G23*I23 -> 8 | L23: =$B$4*$D$23*AVERAGE(K23:K25) -> 1.225 | M23: Manual de Políticas de LA/FT, Check de PEP en Bantotal, KYC Especial para PEP y Verificación de Listas ONU, GAFI, etc. | N23: =LOOKUP(O23,RANGOS!$A$16:$B$20) -> Muy alto | O23: 5 | P23: =LOOKUP(Q23,RANGOS!$F$2:$G$26) -> MUY BAJO | Q23: =K23/$O$23 -> 1.6 | R23: =$B$4*$D$23*AVERAGE(Q23:Q25) -> 0.245
E24: PEP | F24: =LOOKUP(G24,RANGOS!$A$2:$B$6) -> Muy alta | G24: 5 | H24: =LOOKUP(I24,RANGOS!$A$9:$B$13) -> Medio | I24: ='Data cliente'!G26 -> 3 | J24: =LOOKUP(K24,RANGOS!$F$2:$G$26) -> ALTO | K24: =G24*I24 -> 15 | P24: =LOOKUP(Q24,RANGOS!$F$2:$G$26) -> BAJO | Q24: =K24/$O$23 -> 3
E25: Usuario | F25: =LOOKUP(G25,RANGOS!$A$2:$B$6) -> Media | G25: 3 | H25: =LOOKUP(I25,RANGOS!$A$9:$B$13) -> Alto | I25: ='Data cliente'!G27 -> 4 | J25: =LOOKUP(K25,RANGOS!$F$2:$G$26) -> ALTO | K25: =G25*I25 -> 12 | P25: =LOOKUP(Q25,RANGOS!$F$2:$G$26) -> BAJO | Q25: =K25/$O$23 -> 2.4
C26: 1.7 Tipo de producto | D26: 0.15 | E26: Pasivo | F26: =LOOKUP(G26,RANGOS!$A$2:$B$6) -> Muy alta | G26: 5 | H26: =LOOKUP(I26,RANGOS!$A$9:$B$13) -> Alto | I26: ='Data cliente'!G28 -> 4 | J26: =LOOKUP(K26,RANGOS!$F$2:$G$26) -> ALTO | K26: =G26*I26 -> 20 | L26: =$B$4*$D$26*AVERAGE(K26:K28) -> 1.12 | M26: Los Informes de Riesgo Operacional que realizan de acuerdo a la norma de la SBS | N26: =LOOKUP(O26,RANGOS!$A$16:$B$20) -> Muy alto | O26: 5 | P26: =LOOKUP(Q26,RANGOS!$F$2:$G$26) -> BAJO | Q26: =K26/$O$26 -> 4 | R26: =$B$4*$D$26*AVERAGE(Q26:Q28) -> 0.224
E27: Colocaciones | F27: =LOOKUP(G27,RANGOS!$A$2:$B$6) -> Media | G27: 3 | H27: =LOOKUP(I27,RANGOS!$A$9:$B$13) -> Medio | I27: ='Data cliente'!G29 -> 3 | J27: =LOOKUP(K27,RANGOS!$F$2:$G$26) -> MEDIO | K27: =G27*I27 -> 9 | P27: =LOOKUP(Q27,RANGOS!$F$2:$G$26) -> MUY BAJO | Q27: =K27/$O$26 -> 1.8
E28: Servicios | F28: =LOOKUP(G28,RANGOS!$A$2:$B$6) -> Media | G28: 3 | H28: =LOOKUP(I28,RANGOS!$A$9:$B$13) -> Muy bajo | I28: ='Data cliente'!G30 -> 1 | J28: =LOOKUP(K28,RANGOS!$F$2:$G$26) -> BAJO | K28: =G28*I28 -> 3 | P28: =LOOKUP(Q28,RANGOS!$F$2:$G$26) -> MUY BAJO | Q28: =K28/$O$26 -> 0.6
C29: 1.8 Moneda del Producto | D29: 0.05 | E29: Nuevos Soles | F29: =LOOKUP(G29,RANGOS!$A$2:$B$6) -> Alta | G29: 4 | H29: =LOOKUP(I29,RANGOS!$A$9:$B$13) -> Alto | I29: ='Data cliente'!G31 -> 4 | J29: =LOOKUP(K29,RANGOS!$F$2:$G$26) -> ALTO | K29: =G29*I29 -> 16 | L29: =$B$4*$D$29*AVERAGE(K29:K31) -> 0.385 | M29: Bantotal | N29: =LOOKUP(O29,RANGOS!$A$16:$B$20) -> Muy alto | O29: 5 | P29: =LOOKUP(Q29,RANGOS!$F$2:$G$26) -> BAJO | Q29: =K29/$O$29 -> 3.2 | R29: =$B$4*$D$29*AVERAGE(Q29:Q31) -> 0.077
E30: Euros | F30: =LOOKUP(G30,RANGOS!$A$2:$B$6) -> Muy alta | G30: 5 | H30: =LOOKUP(I30,RANGOS!$A$9:$B$13) -> Muy bajo | I30: ='Data cliente'!G32 -> 1 | J30: =LOOKUP(K30,RANGOS!$F$2:$G$26) -> BAJO | K30: =G30*I30 -> 5 | P30: =LOOKUP(Q30,RANGOS!$F$2:$G$26) -> MUY BAJO | Q30: =K30/$O$29 -> 1
E31: Dólares | F31: =LOOKUP(G31,RANGOS!$A$2:$B$6) -> Alta | G31: 4 | H31: =LOOKUP(I31,RANGOS!$A$9:$B$13) -> Medio | I31: ='Data cliente'!G33 -> 3 | J31: =LOOKUP(K31,RANGOS!$F$2:$G$26) -> ALTO | K31: =G31*I31 -> 12 | P31: =LOOKUP(Q31,RANGOS!$F$2:$G$26) -> BAJO | Q31: =K31/$O$29 -> 2.4
C32: 1.9 Lugar de vinculación | D32: 0.15 | E32: Lima | F32: =LOOKUP(G32,RANGOS!$A$2:$B$6) -> Alta | G32: 4 | H32: =LOOKUP(I32,RANGOS!$A$9:$B$13) -> Medio | I32: ='Data cliente'!G34 -> 3 | J32: =LOOKUP(K32,RANGOS!$F$2:$G$26) -> ALTO | K32: =G32*I32 -> 12 | L32: =$B$4*$D$32*AVERAGE(K32:K36) -> 1.05 | M32: KYC - Formato de conocimiento del cliente | N32: =LOOKUP(O32,RANGOS!$A$16:$B$20) -> Muy bajo | O32: 1 | P32: =LOOKUP(Q32,RANGOS!$F$2:$G$26) -> ALTO | Q32: =K32/$O$32 -> 12 | R32: =$B$4*$D$32*AVERAGE(Q32:Q36) -> 1.05
E33: Piura | F33: =LOOKUP(G33,RANGOS!$A$2:$B$6) -> Muy alta | G33: 5 | H33: =LOOKUP(I33,RANGOS!$A$9:$B$13) -> Bajo | I33: ='Data cliente'!G35 -> 2 | J33: =LOOKUP(K33,RANGOS!$F$2:$G$26) -> MEDIO | K33: =G33*I33 -> 10 | P33: =LOOKUP(Q33,RANGOS!$F$2:$G$26) -> MEDIO | Q33: =K33/$O$32 -> 10 | V33: =15*6 -> 90
E34: Chiclayo | F34: =LOOKUP(G34,RANGOS!$A$2:$B$6) -> Muy alta | G34: 5 | H34: =LOOKUP(I34,RANGOS!$A$9:$B$13) -> Bajo | I34: ='Data cliente'!G36 -> 2 | J34: =LOOKUP(K34,RANGOS!$F$2:$G$26) -> MEDIO | K34: =G34*I34 -> 10 | P34: =LOOKUP(Q34,RANGOS!$F$2:$G$26) -> MEDIO | Q34: =K34/$O$32 -> 10
E35: Trujillo | F35: =LOOKUP(G35,RANGOS!$A$2:$B$6) -> Muy alta | G35: 5 | H35: =LOOKUP(I35,RANGOS!$A$9:$B$13) -> Bajo | I35: ='Data cliente'!G37 -> 2 | J35: =LOOKUP(K35,RANGOS!$F$2:$G$26) -> MEDIO | K35: =G35*I35 -> 10 | P35: =LOOKUP(Q35,RANGOS!$F$2:$G$26) -> MEDIO | Q35: =K35/$O$32 -> 10
E36: Arequipa | F36: =LOOKUP(G36,RANGOS!$A$2:$B$6) -> Alta | G36: 4 | H36: =LOOKUP(I36,RANGOS!$A$9:$B$13) -> Bajo | I36: ='Data cliente'!G39 -> 2 | J36: =LOOKUP(K36,RANGOS!$F$2:$G$26) -> MEDIO | K36: =G36*I36 -> 8 | P36: =LOOKUP(Q36,RANGOS!$F$2:$G$26) -> MEDIO | Q36: =K36/$O$32 -> 8
A37: 2. Persona Jurídica | B37: 0.3 | C37: 2.1 Tiempo de constitución de la empresa | D37: 0.2 | E37: ≤ 5 años | F37: =LOOKUP(G37,RANGOS!$A$2:$B$6) -> Muy baja | G37: 1 | H37: =LOOKUP(I37,RANGOS!$A$9:$B$13) -> Muy bajo | I37: 1 | J37: =LOOKUP(K37,RANGOS!$F$2:$G$26) -> MUY BAJO | K37: =G37*I37 -> 1 | L37: =$B$37*$D$37*AVERAGE(K37:K38) -> 0.06 | N37: =LOOKUP(O37,RANGOS!$A$16:$B$20) -> Muy bajo | O37: 1 | P37: =LOOKUP(Q37,RANGOS!$F$2:$G$26) -> MUY BAJO | Q37: =K37/$O$37 -> 1 | R37: =$B$37*$D$37*AVERAGE(Q37:Q38) -> 0.06
E38: > 5 ≤ 10 años | F38: =LOOKUP(G38,RANGOS!$A$2:$B$6) -> Muy baja | G38: 1 | H38: =LOOKUP(I38,RANGOS!$A$9:$B$13) -> Muy bajo | I38: 1 | J38: =LOOKUP(K38,RANGOS!$F$2:$G$26) -> MUY BAJO | K38: =G38*I38 -> 1 | P38: =LOOKUP(Q38,RANGOS!$F$2:$G$26) -> MUY BAJO | Q38: =K38/$O$37 -> 1
C39: 2.2 Antigüedad como cliente | D39: 0.2 | E39: ≤ de 1 año | F39: =LOOKUP(G39,RANGOS!$A$2:$B$6) -> Muy baja | G39: 1 | H39: =LOOKUP(I39,RANGOS!$A$9:$B$13) -> Muy bajo | I39: 1 | J39: =LOOKUP(K39,RANGOS!$F$2:$G$26) -> MUY BAJO | K39: =G39*I39 -> 1 | L39: =$B$37*$D$39*AVERAGE(K39:K40) -> 0.06 | P39: =LOOKUP(Q39,RANGOS!$F$2:$G$26) -> MUY BAJO | Q39: =K39/$O$37 -> 1 | R39: =$B$37*$D$39*AVERAGE(Q39:Q40) -> 0.06
E40: > 1 ≤ 5 años | F40: =LOOKUP(G40,RANGOS!$A$2:$B$6) -> Muy baja | G40: 1 | H40: =LOOKUP(I40,RANGOS!$A$9:$B$13) -> Muy bajo | I40: 1 | J40: =LOOKUP(K40,RANGOS!$F$2:$G$26) -> MUY BAJO | K40: =G40*I40 -> 1 | P40: =LOOKUP(Q40,RANGOS!$F$2:$G$26) -> MUY BAJO | Q40: =K40/$O$37 -> 1
C41: 2.3 Tipo de cliente | D41: 0.2 | E41: Minero | F41: =LOOKUP(G41,RANGOS!$A$2:$B$6) -> Muy baja | G41: 1 | H41: =LOOKUP(I41,RANGOS!$A$9:$B$13) -> Muy bajo | I41: 1 | J41: =LOOKUP(K41,RANGOS!$F$2:$G$26) -> MUY BAJO | K41: =G41*I41 -> 1 | L41: =$B$37*$D$41*AVERAGE(K41:K42) -> 0.06 | P41: =LOOKUP(Q41,RANGOS!$F$2:$G$26) -> MUY BAJO | Q41: =K41/$O$37 -> 1 | R41: =$B$37*$D$41*AVERAGE(Q41:Q42) -> 0.06
...

Sheet Data cliente
A1: ANÁLISIS DEL IMPACTO: CLIENTES
A3: Periodo de análisis: De julio del 2014 a junio del 2015
A5: SUB FACTOR | B5: VARIABLE | C5: INDICADOR | D5: Registro | E5: Porcentaje | F5: IMPACTO
A6: 1. Persona Natural | B6: 1.1 Edad | C6: ≥ 18 ≤ 25 años | D6: 80 | E6: =D6/SUM($D$6:$D$9) -> 0.08 | F6: =LOOKUP(G6,RANGOS!$A$9:$B$13) -> Bajo | G6: =LOOKUP(E6,RANGOS!$I$2:$J$101) -> 2
C7: > 25 ≤ 40 años | D7: 270 | E7: =D7/SUM($D$6:$D$9) -> 0.27 | F7: =LOOKUP(G7,RANGOS!$A$9:$B$13) -> Medio | G7: =LOOKUP(E7,RANGOS!$I$2:$J$101) -> 3
C8: > 40 ≤ 65 años | D8: 400 | E8: =D8/SUM($D$6:$D$9) -> 0.4 | F8: =LOOKUP(G8,RANGOS!$A$9:$B$13) -> Medio | G8: =LOOKUP(E8,RANGOS!$I$2:$J$101) -> 3
C9: > 65 años | D9: 250 | E9: =D9/SUM($D$6:$D$9) -> 0.25 | F9: =LOOKUP(G9,RANGOS!$A$9:$B$13) -> Medio | G9: =LOOKUP(E9,RANGOS!$I$2:$J$101) -> 3
B10: 1.2 Tipo de D.O.I. | C10: DNI | D10: 650 | E10: =D10/SUM($D$10:$D$12) -> 0.65 | F10: =LOOKUP(G10,RANGOS!$A$9:$B$13) -> Alto | G10: =LOOKUP(E10,RANGOS!$I$2:$J$101) -> 4
C11: Carnet de extranjería | D11: 150 | E11: =D11/SUM($D$10:$D$12) -> 0.15 | F11: =LOOKUP(G11,RANGOS!$A$9:$B$13) -> Bajo | G11: =LOOKUP(E11,RANGOS!$I$2:$J$101) -> 2
C12: Pasaporte | D12: 200 | E12: =D12/SUM($D$10:$D$12) -> 0.2 | F12: =LOOKUP(G12,RANGOS!$A$9:$B$13) -> Bajo | G12: =LOOKUP(E12,RANGOS!$I$2:$J$101) -> 2
B13: 1.3 Antigüedad | C13: ≤ 1 año | D13: 150 | E13: =D13/SUM($D$13:$D$16) -> 0.15 | F13: =LOOKUP(G13,RANGOS!$A$9:$B$13) -> Bajo | G13: =LOOKUP(E13,RANGOS!$I$2:$J$101) -> 2
C14: > 1 ≤ 5 años | D14: 200 | E14: =D14/SUM($D$13:$D$16) -> 0.2 | F14: =LOOKUP(G14,RANGOS!$A$9:$B$13) -> Bajo | G14: =LOOKUP(E14,RANGOS!$I$2:$J$101) -> 2
C15: > 5 ≤ 10 años | D15: 400 | E15: =D15/SUM($D$13:$D$16) -> 0.4 | F15: =LOOKUP(G15,RANGOS!$A$9:$B$13) -> Medio | G15: =LOOKUP(E15,RANGOS!$I$2:$J$101) -> 3
C16: > 5 ≤ 10 años | D16: 250 | E16: =D16/SUM($D$13:$D$16) -> 0.25 | F16: =LOOKUP(G16,RANGOS!$A$9:$B$13) -> Medio | G16: =LOOKUP(E16,RANGOS!$I$2:$J$101) -> 3
B17: 1.4 Actividad | C17: Dependiente | D17: 250 | E17: =D17/SUM($D$17:$D$20) -> 0.20833333 | F17: =LOOKUP(G17,RANGOS!$A$9:$B$13) -> Bajo | G17: =LOOKUP(E17,RANGOS!$I$2:$J$101) -> 2
C18: Independiente formal | D18: 350 | E18: =D18/SUM($D$17:$D$20) -> 0.29166667 | F18: =LOOKUP(G18,RANGOS!$A$9:$B$13) -> Medio | G18: =LOOKUP(E18,RANGOS!$I$2:$J$101) -> 3
C19: Independiente informal | D19: 300 | E19: =D19/SUM($D$17:$D$20) -> 0.25 | F19: =LOOKUP(G19,RANGOS!$A$9:$B$13) -> Medio | G19: =LOOKUP(E19,RANGOS!$I$2:$J$101) -> 3
C20: Desconocida | D20: 300 | E20: =D20/SUM($D$17:$D$20) -> 0.25 | F20: =LOOKUP(G20,RANGOS!$A$9:$B$13) -> Medio | G20: =LOOKUP(E20,RANGOS!$I$2:$J$101) -> 3
B21: 1.5 Condición SUNAT | C21: Activo | D21: 600 | E21: =D21/SUM($D$21:$D$24) -> 0.6 | F21: =LOOKUP(G21,RANGOS!$A$9:$B$13) -> Alto | G21: =LOOKUP(E21,RANGOS!$I$2:$J$101) -> 4
C22: Suspensión temporal | D22: 100 | E22: =D22/SUM($D$21:$D$24) -> 0.1 | F22: =LOOKUP(G22,RANGOS!$A$9:$B$13) -> Bajo | G22: =LOOKUP(E22,RANGOS!$I$2:$J$101) -> 2
C23: Baja de oficio | D23: 100 | E23: =D23/SUM($D$21:$D$24) -> 0.1 | F23: =LOOKUP(G23,RANGOS!$A$9:$B$13) -> Bajo | G23: =LOOKUP(E23,RANGOS!$I$2:$J$101) -> 2
C24: Desconocido | D24: 200 | E24: =D24/SUM($D$21:$D$24) -> 0.2 | F24: =LOOKUP(G24,RANGOS!$A$9:$B$13) -> Bajo | G24: =LOOKUP(E24,RANGOS!$I$2:$J$101) -> 2
B25: 1.6 Cliente Sensible | C25: Extranjero no residente | D25: 100 | E25: =D25/SUM($D$25:$D$27) -> 0.1 | F25: =LOOKUP(G25,RANGOS!$A$9:$B$13) -> Bajo | G25: =LOOKUP(E25,RANGOS!$I$2:$J$101) -> 2
C26: PEP | D26: 300 | E26: =D26/SUM($D$25:$D$27) -> 0.3 | F26: =LOOKUP(G26,RANGOS!$A$9:$B$13) -> Medio | G26: =LOOKUP(E26,RANGOS!$I$2:$J$101) -> 3
C27: Usuario | D27: 600 | E27: =D27/SUM($D$25:$D$27) -> 0.6 | F27: =LOOKUP(G27,RANGOS!$A$9:$B$13) -> Alto | G27: =LOOKUP(E27,RANGOS!$I$2:$J$101) -> 4
B28: 1.7 Tipo de cuenta | C28: Pasivo | D28: 550 | E28: =D28/SUM($D$28:$D$30) -> 0.55 | F28: =LOOKUP(G28,RANGOS!$A$9:$B$13) -> Alto | G28: =LOOKUP(E28,RANGOS!$I$2:$J$101) -> 4
C29: Colocaciones | D29: 400 | E29: =D29/SUM($D$28:$D$30) -> 0.4 | F29: =LOOKUP(G29,RANGOS!$A$9:$B$13) -> Medio | G29: =LOOKUP(E29,RANGOS!$I$2:$J$101) -> 3
C30: Servicios | D30: 50 | E30: =D30/SUM($D$28:$D$30) -> 0.05 | F30: =LOOKUP(G30,RANGOS!$A$9:$B$13) -> Muy bajo | G30: =LOOKUP(E30,RANGOS!$I$2:$J$101) -> 1
B31: 1.8 Moneda del producto | C31: Nuevos Soles | D31: 700 | E31: =D31/SUM($D$31:$D$33) -> 0.7 | F31: =LOOKUP(G31,RANGOS!$A$9:$B$13) -> Alto | G31: =LOOKUP(E31,RANGOS!$I$2:$J$101) -> 4
C32: Euros | D32: 5 | E32: =D32/SUM($D$31:$D$33) -> 0.005 | F32: =LOOKUP(G32,RANGOS!$A$9:$B$13) -> Muy bajo | G32: =LOOKUP(E32,RANGOS!$I$2:$J$101) -> 1
C33: Dólares | D33: 295 | E33: =D33/SUM($D$31:$D$33) -> 0.295 | F33: =LOOKUP(G33,RANGOS!$A$9:$B$13) -> Medio | G33: =LOOKUP(E33,RANGOS!$I$2:$J$101) -> 3
B34: 1.9 Lugar de vinculación | C34: Piura | D34: 450 | E34: =D34/SUM($D$34:$D$39) -> 0.37656904 | F34: =LOOKUP(G34,RANGOS!$A$9:$B$13) -> Medio | G34: =LOOKUP(E34,RANGOS!$I$2:$J$101) -> 3
C35: Trujillo | D35: 160 | E35: =D35/SUM($D$34:$D$39) -> 0.13389121 | F35: =LOOKUP(G35,RANGOS!$A$9:$B$13) -> Bajo | G35: =LOOKUP(E35,RANGOS!$I$2:$J$101) -> 2
C36: Chiclayo | D36: 90 | E36: =D36/SUM($D$34:$D$39) -> 0.075313808 | F36: =LOOKUP(G36,RANGOS!$A$9:$B$13) -> Bajo | G36: =LOOKUP(E36,RANGOS!$I$2:$J$101) -> 2
C37: Arequipa Cayma | D37: 105 | E37: =D37/SUM($D$34:$D$39) -> 0.087866109 | F37: =LOOKUP(G37,RANGOS!$A$9:$B$13) -> Bajo | G37: =LOOKUP(E37,RANGOS!$I$2:$J$101) -> 2
C38: Arequipa Centro | D38: 195 | E38: =D38/SUM($D$34:$D$39) -> 0.16317992 | F38: =LOOKUP(G38,RANGOS!$A$9:$B$13) -> Bajo | G38: =LOOKUP(E38,RANGOS!$I$2:$J$101) -> 2
C39: Lima - Plaza San Martín | D39: 195 | E39: =D39/SUM($D$34:$D$39) -> 0.16317992 | F39: =LOOKUP(G39,RANGOS!$A$9:$B$13) -> Bajo | G39: =LOOKUP(E39,RANGOS!$I$2:$J$101) -> 2
C40: Lima - Larco | D40: 195 | E40: =D40/SUM($D$34:$D$39) -> 0.16317992 | F40: =LOOKUP(G40,RANGOS!$A$9:$B$13) -> Bajo | G40: =LOOKUP(E40,RANGOS!$I$2:$J$101) -> 2
C41: Lima - Los Olivos | D41: 195 | E41: =D41/SUM($D$34:$D$39) -> 0.16317992 | F41: =LOOKUP(G41,RANGOS!$A$9:$B$13) -> Bajo | G41: =LOOKUP(E41,RANGOS!$I$2:$J$101) -> 2
C42: Lima - Primavera | D42: 195 | E42: =D42/SUM($D$34:$D$39) -> 0.16317992 | F42: =LOOKUP(G42,RANGOS!$A$9:$B$13) -> Bajo | G42: =LOOKUP(E42,RANGOS!$I$2:$J$101) -> 2
...

Sheet PASIVO
A1: FACTOR DE RIESGO PRODUCTO: PASIVO
A3: SUB FACTOR | C3: VARIABLE | E3: INDICADOR | F3: PROBABILIDAD | H3: IMPACTO | J3: RIESGO INHERENTE | L3: PESO | M3: MITIGANTES IMPLEMENTADOS | N3: NIVEL DE EFICACIA | P3: RIESGO RESIDUAL | R3: PESO
A4: AHORROS | B4: 0.6 | C4: 1.1 Ingreso de dinero | D4: 0.3 | E4: Efectivo | F4: =LOOKUP(G4,RANGOS!$A$2:$B$6) -> Muy alta | G4: 5 | H4: =LOOKUP(I4,RANGOS!$A$9:$B$13) -> Muy alto | I4: ='Data pasivo'!G6 -> 5 | J4: =LOOKUP(K4,RANGOS!$F$2:$G$26) -> MUY ALTO | K4: =G4*I4 -> 25 | L4: =$B$4*$D$4*AVERAGE(K4:K11) -> 1.125 | M4: Registro de Operaciones / Bantotal, Formato de Origen de Fondos, sistema de alertas Assist | N4: MEDIO | O4: 3 | P4: =LOOKUP(Q4,RANGOS!$F$2:$G$26) -> MEDIO | Q4: =K4/$O$4 -> 8.3333333 | R4: =$B$4*$D$4*AVERAGE(Q4:Q11) -> 0.375
E5: Cheque de gerencia | F5: =LOOKUP(G5,RANGOS!$A$2:$B$6) -> Media | G5: 3 | H5: =LOOKUP(I5,RANGOS!$A$9:$B$13) -> Bajo | I5: ='Data pasivo'!G7 -> 2 | J5: =LOOKUP(K5,RANGOS!$F$2:$G$26) -> MEDIO | K5: =G5*I5 -> 6 | P5: =LOOKUP(Q5,RANGOS!$F$2:$G$26) -> BAJO | Q5: =K5/$O$4 -> 2
E6: Cheque del mismo banco | F6: =LOOKUP(G6,RANGOS!$A$2:$B$6) -> Baja | G6: 2 | H6: =LOOKUP(I6,RANGOS!$A$9:$B$13) -> Muy bajo | I6: ='Data pasivo'!G8 -> 1 | J6: =LOOKUP(K6,RANGOS!$F$2:$G$26) -> BAJO | K6: =G6*I6 -> 2 | P6: =LOOKUP(Q6,RANGOS!$F$2:$G$26) -> MUY BAJO | Q6: =K6/$O$4 -> 0.66666667
E7: Cheque de otro banco | F7: Media | G7: 3 | H7: =LOOKUP(I7,RANGOS!$A$9:$B$13) -> Muy bajo | I7: ='Data pasivo'!G9 -> 1 | J7: =LOOKUP(K7,RANGOS!$F$2:$G$26) -> BAJO | K7: =G7*I7 -> 3 | P7: =LOOKUP(Q7,RANGOS!$F$2:$G$26) -> MUY BAJO | Q7: =K7/$O$4 -> 1
E8: Transferencia entre cuentas propias | F8: =LOOKUP(G8,RANGOS!$A$2:$B$6) -> Media | G8: 3 | H8: =LOOKUP(I8,RANGOS!$A$9:$B$13) -> Muy bajo | I8: ='Data pasivo'!G10 -> 1 | J8: =LOOKUP(K8,RANGOS!$F$2:$G$26) -> BAJO | K8: =G8*I8 -> 3 | P8: =LOOKUP(Q8,RANGOS!$F$2:$G$26) -> MUY BAJO | Q8: =K8/$O$4 -> 1
E9: Transferencia entre cuentas de terceros | F9: =LOOKUP(G9,RANGOS!$A$2:$B$6) -> Media | G9: 3 | H9: =LOOKUP(I9,RANGOS!$A$9:$B$13) -> Muy bajo | I9: ='Data pasivo'!G11 -> 1 | J9: =LOOKUP(K9,RANGOS!$F$2:$G$26) -> BAJO | K9: =G9*I9 -> 3 | P9: =LOOKUP(Q9,RANGOS!$F$2:$G$26) -> MUY BAJO | Q9: =K9/$O$4 -> 1
E10: Transferencia de otros bancos | F10: Alta | G10: 3 | H10: =LOOKUP(I10,RANGOS!$A$9:$B$13) -> Muy bajo | I10: ='Data pasivo'!G12 -> 1 | J10: =LOOKUP(K10,RANGOS!$F$2:$G$26) -> BAJO | K10: =G10*I10 -> 3 | P10: =LOOKUP(Q10,RANGOS!$F$2:$G$26) -> MUY BAJO | Q10: =K10/$O$4 -> 1
E11: Transferencia del exterior | F11: =LOOKUP(G11,RANGOS!$A$2:$B$6) -> Muy alta | G11: 5 | H11: =LOOKUP(I11,RANGOS!$A$9:$B$13) -> Muy bajo | I11: ='Data pasivo'!G13 -> 1 | J11: =LOOKUP(K11,RANGOS!$F$2:$G$26) -> BAJO | K11: =G11*I11 -> 5 | P11: =LOOKUP(Q11,RANGOS!$F$2:$G$26) -> MUY BAJO | Q11: =K11/$O$4 -> 1.6666667
C12: 1.2 Salida de dinero | D12: 0.1 | E12: Efectivo | F12: Alta | G12: 3 | H12: =LOOKUP(I12,RANGOS!$A$9:$B$13) -> Medio | I12: ='Data pasivo'!G14 -> 3 | J12: =LOOKUP(K12,RANGOS!$F$2:$G$26) -> MEDIO | K12: =G12*I12 -> 9 | L12: =$B$4*$D$12*AVERAGE(K12:K19) -> 0.285 | M12: Registro de Operaciones / Bantotal | N12: MEDIO | O12: 3 | P12: =LOOKUP(Q12,RANGOS!$F$2:$G$26) -> BAJO | Q12: =K12/$O$12 -> 3 | R12: =$B$4*$D$12*AVERAGE(Q12:Q19) -> 0.095
E13: Cheque de gerencia | F13: =LOOKUP(G13,RANGOS!$A$2:$B$6) -> Alta | G13: 4 | H13: =LOOKUP(I13,RANGOS!$A$9:$B$13) -> Muy bajo | I13: ='Data pasivo'!G15 -> 1 | J13: =LOOKUP(K13,RANGOS!$F$2:$G$26) -> BAJO | K13: =G13*I13 -> 4 | P13: =LOOKUP(Q13,RANGOS!$F$2:$G$26) -> MUY BAJO | Q13: =K13/$O$12 -> 1.3333333
E14: Cheque del mismo banco | F14: Baja | G14: 1 | H14: =LOOKUP(I14,RANGOS!$A$9:$B$13) -> Bajo | I14: ='Data pasivo'!G16 -> 2 | J14: =LOOKUP(K14,RANGOS!$F$2:$G$26) -> BAJO | K14: =G14*I14 -> 2 | P14: =LOOKUP(Q14,RANGOS!$F$2:$G$26) -> MUY BAJO | Q14: =K14/$O$12 -> 0.66666667
E15: Cheque de otro banco | F15: Alta | G15: 3 | H15: =LOOKUP(I15,RANGOS!$A$9:$B$13) -> Muy bajo | I15: ='Data pasivo'!G17 -> 1 | J15: =LOOKUP(K15,RANGOS!$F$2:$G$26) -> BAJO | K15: =G15*I15 -> 3 | P15: =LOOKUP(Q15,RANGOS!$F$2:$G$26) -> MUY BAJO | Q15: =K15/$O$12 -> 1
E16: Transferencia entre cuentas propias | F16: =LOOKUP(G16,RANGOS!$A$2:$B$6) -> Muy baja | G16: 1 | H16: =LOOKUP(I16,RANGOS!$A$9:$B$13) -> Medio | I16: ='Data pasivo'!G18 -> 3 | J16: =LOOKUP(K16,RANGOS!$F$2:$G$26) -> BAJO | K16: =G16*I16 -> 3 | P16: =LOOKUP(Q16,RANGOS!$F$2:$G$26) -> MUY BAJO | Q16: =K16/$O$12 -> 1
E17: Transferencia entre cuentas de terceros | F17: =LOOKUP(G17,RANGOS!$A$2:$B$6) -> Media | G17: 3 | H17: =LOOKUP(I17,RANGOS!$A$9:$B$13) -> Muy bajo | I17: ='Data pasivo'!G19 -> 1 | J17: =LOOKUP(K17,RANGOS!$F$2:$G$26) -> BAJO | K17: =G17*I17 -> 3 | P17: =LOOKUP(Q17,RANGOS!$F$2:$G$26) -> MUY BAJO | Q17: =K17/$O$12 -> 1
E18: Transferencia de otros bancos | F18: =LOOKUP(G18,RANGOS!$A$2:$B$6) -> Media | G18: 3 | H18: =LOOKUP(I18,RANGOS!$A$9:$B$13) -> Medio | I18: ='Data pasivo'!G20 -> 3 | J18: =LOOKUP(K18,RANGOS!$F$2:$G$26) -> MEDIO | K18: =G18*I18 -> 9 | P18: =LOOKUP(Q18,RANGOS!$F$2:$G$26) -> BAJO | Q18: =K18/$O$12 -> 3
E19: Transferencia del exterior | F19: =LOOKUP(G19,RANGOS!$A$2:$B$6) -> Muy alta | G19: 5 | H19: =LOOKUP(I19,RANGOS!$A$9:$B$13) -> Muy bajo | I19: ='Data pasivo'!G21 -> 1 | J19: =LOOKUP(K19,RANGOS!$F$2:$G$26) -> BAJO | K19: =G19*I19 -> 5 | P19: =LOOKUP(Q19,RANGOS!$F$2:$G$26) -> MUY BAJO | Q19: =K19/$O$12 -> 1.6666667
C20: 1.3 Número de cuentas por saldo en cuenta | D20: 0.15 | E20: < USD 10,000 | F20: Muy baja | G20: 1 | H20: =LOOKUP(I20,RANGOS!$A$9:$B$13) -> Muy bajo | I20: ='Data pasivo'!G22 -> 1 | J20: =LOOKUP(K20,RANGOS!$F$2:$G$26) -> MUY BAJO | K20: =G20*I20 -> 1 | L20: =$B$4*$D$20*AVERAGE(K20:K22) -> 0.66 | N20: =LOOKUP(O20,RANGOS!$F$2:$G$26) -> MUY BAJO | O20: 1 | P20: =LOOKUP(Q20,RANGOS!$F$2:$G$26) -> MUY BAJO | Q20: =K20/$O$20 -> 1 | R20: =$B$4*$D$20*AVERAGE(Q20:Q22) -> 0.66
E21: ≥ USD 10,000 < USD 50,000 | F21: =LOOKUP(G21,RANGOS!$A$2:$B$6) -> Media | G21: 3 | H21: =LOOKUP(I21,RANGOS!$A$9:$B$13) -> Medio | I21: ='Data pasivo'!G23 -> 3 | J21: =LOOKUP(K21,RANGOS!$F$2:$G$26) -> MEDIO | K21: =G21*I21 -> 9 | P21: =LOOKUP(Q21,RANGOS!$F$2:$G$26) -> MEDIO | Q21: =K21/$O$20 -> 9
E22: ≥ USD USD 50,000 | F22: Alta | G22: 4 | H22: =LOOKUP(I22,RANGOS!$A$9:$B$13) -> Medio | I22: ='Data pasivo'!G24 -> 3 | J22: =LOOKUP(K22,RANGOS!$F$2:$G$26) -> ALTO | K22: =G22*I22 -> 12 | P22: =LOOKUP(Q22,RANGOS!$F$2:$G$26) -> ALTO | Q22: =K22/$O$20 -> 12
C23: 1.4 Número de cuentas por volumen transado del periodo de análisis | D23: 0.1 | E23: < USD 10,000 | F23: Alta | G23: 4 | H23: =LOOKUP(I23,RANGOS!$A$9:$B$13) -> Alto | I23: ='Data pasivo'!G25 -> 4 | J23: =LOOKUP(K23,RANGOS!$F$2:$G$26) -> ALTO | K23: =G23*I23 -> 16 | L23: =$B$4*$D$23*AVERAGE(K23:K25) -> 0.7 | N23: =LOOKUP(O23,RANGOS!$F$2:$G$26) -> MUY BAJO | O23: 1 | P23: =LOOKUP(Q23,RANGOS!$F$2:$G$26) -> ALTO | Q23: =K23/$O$23 -> 16 | R23: =$B$4*$D$23*AVERAGE(Q23:Q25) -> 0.7
E24: ≥ USD 10,000 < USD 50,000 | F24: Alta | G24: 4 | H24: =LOOKUP(I24,RANGOS!$A$9:$B$13) -> Muy bajo | I24: ='Data pasivo'!G26 -> 1 | J24: =LOOKUP(K24,RANGOS!$F$2:$G$26) -> BAJO | K24: =G24*I24 -> 4 | P24: =LOOKUP(Q24,RANGOS!$F$2:$G$26) -> BAJO | Q24: =K24/$O$23 -> 4
E25: ≥ USD 50,000 | F25: Muy alta | G25: 5 | H25: =LOOKUP(I25,RANGOS!$A$9:$B$13) -> Medio | I25: ='Data pasivo'!G27 -> 3 | J25: =LOOKUP(K25,RANGOS!$F$2:$G$26) -> ALTO | K25: =G25*I25 -> 15 | P25: =LOOKUP(Q25,RANGOS!$F$2:$G$26) -> ALTO | Q25: =K25/$O$23 -> 15
C26: 1.5 Volumen transado en el periodo de análisis | D26: 0.1 | E26: < USD 10,000 | F26: =LOOKUP(G26,RANGOS!$A$2:$B$6) -> Muy alta | G26: 5 | H26: =LOOKUP(I26,RANGOS!$A$9:$B$13) -> Muy bajo | I26: ='Data pasivo'!G28 -> 1 | J26: =LOOKUP(K26,RANGOS!$F$2:$G$26) -> BAJO | K26: =G26*I26 -> 5 | L26: =$B$4*$D$26*AVERAGE(K26:K28) -> 0.8 | N26: =LOOKUP(O26,RANGOS!$F$2:$G$26) -> MUY BAJO | O26: 1 | P26: =LOOKUP(Q26,RANGOS!$F$2:$G$26) -> BAJO | Q26: =K26/$O$26 -> 5 | R26: =$B$4*$D$26*AVERAGE(Q26:Q28) -> 0.8
E27: ≥ USD 10,000 < USD 50,000 | F27: =LOOKUP(G27,RANGOS!$A$2:$B$6) -> Muy alta | G27: 5 | H27: =LOOKUP(I27,RANGOS!$A$9:$B$13) -> Medio | I27: ='Data pasivo'!G29 -> 3 | J27: =LOOKUP(K27,RANGOS!$F$2:$G$26) -> ALTO | K27: =G27*I27 -> 15 | P27: =LOOKUP(Q27,RANGOS!$F$2:$G$26) -> ALTO | Q27: =K27/$O$26 -> 15
E28: ≥ USD 50,000 | F28: =LOOKUP(G28,RANGOS!$A$2:$B$6) -> Muy alta | G28: 5 | H28: =LOOKUP(I28,RANGOS!$A$9:$B$13) -> Alto | I28: ='Data pasivo'!G30 -> 4 | J28: =LOOKUP(K28,RANGOS!$F$2:$G$26) -> ALTO | K28: =G28*I28 -> 20 | P28: =LOOKUP(Q28,RANGOS!$F$2:$G$26) -> ALTO | Q28: =K28/$O$26 -> 20
C29: 1.6 Moneda | D29: 0.05 | E29: Nuevos soles | F29: =LOOKUP(G29,RANGOS!$A$2:$B$6) -> Muy alta | G29: 5 | H29: =LOOKUP(I29,RANGOS!$A$9:$B$13) -> Bajo | I29: ='Data pasivo'!G31 -> 2 | J29: =LOOKUP(K29,RANGOS!$F$2:$G$26) -> MEDIO | K29: =G29*I29 -> 10 | L29: =$B$4*$D$29*AVERAGE(K29:K31) -> 0.4 | N29: =LOOKUP(O29,RANGOS!$F$2:$G$26) -> MUY BAJO | O29: 1 | P29: =LOOKUP(Q29,RANGOS!$F$2:$G$26) -> MEDIO | Q29: =K29/$O$29 -> 10 | R29: =$B$4*$D$29*AVERAGE(Q29:Q31) -> 0.4
E30: Dólares americanos | F30: =LOOKUP(G30,RANGOS!$A$2:$B$6) -> Muy alta | G30: 5 | H30: =LOOKUP(I30,RANGOS!$A$9:$B$13) -> Muy alto | I30: ='Data pasivo'!G32 -> 5 | J30: =LOOKUP(K30,RANGOS!$F$2:$G$26) -> MUY ALTO | K30: =G30*I30 -> 25 | P30: =LOOKUP(Q30,RANGOS!$F$2:$G$26) -> MUY ALTO | Q30: =K30/$O$29 -> 25
E31: Euros | F31: =LOOKUP(G31,RANGOS!$A$2:$B$6) -> Muy alta | G31: 5 | H31: =LOOKUP(I31,RANGOS!$A$9:$B$13) -> Muy bajo | I31: ='Data pasivo'!G33 -> 1 | J31: =LOOKUP(K31,RANGOS!$F$2:$G$26) -> BAJO | K31: =G31*I31 -> 5 | P31: =LOOKUP(Q31,RANGOS!$F$2:$G$26) -> BAJO | Q31: =K31/$O$29 -> 5
C32: 1.7 Canal presencial | D32: 0.05 | E32: Ventanilla | F32: =LOOKUP(G32,RANGOS!$A$2:$B$6) -> Muy alta | G32: 5 | H32: =LOOKUP(I32,RANGOS!$A$9:$B$13) -> Muy alto | I32: ='Data pasivo'!G34 -> 5 | J32: =LOOKUP(K32,RANGOS!$F$2:$G$26) -> MUY ALTO | K32: =G32*I32 -> 25 | L32: =$B$4*$D$32*AVERAGE(K32:K33) -> 0.525 | N32: =LOOKUP(O32,RANGOS!$F$2:$G$26) -> MUY BAJO | O32: 1 | P32: =LOOKUP(Q32,RANGOS!$F$2:$G$26) -> MUY ALTO | Q32: =K32/$O$32 -> 25 | R32: =$B$4*$D$32*AVERAGE(Q32:Q33) -> 0.525
E33: Agentes | F33: =LOOKUP(G33,RANGOS!$A$2:$B$6) -> Muy alta | G33: 5 | H33: =LOOKUP(I33,RANGOS!$A$9:$B$13) -> Bajo | I33: ='Data pasivo'!G35 -> 2 | J33: =LOOKUP(K33,RANGOS!$F$2:$G$26) -> MEDIO | K33: =G33*I33 -> 10 | P33: =LOOKUP(Q33,RANGOS!$F$2:$G$26) -> MEDIO | Q33: =K33/$O$32 -> 10
C34: 1.8 Canal no presencial | D34: 0.05 | E34: Plataforma web | F34: =LOOKUP(G34,RANGOS!$A$2:$B$6) -> Muy alta | G34: 5 | H34: =LOOKUP(I34,RANGOS!$A$9:$B$13) -> Alto | I34: ='Data pasivo'!G36 -> 4 | J34: =LOOKUP(K34,RANGOS!$F$2:$G$26) -> ALTO | K34: =G34*I34 -> 20 | L34: =$B$4*$D$34*AVERAGE(K34:K37) -> 0.3375 | N34: =LOOKUP(O34,RANGOS!$F$2:$G$26) -> MUY BAJO | O34: 1 | P34: =LOOKUP(Q34,RANGOS!$F$2:$G$26) -> ALTO | Q34: =K34/$O$34 -> 20 | R34: =$B$4*$D$34*AVERAGE(Q34:Q37) -> 0.3375
E35: ATM | F35: =LOOKUP(G35,RANGOS!$A$2:$B$6) -> Muy alta | G35: 5 | H35: =LOOKUP(I35,RANGOS!$A$9:$B$13) -> Muy bajo | I35: ='Data pasivo'!G37 -> 1 | J35: =LOOKUP(K35,RANGOS!$F$2:$G$26) -> BAJO | K35: =G35*I35 -> 5 | P35: =LOOKUP(Q35,RANGOS!$F$2:$G$26) -> BAJO | Q35: =K35/$O$34 -> 5
E36: Banca telefónica | F36: =LOOKUP(G36,RANGOS!$A$2:$B$6) -> Muy alta | G36: 5 | H36: =LOOKUP(I36,RANGOS!$A$9:$B$13) -> Muy bajo | I36: ='Data pasivo'!G38 -> 1 | J36: =LOOKUP(K36,RANGOS!$F$2:$G$26) -> BAJO | K36: =G36*I36 -> 5 | P36: =LOOKUP(Q36,RANGOS!$F$2:$G$26) -> BAJO | Q36: =K36/$O$34 -> 5
E37: Procesos masivos | F37: =LOOKUP(G37,RANGOS!$A$2:$B$6) -> Muy alta | G37: 5 | H37: =LOOKUP(I37,RANGOS!$A$9:$B$13) -> Medio | I37: ='Data pasivo'!G39 -> 3 | J37: =LOOKUP(K37,RANGOS!$F$2:$G$26) -> ALTO | K37: =G37*I37 -> 15 | P37: =LOOKUP(Q37,RANGOS!$F$2:$G$26) -> ALTO | Q37: =K37/$O$34 -> 15
C38: 1.9 Lugar de apertura de la cuenta | D38: 0.1 | E38: Lima | F38: =LOOKUP(G38,RANGOS!$A$2:$B$6) -> Muy baja | G38: 1 | H38: =LOOKUP(I38,RANGOS!$A$9:$B$13) -> Muy alto | I38: ='Data pasivo'!D40 -> 3454 | J38: =LOOKUP(K38,RANGOS!$F$2:$G$26) -> MUY ALTO | K38: =G38*I38 -> 3454 | L38: =$B$4*$D$38*AVERAGE(K38:K40) -> 80.66 | N38: =LOOKUP(O38,RANGOS!$F$2:$G$26) -> MUY BAJO | O38: 1 | P38: =LOOKUP(Q38,RANGOS!$F$2:$G$26) -> MUY ALTO | Q38: =K38/$O$38 -> 3454 | R38: =$B$4*$D$38*AVERAGE(Q38:Q40) -> 80.66
E39: Piura | F39: =LOOKUP(G39,RANGOS!$A$2:$B$6) -> Muy baja | G39: 1 | H39: =LOOKUP(I39,RANGOS!$A$9:$B$13) -> Muy alto | I39: ='Data pasivo'!D41 -> 45 | J39: =LOOKUP(K39,RANGOS!$F$2:$G$26) -> MUY ALTO | K39: =G39*I39 -> 45 | P39: =LOOKUP(Q39,RANGOS!$F$2:$G$26) -> MUY ALTO | Q39: =K39/$O$38 -> 45
E40: Trujillo | F40: =LOOKUP(G40,RANGOS!$A$2:$B$6) -> Muy baja | G40: 1 | H40: =LOOKUP(I40,RANGOS!$A$9:$B$13) -> Muy alto | I40: ='Data pasivo'!D42 -> 534 | J40: =LOOKUP(K40,RANGOS!$F$2:$G$26) -> MUY ALTO | K40: =G40*I40 -> 534 | P40: =LOOKUP(Q40,RANGOS!$F$2:$G$26) -> MUY ALTO | Q40: =K40/$O$38 -> 534
A41: 2. Ahorros a plazo | B41: 0.3 | C41: 2.1 Ingreso de dinero | D41: 0.34 | E41: Lima | F41: =LOOKUP(G41,RANGOS!$A$2:$B$6) -> Muy baja | G41: 1 | H41: =LOOKUP(I41,RANGOS!$A$9:$B$13) -> Muy bajo | I41: 1 | J41: =LOOKUP(K41,RANGOS!$F$2:$G$26) -> MUY BAJO | K41: =G41*I41 -> 1 | L41: =$B$41*$D$41*AVERAGE(K41:K42) -> 0.102 | N41: =LOOKUP(O41,RANGOS!$F$2:$G$26) -> MUY BAJO | O41: 1 | P41: =LOOKUP(Q41,RANGOS!$F$2:$G$26) -> MUY BAJO | Q41: =K41/$O$41 -> 1 | R41: =$B$41*$D$41*AVERAGE(Q41:Q42) -> 0.102
...

Sheet Data pasivo
A1: ANÁLISIS DEL IMPACTO: PRODUCTO PASIVO
A3: Periodo de análisis: De julio del 2014 a junio del 2015
A5: SUB FACTOR | B5: VARIABLE | C5: INDICADOR | D5: Registro | E5: Porcentaje | F5: IMPACTO
A6: 1. Ahorros | B6: 1.1 Ingreso de dinero | C6: Efectivo | D6: 62627 | E6: =D6/SUM($D$6:$D$13) -> 0.74968278 | F6: =LOOKUP(E6,RANGOS!#REF!) -> #REF! | G6: =LOOKUP(E6,RANGOS!$I$2:$J$101) -> 5
C7: Cheque de gerencia | D7: 7374 | E7: =D7/SUM($D$6:$D$13) -> 0.088271206 | F7: =LOOKUP(E7,RANGOS!#REF!) -> #REF! | G7: =LOOKUP(E7,RANGOS!$I$2:$J$101) -> 2
C8: Cheque del mismo banco | D8: 2434 | E8: =D8/SUM($D$6:$D$13) -> 0.029136441 | F8: =LOOKUP(E8,RANGOS!#REF!) -> #REF! | G8: =LOOKUP(E8,RANGOS!$I$2:$J$101) -> 1
C9: Cheque de otro banco | D9: 4214 | E9: =D9/SUM($D$6:$D$13) -> 0.050444109 | F9: =LOOKUP(E9,RANGOS!#REF!) -> #REF! | G9: =LOOKUP(E9,RANGOS!$I$2:$J$101) -> 1
C10: Transferencia entre cuentas propias | D10: 4546 | E10: =D10/SUM($D$6:$D$13) -> 0.054418349 | F10: =LOOKUP(E10,RANGOS!#REF!) -> #REF! | G10: =LOOKUP(E10,RANGOS!$I$2:$J$101) -> 1
C11: Transferencia entre cuentas de terceros | D11: 646 | E11: =D11/SUM($D$6:$D$13) -> 0.0077330077 | F11: =LOOKUP(E11,RANGOS!#REF!) -> #REF! | G11: =LOOKUP(E11,RANGOS!$I$2:$J$101) -> 1
C12: Transferencia de otros bancos | D12: 442 | E12: =D12/SUM($D$6:$D$13) -> 0.0052910053 | F12: =LOOKUP(E12,RANGOS!#REF!) -> #REF! | G12: =LOOKUP(E12,RANGOS!$I$2:$J$101) -> 1
C13: Transferencia del exterior | D13: 1255 | E13: =D13/SUM($D$6:$D$13) -> 0.015023103 | F13: =LOOKUP(E13,RANGOS!#REF!) -> #REF! | G13: =LOOKUP(E13,RANGOS!$I$2:$J$101) -> 1
B14: 1.2 Salida de dinero | C14: Efectivo | D14: 33444 | E14: =D14/SUM($D$14:$D$21) -> 0.21998579 | F14: =LOOKUP(E14,RANGOS!#REF!) -> #REF! | G14: =LOOKUP(E14,RANGOS!$I$2:$J$101) -> 3
C15: Cheque de gerencia | D15: 555 | E15: =D15/SUM($D$14:$D$21) -> 0.0036506433 | F15: =LOOKUP(E15,RANGOS!#REF!) -> #REF! | G15: =LOOKUP(E15,RANGOS!$I$2:$J$101) -> 1
C16: Cheque del mismo banco | D16: 23454 | E16: =D16/SUM($D$14:$D$21) -> 0.15427421 | F16: =LOOKUP(E16,RANGOS!#REF!) -> #REF! | G16: =LOOKUP(E16,RANGOS!$I$2:$J$101) -> 2
C17: Cheque de otro banco | D17: 8576 | E17: =D17/SUM($D$14:$D$21) -> 0.056410661 | F17: =LOOKUP(E17,RANGOS!#REF!) -> #REF! | G17: =LOOKUP(E17,RANGOS!$I$2:$J$101) -> 1
C18: Transferencia entre cuentas propias | D18: 36535 | E18: =D18/SUM($D$14:$D$21) -> 0.24031757 | F18: =LOOKUP(E18,RANGOS!#REF!) -> #REF! | G18: =LOOKUP(E18,RANGOS!$I$2:$J$101) -> 3
C19: Transferencia entre cuentas de terceros | D19: 7345 | E19: =D19/SUM($D$14:$D$21) -> 0.048313469 | F19: =LOOKUP(E19,RANGOS!#REF!) -> #REF! | G19: =LOOKUP(E19,RANGOS!$I$2:$J$101) -> 1
C20: Transferencia de otros bancos | D20: 36453 | E20: =D20/SUM($D$14:$D$21) -> 0.2397782 | F20: =LOOKUP(E20,RANGOS!#REF!) -> #REF! | G20: =LOOKUP(E20,RANGOS!$I$2:$J$101) -> 3
C21: Transferencia del exterior | D21: 5666 | E21: =D21/SUM($D$14:$D$21) -> 0.03726945 | F21: =LOOKUP(E21,RANGOS!#REF!) -> #REF! | G21: =LOOKUP(E21,RANGOS!$I$2:$J$101) -> 1
B22: 1.3 Número de cuentas por saldo en cuenta | C22: < USD 10,000 | D22: 673 | E22: =D22/SUM($D$22:$D$24) -> 0.038580601 | F22: =LOOKUP(E22,RANGOS!#REF!) -> #REF! | G22: =LOOKUP(E22,RANGOS!$I$2:$J$101) -> 1
C23: ≥ USD 10,000 < USD 50,000 | D23: 8383 | E23: =D23/SUM($D$22:$D$24) -> 0.48056638 | F23: =LOOKUP(E23,RANGOS!#REF!) -> #REF! | G23: =LOOKUP(E23,RANGOS!$I$2:$J$101) -> 3
C24: ≥ USD USD 50,000 | D24: 8388 | E24: =D24/SUM($D$22:$D$24) -> 0.48085302 | F24: =LOOKUP(E24,RANGOS!#REF!) -> #REF! | G24: =LOOKUP(E24,RANGOS!$I$2:$J$101) -> 3
B25: 1.4 Número de cuentas por volumen transado del periodo de análisis | C25: < USD 10,000 | D25: 9282 | E25: =D25/SUM($D$25:$D$27) -> 0.53094612 | F25: =LOOKUP(E25,RANGOS!#REF!) -> #REF! | G25: =LOOKUP(E25,RANGOS!$I$2:$J$101) -> 4
C26: ≥ USD 10,000 < USD 50,000 | D26: 827 | E26: =D26/SUM($D$25:$D$27) -> 0.0473058 | F26: =LOOKUP(E26,RANGOS!#REF!) -> #REF! | G26: =LOOKUP(E26,RANGOS!$I$2:$J$101) -> 1
C27: ≥ USD 50,000 | D27: 7373 | E27: =D27/SUM($D$25:$D$27) -> 0.42174808 | F27: =LOOKUP(E27,RANGOS!#REF!) -> #REF! | G27: =LOOKUP(E27,RANGOS!$I$2:$J$101) -> 3
B28: 1.5 Volumen transado en el periodo de análisis | C28: < USD 10,000 | D28: 3423 | E28: =D28/SUM($D$28:$D$30) -> 0.029950389 | F28: =LOOKUP(E28,RANGOS!#REF!) -> #REF! | G28: =LOOKUP(E28,RANGOS!$I$2:$J$101) -> 1
C29: ≥ USD 10,000 < USD 50,000 | D29: 45423 | E29: =D29/SUM($D$28:$D$30) -> 0.39743982 | F29: =LOOKUP(E29,RANGOS!#REF!) -> #REF! | G29: =LOOKUP(E29,RANGOS!$I$2:$J$101) -> 3
C30: ≥ USD 50,000 | D30: 65443 | E30: =D30/SUM($D$28:$D$30) -> 0.57260979 | F30: =LOOKUP(E30,RANGOS!#REF!) -> #REF! | G30: =LOOKUP(E30,RANGOS!$I$2:$J$101) -> 4
B31: 1.6 Moneda | C31: Nuevos soles | D31: 543 | E31: =D31/SUM($D$31:$D$33) -> 0.11260888 | F31: =LOOKUP(E31,RANGOS!#REF!) -> #REF! | G31: =LOOKUP(E31,RANGOS!$I$2:$J$101) -> 2
C32: Dólares americanos | D32: 4236 | E32: =D32/SUM($D$31:$D$33) -> 0.87847366 | F32: =LOOKUP(E32,RANGOS!#REF!) -> #REF! | G32: =LOOKUP(E32,RANGOS!$I$2:$J$101) -> 5
C33: Euros | D33: 43 | E33: =D33/SUM($D$31:$D$33) -> 0.0089174616 | F33: =LOOKUP(E33,RANGOS!#REF!) -> #REF! | G33: =LOOKUP(E33,RANGOS!$I$2:$J$101) -> 1
B34: 1.7 Canal presencial | C34: Ventanilla | D34: 24545 | E34: =D34/SUM($D$34:$D$35) -> 0.84347079 | F34: =LOOKUP(E34,RANGOS!#REF!) -> #REF! | G34: =LOOKUP(E34,RANGOS!$I$2:$J$101) -> 5
C35: Agentes | D35: 4555 | E35: =D35/SUM($D$34:$D$35) -> 0.15652921 | F35: =LOOKUP(E35,RANGOS!#REF!) -> #REF! | G35: =LOOKUP(E35,RANGOS!$I$2:$J$101) -> 2
B36: 1.8 Canal no presencial | C36: Plataforma web | D36: 435 | E36: =D36/SUM($D$36:$D$39) -> 0.52536232 | F36: =LOOKUP(E36,RANGOS!#REF!) -> #REF! | G36: =LOOKUP(E36,RANGOS!$I$2:$J$101) -> 4
C37: ATM | D37: 45 | E37: =D37/SUM($D$36:$D$39) -> 0.054347826 | F37: =LOOKUP(E37,RANGOS!#REF!) -> #REF! | G37: =LOOKUP(E37,RANGOS!$I$2:$J$101) -> 1
C38: Banca telefónica | D38: 3 | E38: =D38/SUM($D$36:$D$39) -> 0.0036231884 | F38: =LOOKUP(E38,RANGOS!#REF!) -> #REF! | G38: =LOOKUP(E38,RANGOS!$I$2:$J$101) -> 1
C39: Procesos masivos | D39: 345 | E39: =D39/SUM($D$36:$D$39) -> 0.41666667 | F39: =LOOKUP(E39,RANGOS!#REF!) -> #REF! | G39: =LOOKUP(E39,RANGOS!$I$2:$J$101) -> 3
B40: 1.9 Lugar de Apertura de la cuenta | C40: Lima | D40: 3454 | E40: =D40/SUM($D$40:$D$42) -> 0.85643442 | F40: =LOOKUP(E40,RANGOS!#REF!) -> #REF! | G40: =LOOKUP(E40,RANGOS!$I$2:$J$101) -> 5
C41: Piura | D41: 45 | E41: =D41/SUM($D$40:$D$42) -> 0.011157947 | F41: =LOOKUP(E41,RANGOS!#REF!) -> #REF! | G41: =LOOKUP(E41,RANGOS!$I$2:$J$101) -> 1
C42: Trujillo | D42: 534 | E42: =D42/SUM($D$40:$D$42) -> 0.13240764 | F42: =LOOKUP(E42,RANGOS!#REF!) -> #REF! | G42: =LOOKUP(E42,RANGOS!$I$2:$J$101) -> 2

Sheet SERVICIOS
A1: FACTOR DE RIESGO SERVICIOS
A3: SUB FACTOR | C3: VARIABLE | E3: INDICADOR | F3: PROBABILIDAD | H3: IMPACTO | J3: RIESGO INHERENTE | L3: PESO | M3: MITIGANTES IMPLEMENTADOS | N3: NIVEL DE EFICACIA | P3: RIESGO RESIDUAL | R3: PESO
A4: 1. Remesas / Transferencia de fondos | B4: 0.4 | C4: 1.1 Envío de dinero | D4: 0.2 | E4: Nuevos soles | F4: =LOOKUP(G4,RANGOS!$A$2:$B$6) -> Muy baja | G4: 1 | H4: =LOOKUP(I4,RANGOS!$A$9:$B$13) -> Muy alto | I4: ='Data servicios'!G6 -> 5 | J4: =LOOKUP(K4,RANGOS!$F$2:$G$26) -> BAJO | K4: =G4*I4 -> 5 | L4: =$B$4*$D$4*AVERAGE(K4:K6) -> 0.24 | M4: Bantotal | N4: =LOOKUP(O4,RANGOS!$A$16:$B$20) -> Alto | O4: 4 | P4: =LOOKUP(Q4,RANGOS!$F$2:$G$26) -> MUY BAJO | Q4: =K4/$O$4 -> 1.25 | R4: =$B$4*$D$4*AVERAGE(Q4:Q6) -> 0.06
E5: Dólares americanos | F5: Alta | G5: 1 | H5: =LOOKUP(I5,RANGOS!$A$9:$B$13) -> Bajo | I5: ='Data servicios'!G7 -> 2 | J5: =LOOKUP(K5,RANGOS!$F$2:$G$26) -> BAJO | K5: =G5*I5 -> 2 | P5: =LOOKUP(Q5,RANGOS!$F$2:$G$26) -> MUY BAJO | Q5: =K5/$O$4 -> 0.5
E6: Euros | F6: Alta | G6: 1 | H6: =LOOKUP(I6,RANGOS!$A$9:$B$13) -> Bajo | I6: ='Data servicios'!G8 -> 2 | J6: =LOOKUP(K6,RANGOS!$F$2:$G$26) -> BAJO | K6: =G6*I6 -> 2 | P6: =LOOKUP(Q6,RANGOS!$F$2:$G$26) -> MUY BAJO | Q6: =K6/$O$4 -> 0.5
C7: 1.2 Recepción de dinero | D7: 0.2 | E7: Nuevos soles | F7: Alta | G7: 1 | H7: =LOOKUP(I7,RANGOS!$A$9:$B$13) -> Bajo | I7: ='Data servicios'!G9 -> 2 | J7: =LOOKUP(K7,RANGOS!$F$2:$G$26) -> BAJO | K7: =G7*I7 -> 2 | L7: =$B$4*$D$7*AVERAGE(K7:K9) -> 0.45333333 | M7: Formato Origen de Fondos | N7: =LOOKUP(O7,RANGOS!$A$16:$B$20) -> Alto | O7: 4 | P7: =LOOKUP(Q7,RANGOS!$F$2:$G$26) -> MUY BAJO | Q7: =K7/$O$7 -> 0.5 | R7: =$B$4*$D$7*AVERAGE(Q7:Q9) -> 0.11333333
E8: Dólares americanos | F8: Muy alta | G8: 5 | H8: =LOOKUP(I8,RANGOS!$A$9:$B$13) -> Bajo | I8: ='Data servicios'!G10 -> 2 | J8: =LOOKUP(K8,RANGOS!$F$2:$G$26) -> MEDIO | K8: =G8*I8 -> 10 | P8: =LOOKUP(Q8,RANGOS!$F$2:$G$26) -> BAJO | Q8: =K8/$O$7 -> 2.5
E9: Euros | F9: =LOOKUP(G9,RANGOS!$A$2:$B$6) -> Muy baja | G9: 1 | H9: =LOOKUP(I9,RANGOS!$A$9:$B$13) -> Muy alto | I9: ='Data servicios'!G11 -> 5 | J9: =LOOKUP(K9,RANGOS!$F$2:$G$26) -> BAJO | K9: =G9*I9 -> 5 | P9: =LOOKUP(Q9,RANGOS!$F$2:$G$26) -> MUY BAJO | Q9: =K9/$O$7 -> 1.25
C10: 1.3 Medio | D10: 0.1 | E10: Con cargo en cuenta | F10: =LOOKUP(G10,RANGOS!$A$2:$B$6) -> Muy baja | G10: 1 | H10: =LOOKUP(I10,RANGOS!$A$9:$B$13) -> Bajo | I10: ='Data servicios'!G12 -> 2 | J10: =LOOKUP(K10,RANGOS!$F$2:$G$26) -> BAJO | K10: =G10*I10 -> 2 | L10: =$B$4*$D$10*AVERAGE(K10:K11) -> 0.14 | N10: =LOOKUP(O10,RANGOS!$A$16:$B$20) -> Alto | O10: 4 | P10: =LOOKUP(Q10,RANGOS!$F$2:$G$26) -> MUY BAJO | Q10: =K10/$O$10 -> 0.5 | R10: =$B$4*$D$10*AVERAGE(Q10:Q11) -> 0.035
E11: Sin cargo en cuenta | F11: =LOOKUP(G11,RANGOS!$A$2:$B$6) -> Muy baja | G11: 1 | H11: =LOOKUP(I11,RANGOS!$A$9:$B$13) -> Muy alto | I11: ='Data servicios'!G13 -> 5 | J11: =LOOKUP(K11,RANGOS!$F$2:$G$26) -> BAJO | K11: =G11*I11 -> 5 | P11: =LOOKUP(Q11,RANGOS!$F$2:$G$26) -> MUY BAJO | Q11: =K11/$O$10 -> 1.25
C12: 1.4 Número de operaciones | D12: 0.15 | E12: < USD 1,000 | F12: =LOOKUP(G12,RANGOS!$A$2:$B$6) -> Muy baja | G12: 1 | H12: =LOOKUP(I12,RANGOS!$A$9:$B$13) -> Medio | I12: ='Data servicios'!G14 -> 3 | J12: =LOOKUP(K12,RANGOS!$F$2:$G$26) -> BAJO | K12: =G12*I12 -> 3 | L12: =$B$4*$D$12*AVERAGE(K12:K14) -> 0.14 | N12: =LOOKUP(O12,RANGOS!$A$16:$B$20) -> Alto | O12: 4 | P12: =LOOKUP(Q12,RANGOS!$F$2:$G$26) -> BAJO | Q12: =K12/$O$24 -> 3 | R12: =$B$4*$D$12*AVERAGE(Q12:Q14) -> 0.14
E13: ≥ USD 1,000 < USD 2,500 | F13: =LOOKUP(G13,RANGOS!$A$2:$B$6) -> Muy baja | G13: 1 | H13: =LOOKUP(I13,RANGOS!$A$9:$B$13) -> Medio | I13: ='Data servicios'!G15 -> 3 | J13: =LOOKUP(K13,RANGOS!$F$2:$G$26) -> BAJO | K13: =G13*I13 -> 3 | P13: =LOOKUP(Q13,RANGOS!$F$2:$G$26) -> BAJO | Q13: =K13/$O$24 -> 3
E14: ≥ USD 2,500 | F14: =LOOKUP(G14,RANGOS!$A$2:$B$6) -> Muy baja | G14: 1 | H14: =LOOKUP(I14,RANGOS!$A$9:$B$13) -> Muy bajo | I14: ='Data servicios'!G16 -> 1 | J14: =LOOKUP(K14,RANGOS!$F$2:$G$26) -> MUY BAJO | K14: =G14*I14 -> 1 | P14: =LOOKUP(Q14,RANGOS!$F$2:$G$26) -> MUY BAJO | Q14: =K14/$O$24 -> 1
C15: 1.5 Volumen transado en el periodo de análisis | D15: 0.15 | E15: < USD 1,000 | F15: =LOOKUP(G15,RANGOS!$A$2:$B$6) -> Muy baja | G15: 1 | H15: =LOOKUP(I15,RANGOS!$A$9:$B$13) -> Muy bajo | I15: ='Data servicios'!G17 -> 1 | J15: =LOOKUP(K15,RANGOS!$F$2:$G$26) -> MUY BAJO | K15: =G15*I15 -> 1 | L15: =$B$4*$D$15*AVERAGE(K15:K17) -> 0.16 | N15: =LOOKUP(O15,RANGOS!$A$16:$B$20) -> Alto | O15: 4 | P15: =LOOKUP(Q15,RANGOS!$F$2:$G$26) -> MUY BAJO | Q15: =K15/$O$15 -> 0.25 | R15: =$B$4*$D$15*AVERAGE(Q15:Q17) -> 0.04
E16: ≥ USD 1,000 < USD 2,500 | F16: =LOOKUP(G16,RANGOS!$A$2:$B$6) -> Muy baja | G16: 1 | H16: =LOOKUP(I16,RANGOS!$A$9:$B$13) -> Medio | I16: ='Data servicios'!G18 -> 3 | J16: =LOOKUP(K16,RANGOS!$F$2:$G$26) -> BAJO | K16: =G16*I16 -> 3 | P16: =LOOKUP(Q16,RANGOS!$F$2:$G$26) -> MUY BAJO | Q16: =K16/$O$15 -> 0.75
E17: ≥ USD 2,500 | F17: =LOOKUP(G17,RANGOS!$A$2:$B$6) -> Muy baja | G17: 1 | H17: =LOOKUP(I17,RANGOS!$A$9:$B$13) -> Alto | I17: ='Data servicios'!G19 -> 4 | J17: =LOOKUP(K17,RANGOS!$F$2:$G$26) -> BAJO | K17: =G17*I17 -> 4 | P17: =LOOKUP(Q17,RANGOS!$F$2:$G$26) -> MUY BAJO | Q17: =K17/$O$15 -> 1
C18: 1.6 Canal presencial | D18: 0.1 | E18: Ventanilla | F18: =LOOKUP(G18,RANGOS!$A$2:$B$6) -> Muy baja | G18: 1 | H18: =LOOKUP(I18,RANGOS!$A$9:$B$13) -> Bajo | I18: ='Data servicios'!G20 -> 2 | J18: =LOOKUP(K18,RANGOS!$F$2:$G$26) -> BAJO | K18: =G18*I18 -> 2 | L18: =$B$4*$D$18*AVERAGE(K18:K19) -> 0.14 | N18: =LOOKUP(O18,RANGOS!$A$16:$B$20) -> Alto | O18: 4 | P18: =LOOKUP(Q18,RANGOS!$F$2:$G$26) -> MUY BAJO | Q18: =K18/$O$18 -> 0.5 | R18: =$B$4*$D$18*AVERAGE(Q18:Q19) -> 0.035
E19: Agentes | F19: =LOOKUP(G19,RANGOS!$A$2:$B$6) -> Muy baja | G19: 1 | H19: =LOOKUP(I19,RANGOS!$A$9:$B$13) -> Muy alto | I19: ='Data servicios'!G21 -> 5 | J19: =LOOKUP(K19,RANGOS!$F$2:$G$26) -> BAJO | K19: =G19*I19 -> 5 | P19: =LOOKUP(Q19,RANGOS!$F$2:$G$26) -> MUY BAJO | Q19: =K19/$O$18 -> 1.25
C20: 1.7 Lugar de la operación | D20: 0.1 | E20: Lima | F20: =LOOKUP(G20,RANGOS!$A$2:$B$6) -> Muy baja | G20: 1 | H20: =LOOKUP(I20,RANGOS!$A$9:$B$13) -> Muy bajo | I20: ='Data servicios'!G22 -> 1 | J20: =LOOKUP(K20,RANGOS!$F$2:$G$26) -> MUY BAJO | K20: =G20*I20 -> 1 | L20: =$B$4*$D$20*AVERAGE(K20:K23) -> 0.09 | N20: =LOOKUP(O20,RANGOS!$A$16:$B$20) -> Alto | O20: 4 | P20: =LOOKUP(Q20,RANGOS!$F$2:$G$26) -> MUY BAJO | Q20: =K20/$O$20 -> 0.25 | R20: =$B$4*$D$20*AVERAGE(Q20:Q23) -> 0.0225
E21: Piura | F21: =LOOKUP(G21,RANGOS!$A$2:$B$6) -> Muy baja | G21: 1 | H21: =LOOKUP(I21,RANGOS!$A$9:$B$13) -> Bajo | I21: ='Data servicios'!G23 -> 2 | J21: =LOOKUP(K21,RANGOS!$F$2:$G$26) -> BAJO | K21: =G21*I21 -> 2 | P21: =LOOKUP(Q21,RANGOS!$F$2:$G$26) -> MUY BAJO | Q21: =K21/$O$20 -> 0.5
E22: Trujillo | F22: =LOOKUP(G22,RANGOS!$A$2:$B$6) -> Muy baja | G22: 1 | H22: =LOOKUP(I22,RANGOS!$A$9:$B$13) -> Muy alto | I22: ='Data servicios'!G24 -> 5 | J22: =LOOKUP(K22,RANGOS!$F$2:$G$26) -> BAJO | K22: =G22*I22 -> 5 | P22: =LOOKUP(Q22,RANGOS!$F$2:$G$26) -> MUY BAJO | Q22: =K22/$O$20 -> 1.25
E23: Chiclayo | F23: =LOOKUP(G23,RANGOS!$A$2:$B$6) -> Muy baja | G23: 1 | H23: =LOOKUP(I23,RANGOS!$A$9:$B$13) -> Muy bajo | I23: ='Data servicios'!G25 -> 1 | J23: =LOOKUP(K23,RANGOS!$F$2:$G$26) -> MUY BAJO | K23: =G23*I23 -> 1 | P23: =LOOKUP(Q23,RANGOS!$F$2:$G$26) -> MUY BAJO | Q23: =K23/$O$20 -> 0.25
A24: 2. Operaciones de cambio | B24: 0.5 | C24: 2.1 Compra (ingreso) | D24: 0.2 | E24: Dólares americanos | F24: =LOOKUP(G24,RANGOS!$A$2:$B$6) -> Muy baja | G24: 1 | H24: =LOOKUP(I24,RANGOS!$A$9:$B$13) -> Muy alto | I24: ='Data servicios'!G26 -> 5 | J24: =LOOKUP(K24,RANGOS!$F$2:$G$26) -> BAJO | K24: =G24*I24 -> 5 | L24: =$B$24*$D$24*AVERAGE(K24:K26) -> 0.3 | N24: =LOOKUP(O24,RANGOS!$A$16:$B$20) -> Muy bajo | O24: 1 | P24: =LOOKUP(Q24,RANGOS!$F$2:$G$26) -> BAJO | Q24: =K24/$O$24 -> 5 | R24: =$B$24*$D$24*AVERAGE(Q24:Q26) -> 0.3
E25: Euros | F25: =LOOKUP(G25,RANGOS!$A$2:$B$6) -> Muy baja | G25: 1 | H25: =LOOKUP(I25,RANGOS!$A$9:$B$13) -> Bajo | I25: ='Data servicios'!G27 -> 2 | J25: =LOOKUP(K25,RANGOS!$F$2:$G$26) -> BAJO | K25: =G25*I25 -> 2 | P25: =LOOKUP(Q25,RANGOS!$F$2:$G$26) -> BAJO | Q25: =K25/$O$24 -> 2
E26: Otros | F26: =LOOKUP(G26,RANGOS!$A$2:$B$6) -> Muy baja | G26: 1 | H26: =LOOKUP(I26,RANGOS!$A$9:$B$13) -> Bajo | I26: ='Data servicios'!G28 -> 2 | J26: =LOOKUP(K26,RANGOS!$F$2:$G$26) -> BAJO | K26: =G26*I26 -> 2 | P26: =LOOKUP(Q26,RANGOS!$F$2:$G$26) -> BAJO | Q26: =K26/$O$24 -> 2
C27: 2.2 Venta (salida) | D27: 0.2 | E27: Dólares americanos | F27: Media | G27: 1 | H27: =LOOKUP(I27,RANGOS!$A$9:$B$13) -> Bajo | I27: ='Data servicios'!G29 -> 2 | J27: =LOOKUP(K27,RANGOS!$F$2:$G$26) -> BAJO | K27: =G27*I27 -> 2 | L27: =$B$24*$D$27*AVERAGE(K27:K29) -> 0.3 | N27: =LOOKUP(O27,RANGOS!$A$16:$B$20) -> Muy bajo | O27: 1 | P27: =LOOKUP(Q27,RANGOS!$F$2:$G$26) -> BAJO | Q27: =K27/$O$27 -> 2 | R27: =$B$24*$D$27*AVERAGE(Q27:Q29) -> 0.3
E28: Euros | F28: =LOOKUP(G28,RANGOS!$A$2:$B$6) -> Muy baja | G28: 1 | H28: =LOOKUP(I28,RANGOS!$A$9:$B$13) -> Muy alto | I28: ='Data servicios'!G30 -> 5 | J28: =LOOKUP(K28,RANGOS!$F$2:$G$26) -> BAJO | K28: =G28*I28 -> 5 | P28: =LOOKUP(Q28,RANGOS!$F$2:$G$26) -> BAJO | Q28: =K28/$O$27 -> 5
E29: Otros | F29: =LOOKUP(G29,RANGOS!$A$2:$B$6) -> Muy baja | G29: 1 | H29: =LOOKUP(I29,RANGOS!$A$9:$B$13) -> Bajo | I29: ='Data servicios'!G31 -> 2 | J29: =LOOKUP(K29,RANGOS!$F$2:$G$26) -> BAJO | K29: =G29*I29 -> 2 | P29: =LOOKUP(Q29,RANGOS!$F$2:$G$26) -> BAJO | Q29: =K29/$O$27 -> 2
C30: 2.3 Medio | D30: 0.1 | E30: Con cargo en cuenta | F30: =LOOKUP(G30,RANGOS!$A$2:$B$6) -> Muy baja | G30: 1 | H30: =LOOKUP(I30,RANGOS!$A$9:$B$13) -> Muy alto | I30: ='Data servicios'!G32 -> 5 | J30: =LOOKUP(K30,RANGOS!$F$2:$G$26) -> BAJO | K30: =G30*I30 -> 5 | L30: =$B$24*$D$30*AVERAGE(K30:K31) -> 0.15 | N30: =LOOKUP(O30,RANGOS!$A$16:$B$20) -> Muy bajo | O30: 1 | P30: =LOOKUP(Q30,RANGOS!$F$2:$G$26) -> BAJO | Q30: =K30/$O$30 -> 5 | R30: =$B$24*$D$30*AVERAGE(Q30:Q31) -> 0.15
E31: Sin cargo en cuenta | F31: =LOOKUP(G31,RANGOS!$A$2:$B$6) -> Muy baja | G31: 1 | H31: =LOOKUP(I31,RANGOS!$A$9:$B$13) -> Muy bajo | I31: ='Data servicios'!G33 -> 1 | J31: =LOOKUP(K31,RANGOS!$F$2:$G$26) -> MUY BAJO | K31: =G31*I31 -> 1 | P31: =LOOKUP(Q31,RANGOS!$F$2:$G$26) -> MUY BAJO | Q31: =K31/$O$30 -> 1
C32: 2.4 Número de operaciones | D32: 0.15 | E32: < USD 5,000 | F32: =LOOKUP(G32,RANGOS!$A$2:$B$6) -> Muy baja | G32: 1 | H32: =LOOKUP(I32,RANGOS!$A$9:$B$13) -> Muy alto | I32: ='Data servicios'!G34 -> 5 | J32: =LOOKUP(K32,RANGOS!$F$2:$G$26) -> BAJO | K32: =G32*I32 -> 5 | L32: =$B$24*$D$32*AVERAGE(K32:K34) -> 0.2 | N32: =LOOKUP(O32,RANGOS!$A$16:$B$20) -> Muy bajo | O32: 1 | P32: =LOOKUP(Q32,RANGOS!$F$2:$G$26) -> BAJO | Q32: =K32/$O$32 -> 5 | R32: =$B$24*$D$32*AVERAGE(Q32:Q34) -> 0.2
E33: ≥ USD 5,000 < USD 10,000 | F33: =LOOKUP(G33,RANGOS!$A$2:$B$6) -> Muy baja | G33: 1 | H33: =LOOKUP(I33,RANGOS!$A$9:$B$13) -> Muy bajo | I33: ='Data servicios'!G35 -> 1 | J33: =LOOKUP(K33,RANGOS!$F$2:$G$26) -> MUY BAJO | K33: =G33*I33 -> 1 | P33: =LOOKUP(Q33,RANGOS!$F$2:$G$26) -> MUY BAJO | Q33: =K33/$O$32 -> 1
E34: ≥ USD 10,000 | F34: =LOOKUP(G34,RANGOS!$A$2:$B$6) -> Muy baja | G34: 1 | H34: =LOOKUP(I34,RANGOS!$A$9:$B$13) -> Bajo | I34: ='Data servicios'!G36 -> 2 | J34: =LOOKUP(K34,RANGOS!$F$2:$G$26) -> BAJO | K34: =G34*I34 -> 2 | P34: =LOOKUP(Q34,RANGOS!$F$2:$G$26) -> BAJO | Q34: =K34/$O$32 -> 2
C35: 2.5 Cuantía de la operación | D35: 0.15 | E35: < USD 5,000 | F35: =LOOKUP(G35,RANGOS!$A$2:$B$6) -> Muy baja | G35: 1 | H35: =LOOKUP(I35,RANGOS!$A$9:$B$13) -> Medio | I35: ='Data servicios'!G37 -> 3 | J35: =LOOKUP(K35,RANGOS!$F$2:$G$26) -> BAJO | K35: =G35*I35 -> 3 | L35: =$B$24*$D$35*AVERAGE(K35:K37) -> 0.225 | N35: =LOOKUP(O35,RANGOS!$A$16:$B$20) -> Muy bajo | O35: 1 | P35: =LOOKUP(Q35,RANGOS!$F$2:$G$26) -> BAJO | Q35: =K35/$O$35 -> 3 | R35: =$B$24*$D$35*AVERAGE(Q35:Q37) -> 0.225
E36: ≥ USD 5,000 < USD 10,000 | F36: =LOOKUP(G36,RANGOS!$A$2:$B$6) -> Muy baja | G36: 1 | H36: =LOOKUP(I36,RANGOS!$A$9:$B$13) -> Medio | I36: ='Data servicios'!G38 -> 3 | J36: =LOOKUP(K36,RANGOS!$F$2:$G$26) -> BAJO | K36: =G36*I36 -> 3 | P36: =LOOKUP(Q36,RANGOS!$F$2:$G$26) -> BAJO | Q36: =K36/$O$35 -> 3
E37: ≥ USD 10,000 | F37: =LOOKUP(G37,RANGOS!$A$2:$B$6) -> Muy baja | G37: 1 | H37: =LOOKUP(I37,RANGOS!$A$9:$B$13) -> Medio | I37: ='Data servicios'!G39 -> 3 | J37: =LOOKUP(K37,RANGOS!$F$2:$G$26) -> BAJO | K37: =G37*I37 -> 3 | P37: =LOOKUP(Q37,RANGOS!$F$2:$G$26) -> BAJO | Q37: =K37/$O$35 -> 3
C38: 2.6 Canal presencial | D38: 0.05 | E38: Ventanilla | F38: Alta | G38: 1 | H38: =LOOKUP(I38,RANGOS!$A$9:$B$13) -> Bajo | I38: ='Data servicios'!G40 -> 2 | J38: =LOOKUP(K38,RANGOS!$F$2:$G$26) -> BAJO | K38: =G38*I38 -> 2 | L38: =$B$24*$D$38*AVERAGE(K38:K39) -> 0.0875 | N38: =LOOKUP(O38,RANGOS!$A$16:$B$20) -> Muy bajo | O38: 1 | P38: =LOOKUP(Q38,RANGOS!$F$2:$G$26) -> BAJO | Q38: =K38/$O$38 -> 2 | R38: =$B$24*$D$38*AVERAGE(Q38:Q39) -> 0.0875
E39: Agentes | F39: =LOOKUP(G39,RANGOS!$A$2:$B$6) -> Muy baja | G39: 1 | H39: =LOOKUP(I39,RANGOS!$A$9:$B$13) -> Muy alto | I39: ='Data servicios'!G41 -> 5 | J39: =LOOKUP(K39,RANGOS!$F$2:$G$26) -> BAJO | K39: =G39*I39 -> 5 | P39: =LOOKUP(Q39,RANGOS!$F$2:$G$26) -> BAJO | Q39: =K39/$O$38 -> 5
C40: 2.7 Canal no presencial | D40: 0.05 | E40: Plataforma web | F40: =LOOKUP(G40,RANGOS!$A$2:$B$6) -> Muy baja | G40: 1 | H40: =LOOKUP(I40,RANGOS!$A$9:$B$13) -> Muy bajo | I40: ='Data servicios'!G42 -> 1 | J40: =LOOKUP(K40,RANGOS!$F$2:$G$26) -> MUY BAJO | K40: =G40*I40 -> 1 | L40: =$B$24*$D$40*AVERAGE(K40:K43) -> 0.0625 | N40: =LOOKUP(O40,RANGOS!$A$16:$B$20) -> Muy bajo | O40: 1 | P40: =LOOKUP(Q40,RANGOS!$F$2:$G$26) -> MUY BAJO | Q40: =K40/$O$40 -> 1 | R40: =$B$24*$D$40*AVERAGE(Q40:Q43) -> 0.0625
E41: ATM | F41: =LOOKUP(G41,RANGOS!$A$2:$B$6) -> Muy baja | G41: 1 | H41: =LOOKUP(I41,RANGOS!$A$9:$B$13) -> Medio | I41: ='Data servicios'!G43 -> 3 | J41: =LOOKUP(K41,RANGOS!$F$2:$G$26) -> BAJO | K41: =G41*I41 -> 3 | P41: =LOOKUP(Q41,RANGOS!$F$2:$G$26) -> BAJO | Q41: =K41/$O$40 -> 3
...

Sheet Data servicios
A1: ANÁLISIS DEL IMPACTO: SERVICIOS
A3: Periodo de análisis: De julio del 2014 a junio del 2015
A5: SUB FACTOR | B5: VARIABLE | C5: INDICADOR | D5: Registro | E5: Porcentaje | F5: IMPACTO
A6: 1. Remesas / Transferencia de fondos | B6: 1.1 Envío de dinero | C6: Nuevos soles | D6: 73733 | E6: =D6/SUM($D$6:$D$8) -> 0.82384161 | F6: =LOOKUP(E6,RANGOS!#REF!) -> #REF! | G6: =LOOKUP(E6,RANGOS!$I$2:$J$101) -> 5
C7: Dólares americanos | D7: 7383 | E7: =D7/SUM($D$6:$D$8) -> 0.082492542 | F7: =LOOKUP(E7,RANGOS!#REF!) -> #REF! | G7: =LOOKUP(E7,RANGOS!$I$2:$J$101) -> 2
C8: Euros | D8: 8383 | E8: =D8/SUM($D$6:$D$8) -> 0.093665851 | F8: =LOOKUP(E8,RANGOS!#REF!) -> #REF! | G8: =LOOKUP(E8,RANGOS!$I$2:$J$101) -> 2
B9: 1.2 Recepción de dinero | C9: Nuevos soles | D9: 6362 | E9: =D9/SUM($D$9:$D$11) -> 0.063288369 | F9: =LOOKUP(E9,RANGOS!#REF!) -> #REF! | G9: =LOOKUP(E9,RANGOS!$I$2:$J$101) -> 2
C10: Dólares americanos | D10: 8378 | E10: =D10/SUM($D$9:$D$11) -> 0.083343281 | F10: =LOOKUP(E10,RANGOS!#REF!) -> #REF! | G10: =LOOKUP(E10,RANGOS!$I$2:$J$101) -> 2
C11: Euros | D11: 85784 | E11: =D11/SUM($D$9:$D$11) -> 0.85336835 | F11: =LOOKUP(E11,RANGOS!#REF!) -> #REF! | G11: =LOOKUP(E11,RANGOS!$I$2:$J$101) -> 5
B12: 1.3 Medio | C12: Con cargo en cuenta | D12: 7474 | E12: =D12/SUM($D$12:$D$13) -> 0.089811221 | F12: =LOOKUP(E12,RANGOS!#REF!) -> #REF! | G12: =LOOKUP(E12,RANGOS!$I$2:$J$101) -> 2
C13: Sin cargo en cuenta | D13: 75745 | E13: =D13/SUM($D$12:$D$13) -> 0.91018878 | F13: =LOOKUP(E13,RANGOS!#REF!) -> #REF! | G13: =LOOKUP(E13,RANGOS!$I$2:$J$101) -> 5
B14: 1.4 Número de operaciones | C14: < USD 1,000 | D14: 8484 | E14: =D14/SUM($D$14:$D$16) -> 0.46108696 | F14: =LOOKUP(E14,RANGOS!#REF!) -> #REF! | G14: =LOOKUP(E14,RANGOS!$I$2:$J$101) -> 3
C15: ≥ USD 1,000 < USD 2,500 | D15: 9272 | E15: =D15/SUM($D$14:$D$16) -> 0.50391304 | F15: =LOOKUP(E15,RANGOS!#REF!) -> #REF! | G15: =LOOKUP(E15,RANGOS!$I$2:$J$101) -> 3
C16: ≥ USD 2,500 | D16: 644 | E16: =D16/SUM($D$14:$D$16) -> 0.035 | F16: =LOOKUP(E16,RANGOS!#REF!) -> #REF! | G16: =LOOKUP(E16,RANGOS!$I$2:$J$101) -> 1
B17: 1.5 Volumen transado en el periodo de análisis | C17: < USD 1,000 | D17: 73 | E17: =D17/SUM($D$17:$D$19) -> 0.0062806504 | F17: =LOOKUP(E17,RANGOS!#REF!) -> #REF! | G17: =LOOKUP(E17,RANGOS!$I$2:$J$101) -> 1
C18: ≥ USD 1,000 < USD 2,500 | D18: 3773 | E18: =D18/SUM($D$17:$D$19) -> 0.32461499 | F18: =LOOKUP(E18,RANGOS!#REF!) -> #REF! | G18: =LOOKUP(E18,RANGOS!$I$2:$J$101) -> 3
C19: ≥ USD 2,500 | D19: 7777 | E19: =D19/SUM($D$17:$D$19) -> 0.66910436 | F19: =LOOKUP(E19,RANGOS!#REF!) -> #REF! | G19: =LOOKUP(E19,RANGOS!$I$2:$J$101) -> 4
B20: 1.6 Canal presencial | C20: Ventanilla | D20: 8585 | E20: =D20/SUM($D$20:$D$21) -> 0.093246296 | F20: =LOOKUP(E20,RANGOS!#REF!) -> #REF! | G20: =LOOKUP(E20,RANGOS!$I$2:$J$101) -> 2
C21: Agentes | D21: 83483 | E21: =D21/SUM($D$20:$D$21) -> 0.9067537 | F21: =LOOKUP(E21,RANGOS!#REF!) -> #REF! | G21: =LOOKUP(E21,RANGOS!$I$2:$J$101) -> 5
B22: 1.7 Lugar de la operación | C22: Lima | D22: 774 | E22: =D22/SUM($D$22:$D$25) -> 0.0092330816 | F22: =LOOKUP(E22,RANGOS!#REF!) -> #REF! | G22: =LOOKUP(E22,RANGOS!$I$2:$J$101) -> 1
C23: Piura | D23: 8484 | E23: =D23/SUM($D$22:$D$25) -> 0.10120603 | F23: =LOOKUP(E23,RANGOS!#REF!) -> #REF! | G23: =LOOKUP(E23,RANGOS!$I$2:$J$101) -> 2
C24: Trujillo | D24: 73733 | E24: =D24/SUM($D$22:$D$25) -> 0.87956435 | F24: =LOOKUP(E24,RANGOS!#REF!) -> #REF! | G24: =LOOKUP(E24,RANGOS!$I$2:$J$101) -> 5
C25: Chiclayo | D25: 838 | E25: =D25/SUM($D$22:$D$25) -> 0.0099965406 | F25: =LOOKUP(E25,RANGOS!#REF!) -> #REF! | G25: =LOOKUP(E25,RANGOS!$I$2:$J$101) -> 1
A26: 2. Operaciones de cambio | B26: 2.1 Compra (ingreso) | C26: Dólares americanos | D26: 38833 | E26: =D26/SUM($D$26:$D$28) -> 0.72868348 | F26: =LOOKUP(E26,RANGOS!#REF!) -> #REF! | G26: =LOOKUP(E26,RANGOS!$I$2:$J$101) -> 5
C27: Euros | D27: 5884 | E27: =D27/SUM($D$26:$D$28) -> 0.11041057 | F27: =LOOKUP(E27,RANGOS!#REF!) -> #REF! | G27: =LOOKUP(E27,RANGOS!$I$2:$J$101) -> 2
C28: Otros | D28: 8575 | E28: =D28/SUM($D$26:$D$28) -> 0.16090595 | F28: =LOOKUP(E28,RANGOS!#REF!) -> #REF! | G28: =LOOKUP(E28,RANGOS!$I$2:$J$101) -> 2
B29: 2.2 Venta (salida) | C29: Dólares americanos | D29: 838 | E29: =D29/SUM($D$29:$D$31) -> 0.08158894 | F29: =LOOKUP(E29,RANGOS!#REF!) -> #REF! | G29: =LOOKUP(E29,RANGOS!$I$2:$J$101) -> 2
C30: Euros | D30: 8585 | E30: =D30/SUM($D$29:$D$31) -> 0.83584851 | F30: =LOOKUP(E30,RANGOS!#REF!) -> #REF! | G30: =LOOKUP(E30,RANGOS!$I$2:$J$101) -> 5
C31: Otros | D31: 848 | E31: =D31/SUM($D$29:$D$31) -> 0.082562555 | F31: =LOOKUP(E31,RANGOS!#REF!) -> #REF! | G31: =LOOKUP(E31,RANGOS!$I$2:$J$101) -> 2
B32: 2.3 Medio | C32: Con cargo en cuenta | D32: 56885 | E32: =D32/SUM($D$32:$D$33) -> 0.98982078 | F32: =LOOKUP(E32,RANGOS!#REF!) -> #REF! | G32: =LOOKUP(E32,RANGOS!$I$2:$J$101) -> 5
C33: Sin cargo en cuenta | D33: 585 | E33: =D33/SUM($D$32:$D$33) -> 0.010179224 | F33: =LOOKUP(E33,RANGOS!#REF!) -> #REF! | G33: =LOOKUP(E33,RANGOS!$I$2:$J$101) -> 1
B34: 2.4 Número de operaciones | C34: < USD 5,000 | D34: 83823 | E34: =D34/SUM($D$34:$D$36) -> 0.85278708 | F34: =LOOKUP(E34,RANGOS!#REF!) -> #REF! | G34: =LOOKUP(E34,RANGOS!$I$2:$J$101) -> 5
C35: ≥ USD 5,000 < USD 10,000 | D35: 5885 | E35: =D35/SUM($D$34:$D$36) -> 0.059872015 | F35: =LOOKUP(E35,RANGOS!#REF!) -> #REF! | G35: =LOOKUP(E35,RANGOS!$I$2:$J$101) -> 1
C36: ≥ USD 10,000 | D36: 8585 | E36: =D36/SUM($D$34:$D$36) -> 0.087340909 | F36: =LOOKUP(E36,RANGOS!#REF!) -> #REF! | G36: =LOOKUP(E36,RANGOS!$I$2:$J$101) -> 2
B37: 2.5 Cuantía de la operación | C37: < USD 5,000 | D37: 4774 | E37: =D37/SUM($D$37:$D$39) -> 0.24796136 | F37: =LOOKUP(E37,RANGOS!#REF!) -> #REF! | G37: =LOOKUP(E37,RANGOS!$I$2:$J$101) -> 3
C38: ≥ USD 5,000 < USD 10,000 | D38: 8584 | E38: =D38/SUM($D$37:$D$39) -> 0.44585259 | F38: =LOOKUP(E38,RANGOS!#REF!) -> #REF! | G38: =LOOKUP(E38,RANGOS!$I$2:$J$101) -> 3
