Workbook
Name Administración_de_Tasas_y_Tarifas: Parámetros!#REF!
Name Administración_patrimonial: Parámetros!#REF!
Name Administración_y_Canje_de_Cheques: Parámetros!#REF!
Name Adquisiciones: Parámetros!#REF!
Name Banca_corresponsal: Parámetros!#REF!
Name Captación_de_Productos: Parámetros!#REF!
Name CARACTERIZACION: [1]CARACTERIZACION!$F$3:$K$144
Name CAUSAL: [1]TABLAS!$H$3:$I$9
Name Clasificación_de_Cartera_y_Gestión_de_Provisiones: Parámetros!#REF!
Name Clientes: Parámetros!$E$6:$E$7
Name Clientes_productos_y_prácticas_empresariales: Parámetros!$N$14:$N$18
Name Colocaciones: Parámetros!$E$13:$E$17
Name Compensaciones_del_Colaborador: Parámetros!#REF!
Name Compra_de_Cartera: Parámetros!#REF!
Name Control_Interno: Parámetros!$E$59:$E$61
Name Control_Presupuestal: Parámetros!$E$5
Name Daños_a_activos_materiales: Parámetros!$N$20:$N$20
Name Desarrollo_de_Software: Parámetros!#REF!
Name Desarrollo_y_Administración_del_Presupuesto: Parámetros!#REF!
Name Ejecución_entrega_y_gestión_de_procesos: Parámetros!$N$24:$N$29
Name Fondeo: Parámetros!$E$8:$E$10
Name Fondeo_de_Recursos: Parámetros!#REF!
Name Fraude_externo: Parámetros!$N$7:$N$8
Name Fraude_interno: Parámetros!$N$4:$N$5
Name Gestión_Contable: Parámetros!#REF!
Name Gestión_de_Administración: Parámetros!$E$40:$E$44
Name Gestión_de_Auditoría_Interna: Parámetros!#REF!
Name Gestión_de_Calidad_y_Servicio_al_Cliente: Parámetros!#REF!
Name Gestion_de_Cobranzas_Empresas: Parámetros!#REF!
Name Gestión_de_Cobranzas_Personas: Parámetros!#REF!
Name Gestión_de_Cobranzas_y_Recuperaciones: Parámetros!$E$57:$E$58
Name Gestión_de_Contratos: Parámetros!#REF!
Name Gestión_de_Cumplimiento_Normativo: Parámetros!#REF!
Name Gestión_de_Depósitos: Parámetros!#REF!
Name Gestión_de_digitalización_de_files: Parámetros!#REF!
Name Gestión_de_Dinero_y_Valorados: Parámetros!#REF!
Name Gestión_de_Embargos: Parámetros!#REF!
Name Gestión_de_Garantías: Parámetros!#REF!
Name Gestión_de_Gastos_e_Ingresos: Parámetros!#REF!
Name Gestión_de_Infraestructura: Parámetros!#REF!
Name Gestión_de_la_Continuidad_del_Negocio: Parámetros!#REF!
Name Gestión_de_Marketing: Parámetros!#REF!
Name Gestión_de_Operaciones: Parámetros!$E$45:$E$50
Name Gestión_de_Operaciones_de_TI: Parámetros!#REF!
Name Gestión_de_Planeamiento_Estratégico: Parámetros!#REF!
Name Gestión_de_Poderes: Parámetros!#REF!
Name Gestión_de_Prevención_de_Lavado_de_Activos: Parámetros!#REF!
Name Gestión_de_Procesos: Parámetros!$E$38:$E$39
Name Gestión_de_Procesos_Legales: Parámetros!#REF!
Name Gestión_de_Riesgo_Crediticio_y_Cambiario: Parámetros!#REF!
Name Gestión_de_Riesgo_Operacional: Parámetros!#REF!
Name Gestión_de_Riesgos: Parámetros!$E$22:$E$29
Name Gestión_de_RRHH: Parámetros!$E$35:$E$37
Name Gestión_de_Seguridad_de_la_Información: Parámetros!#REF!
Name Gestión_de_Seguros: Parámetros!#REF!
Name Gestión_de_Servicios_asociados_a_la_Banca_x_internet: Parámetros!#REF!
Name Gestión_de_Servicios_internos: Parámetros!#REF!
Name Gestión_de_Tecnología_de_Información: Parámetros!$E$51:$E$52
Name Gestión_de_Transferencias: Parámetros!#REF!
Name Gestión_del_Colaborador: Parámetros!#REF!

Sheet Matriz de Riesgos
A1: Medición de Riesgos, Controles y Tratamiento
A4: Empresa | D4: XXXXXXXX
A5: Fecha de Elaboración | D5: XXXXXXXX
G6: RIESGO INHERENTE | N6: IDENTIFICACIÓN DE CONTROLES | Q6: DISEÑO | U6: EJECUCION | AF6: RIESGO RESIDUAL | AM6: TRATAMIENTO
A7: Id Riesgo | B7: División/Área | C7: Proceso | D7: Nombre Riesgo | E7: Detalle Riesgo | F7: Factor | G7: Criterio Frecuencia | H7: Sustento Frecuencia | I7: Probabilidad de ocurrencia | J7: Criterio Impacto | K7: Impacto | L7: Sustento Impacto | M7: Nivel de Riesgo | N7: DescripcionControl | O7: Clasificación | P7: AreaEjecución | Q7: Periodicidad | R7: Naturaleza del control (Manual / Automático) | S7: TipoControl | T7: Supervisión | U7: Oportuno | V7: Adecuado | W7: Disminuye | AD7: % de Mitigación | AE7: Calificación del Control | AF7: Criterio Frecuencia | AG7: Probabilidad de Ocurrencia | AI7: Criterio Impacto | AJ7: Impacto | AK7: Exposición Residual | AL7: Nivel de Riesgo | AM7: Plan de Acción | AN7: Área Responsable del Plan de Acción | AO7: Fecha inicio de implementación | AP7: Fecha fin de implementación | AQ7: Criterio Probabilidad & Criterio Impacto
A8: R01 | B8: Ventas | C8: Nuevos Servicios | D8: Soborno a funcionarios públicos | E8: El soborno, o coima, es un acto de corrupción en el que se otorga o recibe una dádiva a cambio de un favor u omisión de las obligaciones a las que está sujeta el cargo. Esta dádiva puede adoptar formas diversas: dinero en efectivo, transferencia de acciones, favores sexuales o promesas diversas (Anwar, 2006; UNODC, 2004). | F8: Procesos | G8: =IF(H8="","",VLOOKUP(H8,Parámetros!$X$56:$Y$60,2,FALSE)) -> Baja | H8: Se produce 1 vez cada 3 años | I8: =IF(H8="","",VLOOKUP(H8,Parámetros!$X$56:$AA$60,4,FALSE)) -> 0.099 | J8: =IF(K8=Parámetros!W2,Parámetros!V2,IF(K8=Parámetros!W3,Parámetros!V3,IF(K8=Parámetros!W4,Parámetros!V4,IF(K8=Parámetros!W5,Parámetros!V5,IF(K8=Parámetros!W6,Parámetros!V6,"error"))))) -> Moderado | K8: Pérdida entre S/. 200,000 y S/. 850,000 | L8: =VLOOKUP(K8,Parámetros!$W$2:$Y$6,3,FALSE) -> Reputacional - Mención en medios de prensa sin mayor cobertura, afectación de la imagen en grupos de interés y clientes principales (reparable en no menos de 3 meses). Clientes - Incumplimiento regulatorio con multas mayores a 50 UITs. Demandas legales por parte de terceros (clientes, proveedores) y daños a la empresa. | M8: =+INDEX(Parámetros!$W$13:$AA$17,VLOOKUP(G8,Parámetros!$U$13:$V$17,2,FALSE),HLOOKUP(J8,Parámetros!$W$11:$AA$12,2,FALSE)) -> Bajo | N8: Agregar cláusulas de corrupción en los contratos con los tramitadores que actúan a nombre de la empresa. | O8: Contratos y disclaimers | P8: Operaciones | Q8: Permanente | R8: Automático | S8: Preventivo | T8: Nivel 2 Analista / Coordinador | U8: Si | V8: Si | W8: Impacto | X8: =+VLOOKUP(Q8,Parámetros!$AC$3:$AD$5,2,FALSE) -> 1 | Y8: =VLOOKUP(R8,Parámetros!$AF$3:$AG$5,2,FALSE) -> 1 | Z8: =VLOOKUP(S8,Parámetros!$AI$3:$AJ$4,2,FALSE) -> 1 | AA8: =VLOOKUP(T8,Parámetros!$AO$3:$AP$5,2,FALSE) -> 0.7 | AB8: =VLOOKUP(U8,Parámetros!$AR$2:$AS$4,2,FALSE) -> 1 | AC8: =VLOOKUP(V8,Parámetros!$AR$2:$AS$4,2,FALSE) -> 1 | AD8: =+(X8*0.2+Y8*0.2+Z8*0.2)*(AB8*0.5+AC8*0.5) -> 0.6 | AE8: =+IF(AD8<0.9,IF(AD8<0.6,IF(AD8>0.3,"Moderado","Insastisfactorio"),"Bueno"),"Excelente") -> Bueno | AF8: =IF(AG8="","",IF(AG8<=Parámetros!$R$11,IF(AG8<=Parámetros!$R$12,IF(AG8<=Parámetros!$R$13,IF(AG8<=Parámetros!$R$14,"Muy Baja","Baja"),"Media"),"Alta"),"Muy Alta")) -> Muy Baja | AG8: =IF(AD8="",I8,(I8*(1-AD8))) -> 0.0396 | AH8: =VLOOKUP(K8,Parámetros!$W$2:$X$6,2,FALSE) -> 850000 | AI8: =IF(AJ8="","",IF(AJ8>Parámetros!$T$7,IF(AJ8>Parámetros!$T$6,IF(AJ8>Parámetros!$T$5,IF(AJ8>Parámetros!$T$4,"Catastrófico","Mayor"),"Moderado"),"Menor"),"Insignificante")) -> Moderado | AJ8: =+IF(AD8="",AH8,ROUND(AH8*(1-AD8),1)) -> 340000 | AK8: =+IF(AG8="","",AG8*AJ8) -> 13464 | AL8: =+INDEX(Parámetros!$W$13:$AA$17,VLOOKUP(AF8,Parámetros!$U$13:$V$17,2,FALSE),HLOOKUP(AI8,Parámetros!$W$11:$AA$12,2,FALSE)) -> Bajo | AQ8: =+AF8&"-"&AI8 -> Muy Baja-Moderado
A9: R02 | B9: Infraestructura y Logística | C9: Adquisiciones | D9: Colusiones (internas, de terceros, con terceros) | E9: Abuso de posición personal, ventaja indebida. | F9: Eventos externos | G9: =IF(H9="","",VLOOKUP(H9,Parámetros!$X$56:$Y$60,2,FALSE)) -> Baja | H9: Se produce 1 vez cada 3 años | I9: =IF(H9="","",VLOOKUP(H9,Parámetros!$X$56:$AA$60,4,FALSE)) -> 0.099 | J9: =IF(K9=Parámetros!W3,Parámetros!V3,IF(K9=Parámetros!W4,Parámetros!V4,IF(K9=Parámetros!W5,Parámetros!V5,IF(K9=Parámetros!W6,Parámetros!V6,IF(K9=Parámetros!W7,Parámetros!V7,"error"))))) -> Catastrófico | K9: Pérdida superior a S/. 1’700,000 | L9: =VLOOKUP(K9,Parámetros!$W$2:$Y$6,3,FALSE) -> Reputacional - Cobertura adversa de amplia difusión en medios a nivel nacional, internacional y redes sociales. Afecta gravemente la imagen de la empresa y genera pérdida de clientes principales y socios estratégicos. Clientes - Incumplimiento regulatorio con multas mayores a 420 UITs. Acciones legales que conllevan a la prisión efectiva de directores, gerentes o funcionarios. | M9: =+INDEX(Parámetros!$W$13:$AA$17,VLOOKUP(G9,Parámetros!$U$13:$V$17,2,FALSE),HLOOKUP(J9,Parámetros!$W$11:$AA$12,2,FALSE)) -> Medio | N9: Capacitaciones para los tramitadores y proveedores en general en temas relacionados a anticorrupción | O9: Políticas | P9: Créditos | Q9: Periódico | R9: Automático | S9: Detectivo | T9: Nivel 2 Analista / Coordinador | U9: Si | V9: Si | W9: Frecuencia | X9: =+VLOOKUP(Q9,Parámetros!$AC$3:$AD$5,2,FALSE) -> 0.7 | Y9: =VLOOKUP(R9,Parámetros!$AF$3:$AG$5,2,FALSE) -> 1 | Z9: =VLOOKUP(S9,Parámetros!$AI$3:$AJ$4,2,FALSE) -> 0.5 | AA9: =VLOOKUP(T9,Parámetros!$AO$3:$AP$5,2,FALSE) -> 0.7 | AB9: =VLOOKUP(U9,Parámetros!$AR$2:$AS$4,2,FALSE) -> 1 | AC9: =VLOOKUP(V9,Parámetros!$AR$2:$AS$4,2,FALSE) -> 1 | AD9: =+(X9*0.2+Y9*0.2+Z9*0.2)*(AB9*0.5+AC9*0.5) -> 0.44 | AE9: =+IF(AD9<0.9,IF(AD9<0.6,IF(AD9>0.3,"Moderado","Insastisfactorio"),"Bueno"),"Excelente") -> Moderado | AF9: =IF(AG9="","",IF(AG9<=Parámetros!$R$11,IF(AG9<=Parámetros!$R$12,IF(AG9<=Parámetros!$R$13,IF(AG9<=Parámetros!$R$14,"Muy Baja","Baja"),"Media"),"Alta"),"Muy Alta")) -> Baja | AG9: =IF(AD9="",I9,(I9*(1-AD9))) -> 0.05544 | AH9: =VLOOKUP(K9,Parámetros!$W$2:$X$6,2,FALSE) -> 1700000 | AI9: =IF(AJ9="","",IF(AJ9>Parámetros!$T$7,IF(AJ9>Parámetros!$T$6,IF(AJ9>Parámetros!$T$5,IF(AJ9>Parámetros!$T$4,"Catastrófico","Mayor"),"Moderado"),"Menor"),"Insignificante")) -> Mayor | AJ9: =+IF(AD9="",AH9,ROUND(AH9*(1-AD9),1)) -> 952000 | AK9: =+IF(AG9="","",AG9*AJ9) -> 52778.88 | AL9: =+INDEX(Parámetros!$W$13:$AA$17,VLOOKUP(AF9,Parámetros!$U$13:$V$17,2,FALSE),HLOOKUP(AI9,Parámetros!$W$11:$AA$12,2,FALSE)) -> Medio | AQ9: =+AF9&"-"&AI9 -> Baja-Mayor

Sheet Parámetros
B1: PROCESOS | N1: TIPO DE EVENTO | R1: Criterio de IMPACTO | V1: Impacto | W1: Descripción - Financiero | X1: Límite superior | Y1: Sustento Impacto | Z1: Descripción - Reputacional | AA1: Descripción - Clientes
B2: ID | C2: División/Área | E2: Proceso | H2: Tipo | I2: Divisón/Área | J2: Proceso | L2: NIVEL 1 | N2: NIVEL 2 | R2: Impacto | S2: Límite inferior | T2: Límite superior | V2: Insignificante | W2: Pérdida menor a S/. 30,000 | X2: 30000 | Y2: Reputacional - Sólo de conocimiento interno de la empresa, puede impactar en ambiente laboral. Clientes - Notificaciones legales o de entes reguladores, sin efectos monetarios. | Z2: Sólo de conocimiento interno de la empresa, puede impactar en ambiente laboral | AA2: Notificaciones legales o de entes reguladores, sin efectos monetarios | AC2: Periodicidad | AD2: Valor | AF2: Operatividad | AG2: Valor | AI2: Tipo de Control | AJ2: Valor | AL2: Segregación | AM2: Valor | AO2: Supervisión | AP2: Valor | AR2: Diseño | AS2: Valor
B3: 1 | C3: Marketing | E3: Gestión de Planeamiento Estratégico | H3: E | I3: 1 | J3: 1 | K3: =CONCATENATE(I3,J3) -> 11 | L3: Fraude interno | N3: Fraude interno | R3: Catastrófico | S3: =+T4+0.01 -> 1700000 | T3: =+S3+1000000 -> 2700000 | V3: Menor | W3: Pérdida entre S/. 30,000 y S/. 200,000 | X3: 200000 | Y3: Reputacional - Conocimiento en grupos de interés locales, afectación de la imagen ante clientes menores. Clientes - Incumplimiento regulatorio con multas de hasta 50 IUTs. Demandas legales menores por parte de terceros, conciliaciones, arbitrajes menores. | Z3: Conocimiento en grupos de interés locales, afectación de la imagen ante clientes menores | AA3: Incumplimiento regulatorio con multas de hasta 50 IUTs. Demandas legales menores por parte de terceros, conciliaciones, arbitrajes menores | AC3: Permanente | AD3: 1 | AF3: Automático | AG3: 1 | AI3: Preventivo | AJ3: 1 | AL3: Otra área o automático | AM3: 1 | AO3: Nivel 3 Directivo o Automático | AP3: 1 | AR3: SI | AS3: 1
B4: 2 | C4: Reclamos | E4: Gestión de Marketing | H4: E | I4: 1 | J4: 2 | K4: =CONCATENATE(I4,J4) -> 12 | L4: Fraude externo | N4: Actividades no autorizadas | R4: Mayor | S4: =+T5+0.01 -> 850000.01 | T4: 1700000 | V4: Moderado | W4: Pérdida entre S/. 200,000 y S/. 850,000 | X4: 850000 | Y4: Reputacional - Mención en medios de prensa sin mayor cobertura, afectación de la imagen en grupos de interés y clientes principales (reparable en no menos de 3 meses). Clientes - Incumplimiento regulatorio con multas mayores a 50 UITs. Demandas legales por parte de terceros (clientes, proveedores) y daños a la empresa. | Z4: Mención en medios de prensa sin mayor cobertura, afectación de la imagen en grupos de interés y clientes principales (reparable en no menos de 3 meses) | AA4: Incumplimiento regulatorio con multas mayores a 50 UITs. Demandas legales por parte de terceros (clientes, proveedores) y daños a la empresa | AC4: Periódico | AD4: 0.7 | AF4: Semiautomático | AG4: 0.7 | AI4: Detectivo | AJ4: 0.5 | AL4: Misma área | AM4: 0.7 | AO4: Nivel 2 Analista / Coordinador | AP4: 0.7 | AR4: NO | AS4: 0
B5: 3 | C5: Servicio al cliente | E5: Desarrollo y Administración del Presupuesto | H5: E | I5: 1 | J5: 2 | K5: =CONCATENATE(I5,J5) -> 12 | L5: Relaciones laborales y seguridad en el puesto de trabajo | N5: Robo y fraude | R5: Moderado | S5: =+T6+0.01 -> 200000.01 | T5: 850000 | V5: Mayor | W5: Pérdida entre S/. 850,000 y S/. 1’700,000 | X5: 1700000 | Y5: Reputacional - Cobertura adversa de amplia difusión en medios locales, afecta altamente la imagen con grupos de interés y clientes principales (reparable en no menos de 6 meses). Clientes - IIncumplimiento regulatorio con multas mayores a 210 UITs. Condena en procesos legales sobre directores, gerentes o funcionarios, que no implique prisión efectiva. | Z5: Cobertura adversa de amplia difusión en medios locales, afecta altamente la imagen con grupos de interés y clientes principales (reparable en no menos de 6 meses) | AA5: Incumplimiento regulatorio con multas mayores a 210 UITs. Condena en procesos legales sobre directores, gerentes o funcionarios, que no implique prisión efectiva | AC5: Eventual | AD5: 0.3 | AF5: Manual | AG5: 0.3 | AL5: Mismo Funcionario | AM5: 0.3 | AO5: Nivel 1 Operativo | AP5: 0.3
B6: 4 | C6: Ventas | E6: Nuevos productos | H6: E | I6: 1 | J6: 2 | K6: =CONCATENATE(I6,J6) -> 12 | L6: Clientes, productos y prácticas empresariales | N6: Fraude externo | R6: Menor | S6: =+T7+0.01 -> 30000.01 | T6: 200000 | V6: Catastrófico | W6: Pérdida superior a S/. 1’700,000 | X6: 1700000 | Y6: Reputacional - Cobertura adversa de amplia difusión en medios a nivel nacional, internacional y redes sociales. Afecta gravemente la imagen de la empresa y genera pérdida de clientes principales y socios estratégicos. Clientes - Incumplimiento regulatorio con multas mayores a 420 UITs. Acciones legales que conllevan a la prisión efectiva de directores, gerentes o funcionarios. | Z6: Cobertura adversa de amplia difusión en medios a nivel nacional, internacional y redes sociales. Afecta gravemente la imagen de la empresa y genera pérdida de clientes principales y socios estratégicos | AA6: Incumplimiento regulatorio con multas mayores a 420 UITs. Acciones legales que conllevan a la prisión efectiva de directores, gerentes o funcionarios
B7: 5 | C7: Infraestructura y Logística | E7: Gestión de Calidad y Servicio al Cliente | H7: E | I7: 1 | J7: 2 | K7: =CONCATENATE(I7,J7) -> 12 | L7: Daños a activos materiales | N7: Robo y fraude | R7: Insignificante | S7: 0 | T7: 30000
B8: 6 | C8: Pagos | E8: Captación de Productos | H8: E | I8: 1 | J8: 2 | K8: =CONCATENATE(I8,J8) -> 12 | L8: Interrupción del negocio y fallos en los sistemas | N8: Seguridad de los sistemas
B9: 7 | C9: Créditos | E9: Nuevos Servicios | H9: E | I9: 2 | J9: 1 | K9: =CONCATENATE(I9,J9) -> 21 | L9: Ejecución, entrega y gestión de procesos | N9: Relaciones laborales y seguridad en el puesto de trabajo | P9: Probabilidad | Q9: % Inferior | R9: % Superior
B10: 8 | C10: Riesgos | E10: Fondeo de Recursos | H10: C | I10: 1 | J10: 1 | K10: =CONCATENATE(I10,J10) -> 11 | N10: Relaciones laborales | P10: Muy Alta | R10: 1 | W10: IMPACTO
B11: 9 | C11: Legal | E11: Gestión de Proveedores | H11: C | I11: 1 | J11: 1 | K11: =CONCATENATE(I11,J11) -> 11 | N11: Higiene y seguridad en el trabajo | P11: Alta | Q11: 0.3 | R11: 0.999 | W11: Insignificante | X11: Menor | Y11: Moderado | Z11: Mayor | AA11: Catastrófico
B12: 10 | C12: RRHH | E12: Gestión de Contrapartes | H12: C | I12: 1 | J12: 1 | K12: =CONCATENATE(I12,J12) -> 11 | N12: Diversidad y discriminación | P12: Media | Q12: 0.1 | R12: 0.299 | W12: 1 | X12: 2 | Y12: 3 | Z12: 4 | AA12: 5
B13: 11 | C13: Procesos | E13: Otorgamiento de Créditos | H13: C | I13: 1 | J13: 2 | K13: =CONCATENATE(I13,J13) -> 12 | N13: Clientes, productos y prácticas empresariales | P13: Baja | Q13: 0.05 | R13: 0.099 | T13: FRECUENCIA | U13: Muy Alta | V13: 1 | W13: Medio | X13: Medio | Y13: Alto | Z13: Extremo | AA13: Extremo
B14: 12 | C14: Administración | E14: Selección de personal | H14: C | I14: 1 | J14: 2 | K14: =CONCATENATE(I14,J14) -> 12 | N14: Adecuación, divulgación de información y confianza | P14: Muy Baja | Q14: 0 | R14: 0.049 | U14: Alta | V14: 2 | W14: Bajo | X14: Medio | Y14: Medio | Z14: Alto | AA14: Extremo
B15: 13 | C15: Operaciones | E15: Gestión de Garantías | H15: C | I15: 1 | J15: 2 | K15: =CONCATENATE(I15,J15) -> 12 | N15: Prácticas empresariales o de mercado improcedentes | U15: Media | V15: 3 | W15: Bajo | X15: Bajo | Y15: Medio | Z15: Medio | AA15: Alto
B16: 14 | C16: Tecnología de Información | E16: Gestión de Logística | H16: C | I16: 1 | J16: 2 | K16: =CONCATENATE(I16,J16) -> 12 | N16: Productos defectuosos | U16: Baja | V16: 4 | W16: Muy Bajo | X16: Bajo | Y16: Bajo | Z16: Medio | AA16: Medio
B17: 15 | C17: Financiera y Contable | E17: Servicios tercerizados | H17: C | I17: 1 | J17: 2 | K17: =CONCATENATE(I17,J17) -> 12 | N17: Selección, patrocinio y riesgos | P17: Clasificacion de Controles | U17: Muy Baja | V17: 5 | W17: Muy Bajo | X17: Muy Bajo | Y17: Bajo | Z17: Bajo | AA17: Medio
B18: 16 | C18: Gestión de Cobranzas y Recuperaciones | E18: Productos tercerizados | H18: C | I18: 2 | J18: 1 | K18: =CONCATENATE(I18,J18) -> 21 | N18: Actividades de asesoramiento
B19: 17 | C19: Auditoría | E19: Gestión de Pagos | H19: C | I19: 2 | J19: 1 | K19: =CONCATENATE(I19,J19) -> 21 | N19: Daños a activos materiales | P19: Contratos y disclaimers | W19: =+T7 -> 30000 | X19: =+T6 -> 200000 | Y19: =+T5 -> 850000 | Z19: =+T4 -> 1700000 | AA19: =+T3 -> 2700000
E20: Gestión de Seguros | H20: C | I20: 2 | J20: 1 | K20: =CONCATENATE(I20,J20) -> 21 | N20: Desastres y otros acontecimientos | P20: Revisión y seguimiento | W20: 1.17 | X20: 4.33 | Y20: 12.95 | Z20: 36.36 | AA20: 100
C21: Factor | E21: Recaudación | H21: C | I21: 2 | J21: 1 | K21: =CONCATENATE(I21,J21) -> 21 | N21: Interrupción del negocio y fallos en los sistemas | P21: Capacitación terceros | V21: 1 | W21: =+V21*$W$19 -> 30000 | X21: =+V21*$X$19 -> 200000 | Y21: =+V21*$Y$19 -> 850000 | Z21: =+V21*$Z$19 -> 1700000 | AA21: =+V21*$AA$19 -> 2700000
C22: Personas | E22: Conflicto de Interés | H22: C | I22: 2 | J22: 2 | K22: =CONCATENATE(I22,J22) -> 22 | N22: Sistemas | P22: Capacitación interna | V22: 0.8 | W22: =+V22*$W$19 -> 24000 | X22: =+V22*$X$19 -> 160000 | Y22: =+V22*$Y$19 -> 680000 | Z22: =+V22*$Z$19 -> 1360000 | AA22: =+V22*$AA$19 -> 2160000
C23: Procesos | E23: Tolerancia cero | H23: C | I23: 2 | J23: 2 | K23: =CONCATENATE(I23,J23) -> 22 | N23: Ejecución, entrega y gestión de procesos | P23: Políticas | V23: 0.6 | W23: =+V23*$W$19 -> 18000 | X23: =+V23*$X$19 -> 120000 | Y23: =+V23*$Y$19 -> 510000 | Z23: =+V23*$Z$19 -> 1020000 | AA23: =+V23*$AA$19 -> 1620000 | AC23: Paso 1
C24: Tecnología | E24: Mesa de partes / Recepción | H24: C | I24: 2 | J24: 2 | K24: =CONCATENATE(I24,J24) -> 22 | N24: Recepción, ejecución y mantenimiento de operaciones | P24: Colaboradores | V24: 0.4 | W24: =+V24*$W$19 -> 12000 | X24: =+V24*$X$19 -> 80000 | Y24: =+V24*$Y$19 -> 340000 | Z24: =+V24*$Z$19 -> 680000 | AA24: =+V24*$AA$19 -> 1080000
C25: Eventos externos | E25: Clasificación de Clientes | H25: C | I25: 2 | J25: 2 | K25: =CONCATENATE(I25,J25) -> 22 | N25: Seguimiento y presentación de informes | P25: Terceros | V25: 0.2 | W25: =+V25*$W$19 -> 6000 | X25: =+V25*$X$19 -> 40000 | Y25: =+V25*$Y$19 -> 170000 | Z25: =+V25*$Z$19 -> 340000 | AA25: =+V25*$AA$19 -> 540000
E26: Código de Conducta | H26: C | I26: 2 | J26: 3 | K26: =CONCATENATE(I26,J26) -> 23 | N26: Aceptación de clientes y documentación | P26: Selección de personal
E27: Gestión de Riesgo Operacional | H27: C | I27: 2 | J27: 3 | K27: =CONCATENATE(I27,J27) -> 23 | N27: Gestión de cuentas de clientes | P27: Denuncias
C28: Riesgo de Interrupción | E28: Gestión de Seguridad de la Información | H28: C | I28: 3 | J28: 1 | K28: =CONCATENATE(I28,J28) -> 31 | N28: Contrapartes comerciales | P28: Procedimientos | Z28: Capacidad: | AA28: 2C1
C29: TRUE | E29: Gestión del Riesgo Ambiental | H29: C | I29: 3 | J29: 1 | K29: =CONCATENATE(I29,J29) -> 31 | N29: Distribuidores y proveedores | P29: Revisiones y seguimiento | Z29: Apetito: | AA29: 7200744
C30: FALSE | E30: Gestión Secretaría General | H30: C | I30: 3 | J30: 1 | K30: =CONCATENATE(I30,J30) -> 31 | Z30: Tolerancia:
E31: Gestión de Contratos | H31: C | I31: 3 | J31: 2 | K31: =CONCATENATE(I31,J31) -> 32
E32: Gestión de Poderes | H32: C | I32: 3 | J32: 2 | K32: =CONCATENATE(I32,J32) -> 32
C33: IMPACTO | E33: Gestión de Procesos Legales | H33: C | I33: 4 | J33: 1 | K33: =CONCATENATE(I33,J33) -> 41 | P33: Areas
C34: FRECUENCIA | E34: Gestión de Embargos | H34: C | I34: 4 | J34: 1 | K34: =CONCATENATE(I34,J34) -> 41 | AC34: Paso 2
C35: AMBOS | E35: Reclutamiento y selección de personal | H35: C | I35: 4 | J35: 1 | K35: =CONCATENATE(I35,J35) -> 41 | P35: ADMINISTRACION / LEGAL
E36: Gestión del Colaborador | H36: C | I36: 4 | J36: 1 | K36: =CONCATENATE(I36,J36) -> 41 | P36: CUMPLIMIENTO
E37: Compensaciones del Colaborador | H37: C | I37: 4 | J37: 1 | K37: =CONCATENATE(I37,J37) -> 41 | P37: RRHH | W37: 84248.705 | X37: 311792.22 | Y37: 932496.35 | Z37: 2618190.5 | AA37: 7200744
C38: Medidas de Tratamiento | E38: Gestión Normativa | H38: C | I38: 4 | J38: 1 | K38: =CONCATENATE(I38,J38) -> 41 | P38: PROCESOS | W38: 67398.964 | X38: 249433.77 | Y38: 745997.08 | Z38: 2094552.4 | AA38: 5760595.2
C39: Evitar | E39: Proceso de atención de proyectos y requerimientos | H39: C | I39: 4 | J39: 1 | K39: =CONCATENATE(I39,J39) -> 41 | P39: ADMINISTRACION | W39: 50549.223 | X39: 187075.33 | Y39: 559497.81 | Z39: 1570914.3 | AA39: 4320446.4
C40: Transferir | E40: Adquisiciones | H40: C | I40: 4 | J40: 1 | K40: =CONCATENATE(I40,J40) -> 41 | P40: LEGAL | W40: 33699.482 | X40: 124716.89 | Y40: 372998.54 | Z40: 1047276.2 | AA40: 2880297.6
...

Sheet Mapa de calor
E2: INHERENTE | N2: RESIDUAL
E5: IMPACTO | N5: IMPACTO
E6: Insignificante | F6: Menor | G6: Moderado | H6: Mayor | I6: Catastrófico | N6: Insignificante | O6: Menor | P6: Moderado | Q6: Mayor | R6: Catastrófico
B8: FRECUENCIA | C8: Muy Alta | K8: FRECUENCIA | L8: Muy Alta
C9: Alta | L9: Alta
C10: Media | L10: Media
C11: Baja | L11: Baja
C12: Muy Baja | L12: Muy Baja
E15: Muy Bajo | F15: 0 | N15: Muy Bajo | O15: 0
E16: Bajo | F16: 0 | N16: Bajo | O16: 1
E17: Medio | F17: 1 | N17: Medio | O17: 1
E18: Alto | F18: 0 | N18: Alto | O18: 0
E19: Extremo | F19: 1 | N19: Extremo | O19: 0

Sheet Multas
B2: ESTIMACIÓN ECONÓMICA
B4: IdRiesgo | C4: 21 | D4: 22 | G4: Nombre Riesgo | H4: =+VLOOKUP(C4,'Matriz de Riesgos'!$A$7:$F$505,7,FALSE) -> #N/A
B5: Riesgo: | C5: =+VLOOKUP(C4,'Matriz de Riesgos'!$A$7:$F$505,8,FALSE) -> #N/A
B7: Variables consideradas: | F7: Supuestos:
B9: - Monto de UIT | D9: 4150 | F9: - Supuesto 1: | G9: Ingreso anual PJ asciende hasta 150 UIT
B10: - N° de UIT | D10: 6 | F10: - Supuesto 2: | G10: Ingreso anual PJ asciende hasta 1,700 UIT
B11: - N° de meses | D11: 9 | F11: - Supuesto 3: | G11: Ingreso anual PJ asciende monto mayor 1,700 UIT
F12: - Supuesto 4:
F13: - Supuesto 5:
B14: Método de cáculo
B16: Importe Estimado: | D16: =+D10*D9*D11 -> 224100
B19: IdRiesgo | C19: 23 | G19: Nombre Riesgo | H19: =+VLOOKUP(C19,'Matriz de Riesgos'!$A$7:$F$505,7,FALSE) -> #N/A
B20: Riesgo: | C20: =+VLOOKUP(C19,'Matriz de Riesgos'!$A$7:$F$505,8,FALSE) -> #N/A
B22: Variables consideradas: | F22: Supuestos:
B24: - Monto de UIT | D24: 4150 | F24: - Supuesto 1: | G24: Ingreso anual PJ asciende hasta 150 UIT
B25: - N° de UIT | D25: 4 | F25: - Supuesto 2: | G25: Ingreso anual PJ asciende hasta 1,700 UIT
B26: - N° de meses | D26: 12 | F26: - Supuesto 3: | G26: Ingreso anual PJ asciende monto mayor 1,700 UIT
F27: - Supuesto 4:
F28: - Supuesto 5:
B29: Método de cáculo
B31: Importe Estimado: | D31: =D24*D25*D26 -> 199200

Sheet Eventos
B3: Código de Evento | C3: Ciudad del Evento | D3: Fecha de registro | E3: Fecha Ocurrencia | F3: Fecha Detección | G3: Descripción breve del evento | H3: Decripción detalle del evento | I3: Línea de Negocio Nivel 1 | J3: Código Línea de Negocio Nivel 1 | K3: Línea de Negocio Nivel 2 | L3: Código Línea de Negocio Nivel 2 | M3: Código Causal de Riesgo Operativo (SARO) | N3: Tipo de Evento de Pérdida Nivel 1 | O3: Código de Tipo de Evento de Pérdida Nivel 2 | P3: Tipo de Evento de Pérdida Nivel 2 | Q3: Código Subcausal de Riesgo Operativo (SARO) | R3: Subcausal de Riesgo (SARO) | S3: Código del Proceso de Riesgo Operacional | T3: Procesos de Riesgo Operacional | U3: Procesos de Riesgo Operacional | V3: Tipo de Producto Según SBS Nivel 1 (automático) | W3: División/ÁREA | X3: Proceso Asociado al evento | Y3: Moneda Original del Evento | Z3: Pérdida Bruta | AA3: Monto Total de Pérdida Bruta (PEN) | AB3: Fecha Registro Contable | AC3: Diario (Asiento) | AD3: # Cuenta Contable | AE3: Centro de Costo | AF3: Tipo Recupero | AG3: Monto Recuperado (USD) | AH3: Monto Recuperado (PEN) | AI3: Tipo de Cambio | AJ3: Monto Total Recuperado (PEN) | AK3: Monto Total Recuperado (USD) | AL3: Fecha Registro Contable | AM3: Diario (Asiento) | AN3: # Cuenta Contable | AO3: Pérdida Neta (PEN) | AP3: Pérdida Neta (USD) | AQ3: Área Detección (Reportó) | AR3: Área/Unidad Ocurrencia | AS3: Relacionado a Riesgo de Mercado/ Riesgo de Crédito | AT3: Informe (SI / NO) | AU3: Sesión Comité Riesgo | AV3: Evento Relacionado (ER)/ Pérdida Múltiple (PM) | AW3: Número de ER / PM | AX3: Observaciones | AY3: Estado | AZ3: Periodo de Reporte | BA3: Riesgo
B4: EV-2018-001 | C4: Lima | D4: 43113 | E4: 43152 | F4: 43353 | G4: Multa por tener un sistema de prevención de corrupción defectuoso. | H4: Nos visitó la SMV a solicitud de la Fiscalía y el Informe dio por resultado de "Defectuoso" el sistema de prevención de corrupción de la empresa. | I4: Banca minorista | J4: 3 | K4: Banca minorista | L4: 10 | M4: 7 | N4: Ejecución, entrega y gestión de procesos | O4: 15 | P4: Recepción, ejecución y mantenimiento de operaciones | Q4: 28 | R4: Multas, Sanciones, Sobrecargos | S4: 9 | T4: Convenios | U4: Convenios | V4: Crédito minorista de consumo | Y4: PEN | Z4: 7161 | AA4: 7161 | AB4: 17/01/2014 20/01/2014 | AC4: 43454715 43479627 | AD4: 4615000100711001 | AE4: HBPE 100 - 033 - 00 | AF4: N/A | AG4: 0 | AH4: 0 | AI4: 1 | AJ4: 0 | AK4: 0 | AL4: N/A | AM4: N/A | AN4: N/A | AO4: 7161 | AP4: 2549.3058 | AQ4: Legal | AR4: Operaciones Banca Personal | AS4: N/A | AT4: No | AU4: Febrero | AY4: Cerrado | AZ4: 43101
B5: EV-2018-002 | C5: Lima | D5: 43238 | E5: 43416 | F5: 43136 | G5: Almuerzo con funcionario público sin autorización. | H5: No se registró almuerzo con funcionario del Ministerio de Transportes. | I5: Banca minorista | J5: 3 | K5: Banca minorista | L5: 10 | M5: 4 | N5: Clientes, productos y prácticas empresariales | O5: 10 | P5: Productos defectuosos | Q5: 26 | R5: Fallas en el diseño del proceso | S5: 9 | T5: Convenios | U5: Convenios | V5: Crédito minorista de consumo | Y5: PEN | Z5: 7681.93 | AA5: 7681.93 | AB5: 42510 | AC5: 7 | AD5: 4619090901211001 | AE5: 26 | AF5: N/A | AG5: 0 | AH5: 0 | AI5: 3.341 | AJ5: 0 | AK5: 0 | AL5: N/A | AM5: NA | AN5: N/A | AO5: 7681.93 | AP5: 2299.2906 | AQ5: Calidad y Servicio al Cliente | AR5: Ventas | AS5: No | AT5: No | AU5: Junio | AY5: Cerrado | AZ5: 43221
B6: EV-2019-003 | C6: Piura | D6: 43636 | E6: 43565 | F6: 43683 | G6: Multa por incumplimiento al no tener canal de denuncias | H6: No se implementó canal de denuncias | I6: Banca minorista | J6: 3 | K6: Banca minorista | L6: 10 | M6: 4 | N6: Clientes, productos y prácticas empresariales | O6: 9 | P6: Prácticas empresariales o de mercado improcedentes | Q6: 14 | R6: Sanciones o sentencias a favor del cliente | S6: 9 | T6: Convenios | U6: Convenios | V6: Crédito minorista de consumo | Y6: PEN | Z6: 8923.5 | AA6: 8923.5 | AB6: 06/06/2016 03/06/2016 | AC6: 1 27 | AD6: 4615000100711001 | AE6: 26 | AF6: N/A | AG6: 0 | AH6: 0 | AI6: 1 | AJ6: 0 | AK6: 0 | AL6: N/A | AM6: NA | AN6: N/A | AO6: 8923.5 | AP6: 2687.6977 | AQ6: Legal | AR6: Productos | AS6: No | AT6: No | AU6: Julio | AY6: Cerrado | AZ6: 43617
B7: EV-2019-004 | C7: Arequipa | D7: 43766 | E7: 43656 | F7: 43801 | G7: Multa por no realizar capacitaciones del sistema de prevención de corrupción. | H7: No se evidenciaron las capacitaciones de acuerdo al Plan de Capacitaciones. | I7: Banca minorista | J7: 3 | K7: Banca minorista | L7: 10 | M7: 4 | N7: Clientes, productos y prácticas empresariales | O7: 9 | P7: Prácticas empresariales o de mercado improcedentes | Q7: 14 | R7: Sanciones o sentencias a favor del cliente | S7: 9 | T7: Convenios | U7: Convenios | V7: Crédito minorista de consumo | Y7: PEN | Z7: 5961 | AA7: 5961 | AB7: 42671 | AC7: 5 4 | AD7: 4615000100711001 | AE7: 26 | AF7: N/A | AG7: 0 | AH7: 0 | AI7: 1 | AJ7: 0 | AK7: 0 | AL7: N/A | AM7: NA | AN7: N/A | AO7: 5961 | AP7: 1770.4188 | AQ7: Legal | AR7: Productos | AS7: No | AT7: No | AU7: Noviembre | AX7: PP-2016-040 | AY7: Cerrado | AZ7: 43739
