Workbook
Name Administración_de_Tasas_y_Tarifas: Parámetros!$G$173:$G$175
Name Administración_patrimonial: Parámetros!$G$141:$G$142
Name Administración_y_Canje_de_Cheques: Parámetros!$G$150:$G$151
Name Adquisiciones: Parámetros!$G$130:$G$132
Name Banca_corresponsal: Parámetros!$G$72
Name Captación_de_Productos: Parámetros!$G$18:$G$21
Name CARACTERIZACION: [1]CARACTERIZACION!$F$3:$K$144
Name CAUSAL: [1]TABLAS!$H$3:$I$9
Name Clasificación_de_Cartera_y_Gestión_de_Provisiones: Parámetros!$G$92:$G$93
Name Clientes: Parámetros!$E$6:$E$7
Name Clientes_productos_y_prácticas_empresariales: Parámetros!$P$14:$P$18
Name Colocaciones: Parámetros!$E$13:$E$17
Name Compensaciones_del_Colaborador: Parámetros!$G$123:$G$125
Name Compra_de_Cartera: Parámetros!$G$70:$G$71
Name Control_Interno: Parámetros!$E$59:$E$61
Name Control_Presupuestal: Parámetros!$E$5
Name Daños_a_activos_materiales: Parámetros!$P$20:$P$20
Name Desarrollo_de_Software: Parámetros!$G$164:$G$167
Name Desarrollo_y_Administración_del_Presupuesto: Parámetros!$G$9
Name DESCR_ORIGEN: [2]Hoja1!$H$2:$H$20
Name Ejecución_entrega_y_gestión_de_procesos: Parámetros!$P$24:$P$29
Name Eventos_externos: Parámetros!$E$79:$E$83
Name Fondeo: Parámetros!$E$8:$E$10
Name Fondeo_de_Recursos: Parámetros!$G$26:$G$27
Name Fraude_externo: Parámetros!$P$7:$P$8
Name Fraude_interno: Parámetros!$P$4:$P$5
Name Gestión_Contable: Parámetros!$G$176:$G$178
Name Gestión_de_Administración: Parámetros!$E$40:$E$44
Name Gestión_de_Auditoría_Interna: Parámetros!$G$198:$G$199
Name Gestión_de_Calidad_y_Servicio_al_Cliente: Parámetros!$G$13:$G$17
Name Gestion_de_Cobranzas_Empresas: Parámetros!$G$190:$G$197
Name Gestión_de_Cobranzas_Personas: Parámetros!$G$182:$G$189
Name Gestión_de_Cobranzas_y_Recuperaciones: Parámetros!$E$57:$E$58
Name Gestión_de_Contratos: Parámetros!$G$103:$G$104
Name Gestión_de_Cumplimiento_Normativo: Parámetros!$G$200
Name Gestión_de_Depósitos: Parámetros!$G$162:$G$163
Name Gestión_de_digitalización_de_files: Parámetros!$G$139:$G$140
Name Gestión_de_Dinero_y_Valorados: Parámetros!$G$147:$G$149
Name Gestión_de_Embargos: Parámetros!$G$110
Name Gestión_de_Garantías: Parámetros!$G$65:$G$69
Name Gestión_de_Gastos_e_Ingresos: Parámetros!$G$179:$G$180
Name Gestión_de_Infraestructura: Parámetros!$G$133:$G$134
Name Gestión_de_la_Continuidad_del_Negocio: Parámetros!$G$94:$G$95
Name Gestión_de_Marketing: Parámetros!$G$4:$G$8
Name Gestión_de_Operaciones: Parámetros!$E$45:$E$50
Name Gestión_de_Operaciones_de_TI: Parámetros!$G$168:$G$172
Name Gestión_de_Planeamiento_Estratégico: Parámetros!$G$3
Name Gestión_de_Poderes: Parámetros!$G$105:$G$106
Name Gestión_de_Prevención_de_Lavado_de_Activos: Parámetros!$G$201
Name Gestión_de_Procesos: Parámetros!$E$38:$E$39
Name Gestión_de_Procesos_Legales: Parámetros!$G$107:$G$109
Name Gestión_de_Riesgo_Crediticio_y_Cambiario: Parámetros!$G$85:$G$89
Name Gestión_de_Riesgo_Operacional: Parámetros!$G$96:$G$98
Name Gestión_de_Riesgos: Parámetros!$E$22:$E$29
Name Gestión_de_RRHH: Parámetros!$E$35:$E$37
Name Gestión_de_Seguridad_de_la_Información: Parámetros!$G$99:$G$100
Name Gestión_de_Seguros: Parámetros!$G$82:$G$83
Name Gestión_de_Servicios_asociados_a_la_Banca_x_internet: Parámetros!$G$73:$G$77
Name Gestión_de_Servicios_internos: Parámetros!$G$135:$G$138
Name Gestión_de_Tecnología_de_Información: Parámetros!$E$51:$E$52

Sheet SARO-01
C2: Conocimiento y Analisis del Proceso
G3: Nombre | H3: Cargo
B4: MACRO PROCESO | C4: Control Interno | F4: DUEÑO DEL PROCESO | G4: Carlos Wisse
B5: PROCESO | C5: Gestión de Prevención de Lavado de Activos | F5: APROBADOR | G5: Carlos Wisse
B6: LINEA DE NEGOCIO | F6: RESPONSABLE REGISTRO RO | G6: Elkee Altamirano
B8: FECHA DE ELABORACIÓN | C8: 43136
B10: A. Diagrama de bloques del proceso (Sub procesos que lo integran y relación)
B27: B. Información adicional/ Comentarios

Sheet SARO-02
C2: Identificación y Medición de Riesgos, Controles y Tratamiento
Q4: RIESGO INHERENTE | X4: IDENTIFICACIÓN DE CONTROLES | AE4: DISEÑO | AJ4: EJECUCION | AY4: RIESGO RESIDUAL | BE4: TRATAMIENTO | BM4: RECOMENDACIONES | BO4: RIESGO ESPERADO
A5: IdRiesgo | B5: Macro Proceso | C5: Proceso | D5: Subproceso | E5: Tipo de Evento Nivel 1 | F5: Tipo de Evento Nivel 2 | G5: Titulo del Riesgo | H5: Detalle Riesgo | I5: CAUSA | J5: EVENTO | K5: CONSECUENCIA | L5: Factor de Riesgo N1 | M5: Factor de Riesgo N2 | N5: Impacto Asociado | O5: Riesgo Asociado | P5: Riesgo Materializado? | Q5: Criterio Probabilidad | R5: Probabilidad | S5: Sustento Probabilidad | T5: Criterio Impacto | U5: Impacto | V5: Sustento Impacto | W5: Nivel de Riesgo | X5: IdControl | Y5: Control de referencia | Z5: Titulo de Control | AA5: Descripcion Control | AB5: Documento Normativo Fuente | AC5: Evidencia del Control | AD5: Area de Ejecucion | AE5: Periodicidad | AF5: Operatividad | AG5: TipoControl | AH5: Segregacion | AI5: Supervision | AJ5: Oportuno | AK5: Adecuado | AL5: Disminuye | AM5: CÁLCULO | AT5: Probabilidad Inherente | AU5: % de Mitigación | AV5: Calificación del Control | AW5: Mitigación Probabilidad | AX5: Mitigación Impacto | AY5: Criterio Probabilidad | AZ5: Probabilidad | BA5: Criterio Impacto | BB5: Impacto | BC5: Exposición Residual | BD5: Nivel de Riesgo | BE5: TRATAMIENTO | BF5: IdPlan | BG5: Plan de Acción | BH5: Calificación esperada del Control | BI5: % de Mitigación | BJ5: Área Responsable del Plan de Acción | BK5: Fecha inicio de implementación | BL5: Fecha fin de implementación | BM5: Acciones Complementarias | BN5: Área responsable | BO5: Exposición Esperada | BP5: Nivel de Riesgo Esperado
A6: 1 | G6: Fallas en gestión de alertas | H6: =IF(I6="","",CONCATENATE(I6," ","podría ocasionar"," ",J6," ", "generando"," ",K6)) -> Fallas en registro u omisión de reporte de clientes (Funcionario o…) podría ocasionar no reportemos operacions sospechosas o inusuales a SBS generando multa de SBS o UIF | I6: Fallas en registro u omisión de reporte de clientes (Funcionario o…) | J6: no reportemos operacions sospechosas o inusuales a SBS | K6: multa de SBS o UIF | L6: Personal | M6: Omisión de Funciones | N6: Legal / Regulatorio | O6: Riesgo de Reputación | P6: No | Q6: =IF(R6="","",IF(R6>Parámetros!$T$14,IF(R6>Parámetros!$T$13,IF(R6>Parámetros!$T$12,IF(R6>Parámetros!$T$11,"Muy Alta","Alta"),"Media"),"Baja"),"Muy Baja")) -> Muy Alta | R6: 0.8 | S6: Omisión de registro | T6: =IF(U6="","",IF(U6>Parámetros!$T$7,IF(U6>Parámetros!$T$6,IF(U6>Parámetros!$T$5,IF(U6>Parámetros!$T$4,"Catastrófico","Mayor"),"Moderado"),"Menor"),"Insignificante")) -> Moderado | U6: =100*4050 -> 405000 | V6: 100 UIT | W6: =IF(Q6="","",INDEX(Parámetros!$Y$13:$AC$17,VLOOKUP(Q6,Parámetros!$W$13:$X$17,2,FALSE),HLOOKUP(T6,Parámetros!$Y$11:$AC$12,2,FALSE))) -> Alto | X6: 1 | AA6: Bantotal valida el largo del telefono, el código de provincia, primer nombre y primer apelido, campo obligatorio de dirección. | AB6: Manuales de cada producto | AC6: Automático | AM6: =IF(AE6="","",VLOOKUP(AE6,Parámetros!$AE$3:$AF$5,2,FALSE)) | AN6: =IF(AF6="","",VLOOKUP(AF6,Parámetros!$AH$3:$AI$5,2,FALSE)) | AO6: =IF(AG6="","",VLOOKUP(AG6,Parámetros!$AK$3:$AL$4,2,FALSE)) | AP6: =IF(AH6="","",VLOOKUP(AH6,Parámetros!$AN$3:$AO$5,2,FALSE)) | AQ6: =IF(AI6="","",VLOOKUP(AI6,Parámetros!$AQ$3:$AR$5,2,FALSE)) | AR6: =IF(AJ6="","",VLOOKUP(AJ6,Parámetros!$AT$3:$AU$4,2,FALSE)) | AS6: =IF(AK6="","",VLOOKUP(AK6,Parámetros!$AT$3:$AU$4,2,FALSE)) | AT6: =IF(R6="","",VLOOKUP(Q6,Parámetros!$R$10:$T$14,3,FALSE)) -> 1 | AU6: =+(AM6*0.2+AN6*0.2+AO6*0.2+AP6*0.2+AQ6*0.2)*(AR6*0.5+AS6*0.5) -> #VALUE! | AV6: =+IF(AU6<0.9,IF(AU6<0.6,IF(AU6>0.3,"Moderado","Insastisfactorio"),"Bueno"),"Excelente") -> #VALUE! | AY6: =IF(AZ6="","",IF(AZ6<=Parámetros!$T$11,IF(AZ6<=Parámetros!$T$12,IF(AZ6<=Parámetros!$T$13,IF(AZ6<=Parámetros!$T$14,"Muy Baja","Baja"),"Media"),"Alta"),"Muy Alta")) -> Muy Alta | AZ6: =IF(AT6="","",IF(AW6="",AT6,(AT6*(1-AW6)))) -> 1 | BA6: =IF(BB6="","",IF(BB6>Parámetros!$T$7,IF(BB6>Parámetros!$T$6,IF(BB6>Parámetros!$T$5,IF(BB6>Parámetros!$T$4,"Catastrófico","Mayor"),"Moderado"),"Menor"),"Insignificante")) -> Moderado | BB6: =IF(U6="","",IF(AX6="",U6,ROUND(U6*(1-AX6),1))) -> 405000 | BC6: =IF(BB6="","",IF(AZ6*BB6=0,"",AZ6*BB6)) -> 405000 | BD6: =IF(BC6="","",INDEX(Parámetros!$Y$13:$AC$17,VLOOKUP(AY6,Parámetros!$W$13:$X$17,2,FALSE),HLOOKUP(BA6,Parámetros!$Y$11:$AC$12,2,FALSE))) -> Alto | BI6: =IF(BH6="","",VLOOKUP(BH6,Parámetros!$AW$3:$AX$6,2,FALSE)) | BO6: =IF(BE6="Aceptar",BC6,IF(BI6="","",(BC6*(1-BI6)))) | BP6: =IF(BO6="","",IF(BO6<=Parámetros!R35,Parámetros!S35,IF(BO6<=Parámetros!R34,Parámetros!S34,IF(BO6>=Parámetros!R33,Parámetros!S33,IF(BO6>=Parámetros!R32,Parámetros!S32,Parámetros!S31)))))
X7: 2 | AA7: Valida que la información (a solicitud de área con documento sustento de cliente) y modifica si corresponde (sólo lo solicitado) | AB7: Guia de Actualización de Datos | AC7: Solicitud sellada por área de Mantenimiento de Base de Datos | AD7: Mantenimiento de Base de Datos | AE7: Eventual | AF7: Manual | AG7: Detectivo | AH7: Misma área | AI7: Nivel 1 | AJ7: SI | AK7: NO
A8: 2 | H8: =IF(I8="","",CONCATENATE(I8," ","podría ocasionar"," ",J8," ", "generando"," ",K8)) -> Error en el registro de clientes podría ocasionar no reportemos operacions sospechosas o inusuales a SBS generando multa de SBS o UIF | I8: Error en el registro de clientes | J8: no reportemos operacions sospechosas o inusuales a SBS | K8: multa de SBS o UIF | L8: Personal | M8: Error involuntario | N8: Legal / Regulatorio | O8: Riesgo Legal | P8: No | Q8: =IF(R8="","",IF(R8>Parámetros!$T$14,IF(R8>Parámetros!$T$13,IF(R8>Parámetros!$T$12,IF(R8>Parámetros!$T$11,"Muy Alta","Alta"),"Media"),"Baja"),"Muy Baja")) -> Media | R8: 0.1 | T8: =IF(U8="","",IF(U8>Parámetros!$T$7,IF(U8>Parámetros!$T$6,IF(U8>Parámetros!$T$5,IF(U8>Parámetros!$T$4,"Catastrófico","Mayor"),"Moderado"),"Menor"),"Insignificante")) -> Moderado | U8: =100*4050 -> 405000 | V8: 100 UIT | W8: =IF(Q8="","",INDEX(Parámetros!$Y$13:$AC$17,VLOOKUP(Q8,Parámetros!$W$13:$X$17,2,FALSE),HLOOKUP(T8,Parámetros!$Y$11:$AC$12,2,FALSE))) -> Medio | AA8: idem | AM8: =IF(AE8="","",VLOOKUP(AE8,Parámetros!$AE$3:$AF$5,2,FALSE)) | AN8: =IF(AF8="","",VLOOKUP(AF8,Parámetros!$AH$3:$AI$5,2,FALSE)) | AO8: =IF(AG8="","",VLOOKUP(AG8,Parámetros!$AK$3:$AL$4,2,FALSE)) | AP8: =IF(AH8="","",VLOOKUP(AH8,Parámetros!$AN$3:$AO$5,2,FALSE)) | AQ8: =IF(AI8="","",VLOOKUP(AI8,Parámetros!$AQ$3:$AR$5,2,FALSE)) | AR8: =IF(AJ8="","",VLOOKUP(AJ8,Parámetros!$AT$3:$AU$4,2,FALSE)) | AS8: =IF(AK8="","",VLOOKUP(AK8,Parámetros!$AT$3:$AU$4,2,FALSE)) | AT8: =IF(R8="","",VLOOKUP(Q8,Parámetros!$R$10:$T$14,3,FALSE)) -> 0.11 | AU8: =+(AM8*0.2+AN8*0.2+AO8*0.2+AP8*0.2+AQ8*0.2)*(AR8*0.5+AS8*0.5) -> #VALUE! | AV8: =+IF(AU8<0.9,IF(AU8<0.6,IF(AU8>0.3,"Moderado","Insastisfactorio"),"Bueno"),"Excelente") -> #VALUE! | AY8: =IF(AZ8="","",IF(AZ8<=Parámetros!$T$11,IF(AZ8<=Parámetros!$T$12,IF(AZ8<=Parámetros!$T$13,IF(AZ8<=Parámetros!$T$14,"Muy Baja","Baja"),"Media"),"Alta"),"Muy Alta")) -> Media | AZ8: =IF(AT8="","",IF(AW8="",AT8,(AT8*(1-AW8)))) -> 0.11 | BA8: =IF(BB8="","",IF(BB8>Parámetros!$T$7,IF(BB8>Parámetros!$T$6,IF(BB8>Parámetros!$T$5,IF(BB8>Parámetros!$T$4,"Catastrófico","Mayor"),"Moderado"),"Menor"),"Insignificante")) -> Moderado | BB8: =IF(U8="","",IF(AX8="",U8,ROUND(U8*(1-AX8),1))) -> 405000 | BC8: =IF(BB8="","",IF(AZ8*BB8=0,"",AZ8*BB8)) -> 44550 | BD8: =IF(BC8="","",INDEX(Parámetros!$Y$13:$AC$17,VLOOKUP(AY8,Parámetros!$W$13:$X$17,2,FALSE),HLOOKUP(BA8,Parámetros!$Y$11:$AC$12,2,FALSE))) -> Medio | BI8: =IF(BH8="","",VLOOKUP(BH8,Parámetros!$AW$3:$AX$6,2,FALSE)) | BO8: =IF(BE8="Aceptar",BC8,IF(BI8="","",(BC8*(1-BI8)))) | BP8: =IF(BO8="","",IF(BO8<=Parámetros!R36,Parámetros!S36,IF(BO8<=Parámetros!R35,Parámetros!S35,IF(BO8>=Parámetros!R34,Parámetros!S34,IF(BO8>=Parámetros!R33,Parámetros!S33,Parámetros!S32)))))
A9: 3 | H9: =IF(I9="","",CONCATENATE(I9," ","podría ocasionar"," ",J9," ", "generando"," ",K9)) -> Fallas en el sistema de alertas de ASSIT o en el registro de transacciones en Bantotal podría ocasionar no reportemos operacions sospechosas o inusuales a SBS generando multa de SBS o UIF | I9: Fallas en el sistema de alertas de ASSIT o en el registro de transacciones en Bantotal | J9: no reportemos operacions sospechosas o inusuales a SBS | K9: multa de SBS o UIF | L9: Tecnologia de Informacion | M9: Falta de Integridad | N9: Legal / Regulatorio | O9: Riesgo Legal | P9: No | Q9: =IF(R9="","",IF(R9>Parámetros!$T$14,IF(R9>Parámetros!$T$13,IF(R9>Parámetros!$T$12,IF(R9>Parámetros!$T$11,"Muy Alta","Alta"),"Media"),"Baja"),"Muy Baja")) -> Alta | R9: 0.3 | T9: =IF(U9="","",IF(U9>Parámetros!$T$7,IF(U9>Parámetros!$T$6,IF(U9>Parámetros!$T$5,IF(U9>Parámetros!$T$4,"Catastrófico","Mayor"),"Moderado"),"Menor"),"Insignificante")) -> Moderado | U9: =100*4050 -> 405000 | V9: 100 UIT | W9: =IF(Q9="","",INDEX(Parámetros!$Y$13:$AC$17,VLOOKUP(Q9,Parámetros!$W$13:$X$17,2,FALSE),HLOOKUP(T9,Parámetros!$Y$11:$AC$12,2,FALSE))) -> Medio | AA9: No hay control | AM9: =IF(AE9="","",VLOOKUP(AE9,Parámetros!$AE$3:$AF$5,2,FALSE)) | AN9: =IF(AF9="","",VLOOKUP(AF9,Parámetros!$AH$3:$AI$5,2,FALSE)) | AO9: =IF(AG9="","",VLOOKUP(AG9,Parámetros!$AK$3:$AL$4,2,FALSE)) | AP9: =IF(AH9="","",VLOOKUP(AH9,Parámetros!$AN$3:$AO$5,2,FALSE)) | AQ9: =IF(AI9="","",VLOOKUP(AI9,Parámetros!$AQ$3:$AR$5,2,FALSE)) | AR9: =IF(AJ9="","",VLOOKUP(AJ9,Parámetros!$AT$3:$AU$4,2,FALSE)) | AS9: =IF(AK9="","",VLOOKUP(AK9,Parámetros!$AT$3:$AU$4,2,FALSE)) | AT9: =IF(R9="","",VLOOKUP(Q9,Parámetros!$R$10:$T$14,3,FALSE)) -> 0.33 | AU9: =+(AM9*0.2+AN9*0.2+AO9*0.2+AP9*0.2+AQ9*0.2)*(AR9*0.5+AS9*0.5) -> #VALUE! | AV9: =+IF(AU9<0.9,IF(AU9<0.6,IF(AU9>0.3,"Moderado","Insastisfactorio"),"Bueno"),"Excelente") -> #VALUE! | AY9: =IF(AZ9="","",IF(AZ9<=Parámetros!$T$11,IF(AZ9<=Parámetros!$T$12,IF(AZ9<=Parámetros!$T$13,IF(AZ9<=Parámetros!$T$14,"Muy Baja","Baja"),"Media"),"Alta"),"Muy Alta")) -> Alta | AZ9: =IF(AT9="","",IF(AW9="",AT9,(AT9*(1-AW9)))) -> 0.33 | BA9: =IF(BB9="","",IF(BB9>Parámetros!$T$7,IF(BB9>Parámetros!$T$6,IF(BB9>Parámetros!$T$5,IF(BB9>Parámetros!$T$4,"Catastrófico","Mayor"),"Moderado"),"Menor"),"Insignificante")) -> Moderado | BB9: =IF(U9="","",IF(AX9="",U9,ROUND(U9*(1-AX9),1))) -> 405000 | BC9: =IF(BB9="","",IF(AZ9*BB9=0,"",AZ9*BB9)) -> 133650 | BD9: =IF(BC9="","",INDEX(Parámetros!$Y$13:$AC$17,VLOOKUP(AY9,Parámetros!$W$13:$X$17,2,FALSE),HLOOKUP(BA9,Parámetros!$Y$11:$AC$12,2,FALSE))) -> Medio | BI9: =IF(BH9="","",VLOOKUP(BH9,Parámetros!$AW$3:$AX$6,2,FALSE)) | BO9: =IF(BE9="Aceptar",BC9,IF(BI9="","",(BC9*(1-BI9)))) | BP9: =IF(BO9="","",IF(BO9<=Parámetros!R37,Parámetros!S37,IF(BO9<=Parámetros!R36,Parámetros!S36,IF(BO9>=Parámetros!R35,Parámetros!S35,IF(BO9>=Parámetros!R34,Parámetros!S34,Parámetros!S33)))))
A10: 4 | H10: =IF(I10="","",CONCATENATE(I10," ","podría ocasionar"," ",J10," ", "generando"," ",K10)) -> Omisión o desconocimiento de G. de Agencia o Funcionario durante la investigación podría ocasionar no reportemos operacions sospechosas o inusuales a SBS generando multa de SBS o UIF | I10: Omisión o desconocimiento de G. de Agencia o Funcionario durante la investigación | J10: no reportemos operacions sospechosas o inusuales a SBS | K10: multa de SBS o UIF | L10: Personal | M10: Omisión de Funciones | Q10: =IF(R10="","",IF(R10>Parámetros!$T$14,IF(R10>Parámetros!$T$13,IF(R10>Parámetros!$T$12,IF(R10>Parámetros!$T$11,"Muy Alta","Alta"),"Media"),"Baja"),"Muy Baja")) -> Media | R10: 0.1 | T10: =IF(U10="","",IF(U10>Parámetros!$T$7,IF(U10>Parámetros!$T$6,IF(U10>Parámetros!$T$5,IF(U10>Parámetros!$T$4,"Catastrófico","Mayor"),"Moderado"),"Menor"),"Insignificante")) -> Moderado | U10: =100*4050 -> 405000 | V10: 100 UIT | W10: =IF(Q10="","",INDEX(Parámetros!$Y$13:$AC$17,VLOOKUP(Q10,Parámetros!$W$13:$X$17,2,FALSE),HLOOKUP(T10,Parámetros!$Y$11:$AC$12,2,FALSE))) -> Medio | AA10: Sistema de Alertas, monitoreo todas las operaciones de acuerdo a las reglas (pe. Monto, tipo de cliente, perfile, etc.) | AB10: Gestión de Alertas | AC10: Registro de Operaciones Inusuales | AD10: PLAFT | AE10: Permanente | AF10: Automático | AG10: Preventivo | AH10: Otra área o automático | AI10: Nivel 3 | AJ10: SI | AK10: SI | AM10: =IF(AE10="","",VLOOKUP(AE10,Parámetros!$AE$3:$AF$5,2,FALSE)) -> 1 | AN10: =IF(AF10="","",VLOOKUP(AF10,Parámetros!$AH$3:$AI$5,2,FALSE)) -> 1 | AO10: =IF(AG10="","",VLOOKUP(AG10,Parámetros!$AK$3:$AL$4,2,FALSE)) -> 1 | AP10: =IF(AH10="","",VLOOKUP(AH10,Parámetros!$AN$3:$AO$5,2,FALSE)) -> 1 | AQ10: =IF(AI10="","",VLOOKUP(AI10,Parámetros!$AQ$3:$AR$5,2,FALSE)) -> 1 | AR10: =IF(AJ10="","",VLOOKUP(AJ10,Parámetros!$AT$3:$AU$4,2,FALSE)) -> 1 | AS10: =IF(AK10="","",VLOOKUP(AK10,Parámetros!$AT$3:$AU$4,2,FALSE)) -> 1 | AT10: =IF(R10="","",VLOOKUP(Q10,Parámetros!$R$10:$T$14,3,FALSE)) -> 0.11 | AU10: =+(AM10*0.2+AN10*0.2+AO10*0.2+AP10*0.2+AQ10*0.2)*(AR10*0.5+AS10*0.5) -> 1 | AV10: =+IF(AU10<0.9,IF(AU10<0.6,IF(AU10>0.3,"Moderado","Insastisfactorio"),"Bueno"),"Excelente") -> Excelente | AY10: =IF(AZ10="","",IF(AZ10<=Parámetros!$T$11,IF(AZ10<=Parámetros!$T$12,IF(AZ10<=Parámetros!$T$13,IF(AZ10<=Parámetros!$T$14,"Muy Baja","Baja"),"Media"),"Alta"),"Muy Alta")) -> Media | AZ10: =IF(AT10="","",IF(AW10="",AT10,(AT10*(1-AW10)))) -> 0.11 | BA10: =IF(BB10="","",IF(BB10>Parámetros!$T$7,IF(BB10>Parámetros!$T$6,IF(BB10>Parámetros!$T$5,IF(BB10>Parámetros!$T$4,"Catastrófico","Mayor"),"Moderado"),"Menor"),"Insignificante")) -> Moderado | BB10: =IF(U10="","",IF(AX10="",U10,ROUND(U10*(1-AX10),1))) -> 405000 | BC10: =IF(BB10="","",IF(AZ10*BB10=0,"",AZ10*BB10)) -> 44550 | BD10: =IF(BC10="","",INDEX(Parámetros!$Y$13:$AC$17,VLOOKUP(AY10,Parámetros!$W$13:$X$17,2,FALSE),HLOOKUP(BA10,Parámetros!$Y$11:$AC$12,2,FALSE))) -> Medio | BI10: =IF(BH10="","",VLOOKUP(BH10,Parámetros!$AW$3:$AX$6,2,FALSE)) | BO10: =IF(BE10="Aceptar",BC10,IF(BI10="","",(BC10*(1-BI10)))) | BP10: =IF(BO10="","",IF(BO10<=Parámetros!R38,Parámetros!S38,IF(BO10<=Parámetros!R37,Parámetros!S37,IF(BO10>=Parámetros!R36,Parámetros!S36,IF(BO10>=Parámetros!R35,Parámetros!S35,Parámetros!S34)))))
H11: =IF(I11="","",CONCATENATE(I11," ","podría ocasionar"," ",J11," ", "generando"," ",K11)) | Q11: =IF(R11="","",IF(R11>Parámetros!$T$14,IF(R11>Parámetros!$T$13,IF(R11>Parámetros!$T$12,IF(R11>Parámetros!$T$11,"Muy Alta","Alta"),"Media"),"Baja"),"Muy Baja")) | T11: =IF(U11="","",IF(U11>Parámetros!$T$7,IF(U11>Parámetros!$T$6,IF(U11>Parámetros!$T$5,IF(U11>Parámetros!$T$4,"Catastrófico","Mayor"),"Moderado"),"Menor"),"Insignificante")) | W11: =IF(Q11="","",INDEX(Parámetros!$Y$13:$AC$17,VLOOKUP(Q11,Parámetros!$W$13:$X$17,2,FALSE),HLOOKUP(T11,Parámetros!$Y$11:$AC$12,2,FALSE))) | AA11: Especialista contacta con el funcionario para que pueda proporcionar la información (5 días habiles) | AB11: Gestión de Alertas | AC11: Acta de Visita y Correos | AD11: PLAFT | AE11: Permanente | AF11: Manual | AG11: Preventivo | AH11: Misma área | AI11: Nivel 2 | AJ11: SI | AK11: SI | AM11: =IF(AE11="","",VLOOKUP(AE11,Parámetros!$AE$3:$AF$5,2,FALSE)) -> 1 | AN11: =IF(AF11="","",VLOOKUP(AF11,Parámetros!$AH$3:$AI$5,2,FALSE)) -> 0.3 | AO11: =IF(AG11="","",VLOOKUP(AG11,Parámetros!$AK$3:$AL$4,2,FALSE)) -> 1 | AP11: =IF(AH11="","",VLOOKUP(AH11,Parámetros!$AN$3:$AO$5,2,FALSE)) -> 0.5 | AQ11: =IF(AI11="","",VLOOKUP(AI11,Parámetros!$AQ$3:$AR$5,2,FALSE)) -> 0.7 | AR11: =IF(AJ11="","",VLOOKUP(AJ11,Parámetros!$AT$3:$AU$4,2,FALSE)) -> 1 | AS11: =IF(AK11="","",VLOOKUP(AK11,Parámetros!$AT$3:$AU$4,2,FALSE)) -> 1 | AT11: =IF(R11="","",VLOOKUP(Q11,Parámetros!$R$10:$T$14,3,FALSE)) | AU11: =+(AM11*0.2+AN11*0.2+AO11*0.2+AP11*0.2+AQ11*0.2)*(AR11*0.5+AS11*0.5) -> 0.7 | AV11: =+IF(AU11<0.9,IF(AU11<0.6,IF(AU11>0.3,"Moderado","Insastisfactorio"),"Bueno"),"Excelente") -> Bueno | AY11: =IF(AZ11="","",IF(AZ11<=Parámetros!$T$11,IF(AZ11<=Parámetros!$T$12,IF(AZ11<=Parámetros!$T$13,IF(AZ11<=Parámetros!$T$14,"Muy Baja","Baja"),"Media"),"Alta"),"Muy Alta")) | AZ11: =IF(AT11="","",IF(AW11="",AT11,(AT11*(1-AW11)))) | BA11: =IF(BB11="","",IF(BB11>Parámetros!$T$7,IF(BB11>Parámetros!$T$6,IF(BB11>Parámetros!$T$5,IF(BB11>Parámetros!$T$4,"Catastrófico","Mayor"),"Moderado"),"Menor"),"Insignificante")) | BB11: =IF(U11="","",IF(AX11="",U11,ROUND(U11*(1-AX11),1))) | BC11: =IF(BB11="","",IF(AZ11*BB11=0,"",AZ11*BB11)) | BD11: =IF(BC11="","",INDEX(Parámetros!$Y$13:$AC$17,VLOOKUP(AY11,Parámetros!$W$13:$X$17,2,FALSE),HLOOKUP(BA11,Parámetros!$Y$11:$AC$12,2,FALSE))) | BI11: =IF(BH11="","",VLOOKUP(BH11,Parámetros!$AW$3:$AX$6,2,FALSE)) | BO11: =IF(BE11="Aceptar",BC11,IF(BI11="","",(BC11*(1-BI11)))) | BP11: =IF(BO11="","",IF(BO11<=Parámetros!R39,Parámetros!S39,IF(BO11<=Parámetros!R38,Parámetros!S38,IF(BO11>=Parámetros!R37,Parámetros!S37,IF(BO11>=Parámetros!R36,Parámetros!S36,Parámetros!S35)))))
A12: 5 | H12: =IF(I12="","",CONCATENATE(I12," ","podría ocasionar"," ",J12," ", "generando"," ",K12)) -> Desconocimiento el Funcionario o Gerente de Agencia comunique podría ocasionar denuncia por parte del cliente generando Indemnización (preguntar a Edgar) | I12: Desconocimiento el Funcionario o Gerente de Agencia comunique | J12: denuncia por parte del cliente | K12: Indemnización (preguntar a Edgar) | L12: Personal | M12: Desconocimiento del personal | N12: Financiero | Q12: =IF(R12="","",IF(R12>Parámetros!$T$14,IF(R12>Parámetros!$T$13,IF(R12>Parámetros!$T$12,IF(R12>Parámetros!$T$11,"Muy Alta","Alta"),"Media"),"Baja"),"Muy Baja")) -> Media | R12: 0.1 | T12: =IF(U12="","",IF(U12>Parámetros!$T$7,IF(U12>Parámetros!$T$6,IF(U12>Parámetros!$T$5,IF(U12>Parámetros!$T$4,"Catastrófico","Mayor"),"Moderado"),"Menor"),"Insignificante")) -> Insignificante | U12: 10000 | W12: =IF(Q12="","",INDEX(Parámetros!$Y$13:$AC$17,VLOOKUP(Q12,Parámetros!$W$13:$X$17,2,FALSE),HLOOKUP(T12,Parámetros!$Y$11:$AC$12,2,FALSE))) -> Muy Bajo | AA12: El área realiza capacitación al personal (mantiene programa de capacitación) | AB12: Manual de Políticas | AC12: Actas de Capacitación / Examen / Sistema interna | AE12: Periódico | AF12: Manual | AG12: Preventivo | AH12: Misma área | AI12: Nivel 2 | AJ12: SI | AK12: SI | AM12: =IF(AE12="","",VLOOKUP(AE12,Parámetros!$AE$3:$AF$5,2,FALSE)) -> 0.7 | AN12: =IF(AF12="","",VLOOKUP(AF12,Parámetros!$AH$3:$AI$5,2,FALSE)) -> 0.3 | AO12: =IF(AG12="","",VLOOKUP(AG12,Parámetros!$AK$3:$AL$4,2,FALSE)) -> 1 | AP12: =IF(AH12="","",VLOOKUP(AH12,Parámetros!$AN$3:$AO$5,2,FALSE)) -> 0.5 | AQ12: =IF(AI12="","",VLOOKUP(AI12,Parámetros!$AQ$3:$AR$5,2,FALSE)) -> 0.7 | AR12: =IF(AJ12="","",VLOOKUP(AJ12,Parámetros!$AT$3:$AU$4,2,FALSE)) -> 1 | AS12: =IF(AK12="","",VLOOKUP(AK12,Parámetros!$AT$3:$AU$4,2,FALSE)) -> 1 | AT12: =IF(R12="","",VLOOKUP(Q12,Parámetros!$R$10:$T$14,3,FALSE)) -> 0.11 | AU12: =+(AM12*0.2+AN12*0.2+AO12*0.2+AP12*0.2+AQ12*0.2)*(AR12*0.5+AS12*0.5) -> 0.64 | AV12: =+IF(AU12<0.9,IF(AU12<0.6,IF(AU12>0.3,"Moderado","Insastisfactorio"),"Bueno"),"Excelente") -> Bueno | AY12: =IF(AZ12="","",IF(AZ12<=Parámetros!$T$11,IF(AZ12<=Parámetros!$T$12,IF(AZ12<=Parámetros!$T$13,IF(AZ12<=Parámetros!$T$14,"Muy Baja","Baja"),"Media"),"Alta"),"Muy Alta")) -> Media | AZ12: =IF(AT12="","",IF(AW12="",AT12,(AT12*(1-AW12)))) -> 0.11 | BA12: =IF(BB12="","",IF(BB12>Parámetros!$T$7,IF(BB12>Parámetros!$T$6,IF(BB12>Parámetros!$T$5,IF(BB12>Parámetros!$T$4,"Catastrófico","Mayor"),"Moderado"),"Menor"),"Insignificante")) -> Insignificante | BB12: =IF(U12="","",IF(AX12="",U12,ROUND(U12*(1-AX12),1))) -> 10000 | BC12: =IF(BB12="","",IF(AZ12*BB12=0,"",AZ12*BB12)) -> 1100 | BD12: =IF(BC12="","",INDEX(Parámetros!$Y$13:$AC$17,VLOOKUP(AY12,Parámetros!$W$13:$X$17,2,FALSE),HLOOKUP(BA12,Parámetros!$Y$11:$AC$12,2,FALSE))) -> Muy Bajo | BI12: =IF(BH12="","",VLOOKUP(BH12,Parámetros!$AW$3:$AX$6,2,FALSE)) | BO12: =IF(BE12="Aceptar",BC12,IF(BI12="","",(BC12*(1-BI12)))) | BP12: =IF(BO12="","",IF(BO12<=Parámetros!R40,Parámetros!S40,IF(BO12<=Parámetros!R39,Parámetros!S39,IF(BO12>=Parámetros!R38,Parámetros!S38,IF(BO12>=Parámetros!R37,Parámetros!S37,Parámetros!S36)))))
A13: 6 | H13: =IF(I13="","",CONCATENATE(I13," ","podría ocasionar"," ",J13," ", "generando"," ",K13)) -> Omisión por parte de área de Cumplimiento podría ocasionar envien reporte reportes regualtorios tarde o que no se envie generando multa de SBS | I13: Omisión por parte de área de Cumplimiento | J13: envien reporte reportes regualtorios tarde o que no se envie | K13: multa de SBS | L13: Personal | M13: Omisión de Funciones | Q13: =IF(R13="","",IF(R13>Parámetros!$T$14,IF(R13>Parámetros!$T$13,IF(R13>Parámetros!$T$12,IF(R13>Parámetros!$T$11,"Muy Alta","Alta"),"Media"),"Baja"),"Muy Baja")) -> Media | R13: 0.05 | T13: =IF(U13="","",IF(U13>Parámetros!$T$7,IF(U13>Parámetros!$T$6,IF(U13>Parámetros!$T$5,IF(U13>Parámetros!$T$4,"Catastrófico","Mayor"),"Moderado"),"Menor"),"Insignificante")) -> Moderado | U13: =100*4050 -> 405000 | V13: 100 UIT | W13: =IF(Q13="","",INDEX(Parámetros!$Y$13:$AC$17,VLOOKUP(Q13,Parámetros!$W$13:$X$17,2,FALSE),HLOOKUP(T13,Parámetros!$Y$11:$AC$12,2,FALSE))) -> Medio | AA13: Monitoreo de la información a enviar a SBS | AB13: Manual de reportes regulatorios | AC13: Correo electrónico y carpeta compartida de Cumplimiento (cargos) | AE13: Periódico | AF13: Manual | AG13: Preventivo | AH13: Misma área | AI13: Nivel 3 | AJ13: SI | AK13: SI | AM13: =IF(AE13="","",VLOOKUP(AE13,Parámetros!$AE$3:$AF$5,2,FALSE)) -> 0.7 | AN13: =IF(AF13="","",VLOOKUP(AF13,Parámetros!$AH$3:$AI$5,2,FALSE)) -> 0.3 | AO13: =IF(AG13="","",VLOOKUP(AG13,Parámetros!$AK$3:$AL$4,2,FALSE)) -> 1 | AP13: =IF(AH13="","",VLOOKUP(AH13,Parámetros!$AN$3:$AO$5,2,FALSE)) -> 0.5 | AQ13: =IF(AI13="","",VLOOKUP(AI13,Parámetros!$AQ$3:$AR$5,2,FALSE)) -> 1 | AR13: =IF(AJ13="","",VLOOKUP(AJ13,Parámetros!$AT$3:$AU$4,2,FALSE)) -> 1 | AS13: =IF(AK13="","",VLOOKUP(AK13,Parámetros!$AT$3:$AU$4,2,FALSE)) -> 1 | AT13: =IF(R13="","",VLOOKUP(Q13,Parámetros!$R$10:$T$14,3,FALSE)) -> 0.11 | AU13: =+(AM13*0.2+AN13*0.2+AO13*0.2+AP13*0.2+AQ13*0.2)*(AR13*0.5+AS13*0.5) -> 0.7 | AV13: =+IF(AU13<0.9,IF(AU13<0.6,IF(AU13>0.3,"Moderado","Insastisfactorio"),"Bueno"),"Excelente") -> Bueno | AY13: =IF(AZ13="","",IF(AZ13<=Parámetros!$T$11,IF(AZ13<=Parámetros!$T$12,IF(AZ13<=Parámetros!$T$13,IF(AZ13<=Parámetros!$T$14,"Muy Baja","Baja"),"Media"),"Alta"),"Muy Alta")) -> Media | AZ13: =IF(AT13="","",IF(AW13="",AT13,(AT13*(1-AW13)))) -> 0.11 | BA13: =IF(BB13="","",IF(BB13>Parámetros!$T$7,IF(BB13>Parámetros!$T$6,IF(BB13>Parámetros!$T$5,IF(BB13>Parámetros!$T$4,"Catastrófico","Mayor"),"Moderado"),"Menor"),"Insignificante")) -> Moderado | BB13: =IF(U13="","",IF(AX13="",U13,ROUND(U13*(1-AX13),1))) -> 405000 | BC13: =IF(BB13="","",IF(AZ13*BB13=0,"",AZ13*BB13)) -> 44550 | BD13: =IF(BC13="","",INDEX(Parámetros!$Y$13:$AC$17,VLOOKUP(AY13,Parámetros!$W$13:$X$17,2,FALSE),HLOOKUP(BA13,Parámetros!$Y$11:$AC$12,2,FALSE))) -> Medio | BI13: =IF(BH13="","",VLOOKUP(BH13,Parámetros!$AW$3:$AX$6,2,FALSE)) | BO13: =IF(BE13="Aceptar",BC13,IF(BI13="","",(BC13*(1-BI13)))) | BP13: =IF(BO13="","",IF(BO13<=Parámetros!R41,Parámetros!S41,IF(BO13<=Parámetros!R40,Parámetros!S40,IF(BO13>=Parámetros!R39,Parámetros!S39,IF(BO13>=Parámetros!R38,Parámetros!S38,Parámetros!S37)))))
A14: 7 | H14: =IF(I14="","",CONCATENATE(I14," ","podría ocasionar"," ",J14," ", "generando"," ",K14)) -> Fallas en el sistema Bantotal podría ocasionar envien reporte reportes con información inconsistente generando multa de SBS | I14: Fallas en el sistema Bantotal | J14: envien reporte reportes con información inconsistente | K14: multa de SBS | L14: Tecnologia de Informacion | M14: Falta de Integridad | Q14: =IF(R14="","",IF(R14>Parámetros!$T$14,IF(R14>Parámetros!$T$13,IF(R14>Parámetros!$T$12,IF(R14>Parámetros!$T$11,"Muy Alta","Alta"),"Media"),"Baja"),"Muy Baja")) -> Alta | R14: 0.2 | T14: =IF(U14="","",IF(U14>Parámetros!$T$7,IF(U14>Parámetros!$T$6,IF(U14>Parámetros!$T$5,IF(U14>Parámetros!$T$4,"Catastrófico","Mayor"),"Moderado"),"Menor"),"Insignificante")) -> Moderado | U14: =100*4050 -> 405000 | V14: 100 UIT | W14: =IF(Q14="","",INDEX(Parámetros!$Y$13:$AC$17,VLOOKUP(Q14,Parámetros!$W$13:$X$17,2,FALSE),HLOOKUP(T14,Parámetros!$Y$11:$AC$12,2,FALSE))) -> Medio | AA14: Validación (1 o 2) de data antes de enviar el reporte | AB14: Manual de reportes regulatorios | AC14: carpeta compartida de Cumplimiento (cargos) | AE14: Periódico | AF14: Manual | AG14: Preventivo | AH14: Misma área | AI14: Nivel 2 | AJ14: SI | AK14: SI | AM14: =IF(AE14="","",VLOOKUP(AE14,Parámetros!$AE$3:$AF$5,2,FALSE)) -> 0.7 | AN14: =IF(AF14="","",VLOOKUP(AF14,Parámetros!$AH$3:$AI$5,2,FALSE)) -> 0.3 | AO14: =IF(AG14="","",VLOOKUP(AG14,Parámetros!$AK$3:$AL$4,2,FALSE)) -> 1 | AP14: =IF(AH14="","",VLOOKUP(AH14,Parámetros!$AN$3:$AO$5,2,FALSE)) -> 0.5 | AQ14: =IF(AI14="","",VLOOKUP(AI14,Parámetros!$AQ$3:$AR$5,2,FALSE)) -> 0.7 | AR14: =IF(AJ14="","",VLOOKUP(AJ14,Parámetros!$AT$3:$AU$4,2,FALSE)) -> 1 | AS14: =IF(AK14="","",VLOOKUP(AK14,Parámetros!$AT$3:$AU$4,2,FALSE)) -> 1 | AT14: =IF(R14="","",VLOOKUP(Q14,Parámetros!$R$10:$T$14,3,FALSE)) -> 0.33 | AU14: =+(AM14*0.2+AN14*0.2+AO14*0.2+AP14*0.2+AQ14*0.2)*(AR14*0.5+AS14*0.5) -> 0.64 | AV14: =+IF(AU14<0.9,IF(AU14<0.6,IF(AU14>0.3,"Moderado","Insastisfactorio"),"Bueno"),"Excelente") -> Bueno | AY14: =IF(AZ14="","",IF(AZ14<=Parámetros!$T$11,IF(AZ14<=Parámetros!$T$12,IF(AZ14<=Parámetros!$T$13,IF(AZ14<=Parámetros!$T$14,"Muy Baja","Baja"),"Media"),"Alta"),"Muy Alta")) -> Alta | AZ14: =IF(AT14="","",IF(AW14="",AT14,(AT14*(1-AW14)))) -> 0.33 | BA14: =IF(BB14="","",IF(BB14>Parámetros!$T$7,IF(BB14>Parámetros!$T$6,IF(BB14>Parámetros!$T$5,IF(BB14>Parámetros!$T$4,"Catastrófico","Mayor"),"Moderado"),"Menor"),"Insignificante")) -> Moderado | BB14: =IF(U14="","",IF(AX14="",U14,ROUND(U14*(1-AX14),1))) -> 405000 | BC14: =IF(BB14="","",IF(AZ14*BB14=0,"",AZ14*BB14)) -> 133650 | BD14: =IF(BC14="","",INDEX(Parámetros!$Y$13:$AC$17,VLOOKUP(AY14,Parámetros!$W$13:$X$17,2,FALSE),HLOOKUP(BA14,Parámetros!$Y$11:$AC$12,2,FALSE))) -> Medio | BI14: =IF(BH14="","",VLOOKUP(BH14,Parámetros!$AW$3:$AX$6,2,FALSE)) | BO14: =IF(BE14="Aceptar",BC14,IF(BI14="","",(BC14*(1-BI14)))) | BP14: =IF(BO14="","",IF(BO14<=Parámetros!R42,Parámetros!S42,IF(BO14<=Parámetros!R41,Parámetros!S41,IF(BO14>=Parámetros!R40,Parámetros!S40,IF(BO14>=Parámetros!R39,Parámetros!S39,Parámetros!S38)))))
A15: 8 | H15: =IF(I15="","",CONCATENATE(I15," ","podría ocasionar"," ",J15," ", "generando"," ",K15)) -> Omisión de personal (cumplimiento) podría ocasionar no se encuentre actualizada generando multa de SBS | I15: Omisión de personal (cumplimiento) | J15: no se encuentre actualizada | K15: multa de SBS | L15: Personal | M15: Omisión de Funciones | Q15: =IF(R15="","",IF(R15>Parámetros!$T$14,IF(R15>Parámetros!$T$13,IF(R15>Parámetros!$T$12,IF(R15>Parámetros!$T$11,"Muy Alta","Alta"),"Media"),"Baja"),"Muy Baja")) -> Media | R15: 0.05 | T15: =IF(U15="","",IF(U15>Parámetros!$T$7,IF(U15>Parámetros!$T$6,IF(U15>Parámetros!$T$5,IF(U15>Parámetros!$T$4,"Catastrófico","Mayor"),"Moderado"),"Menor"),"Insignificante")) -> Moderado | U15: =100*4050 -> 405000 | V15: 100 UIT | W15: =IF(Q15="","",INDEX(Parámetros!$Y$13:$AC$17,VLOOKUP(Q15,Parámetros!$W$13:$X$17,2,FALSE),HLOOKUP(T15,Parámetros!$Y$11:$AC$12,2,FALSE))) -> Medio | AA15: Validación mensual de cruce de listas negativas | AB15: Manual de registro, carga y cruce de lista negativas | AC15: Informe a Oficial de Cumplimiento | AE15: Periódico | AF15: Manual | AG15: Detectivo | AH15: Misma área | AI15: Nivel 2 | AJ15: SI | AK15: SI | AU15: =+(AM15*0.2+AN15*0.2+AO15*0.2+AP15*0.2+AQ15*0.2)*(AR15*0.5+AS15*0.5) -> 0 | AV15: =+IF(AU15<0.9,IF(AU15<0.6,IF(AU15>0.3,"Moderado","Insastisfactorio"),"Bueno"),"Excelente") -> Insastisfactorio
A16: 9 | H16: =IF(I16="","",CONCATENATE(I16," ","podría ocasionar"," ",J16," ", "generando"," ",K16)) -> Fallas en el sistema Bantotal (se registre y no lo tenga el sistema) podría ocasionar no se encuentre actualizada generando multa de SBS | I16: Fallas en el sistema Bantotal (se registre y no lo tenga el sistema) | J16: no se encuentre actualizada | K16: multa de SBS | L16: Tecnologia de Informacion | M16: Falta de Integridad | Q16: =IF(R16="","",IF(R16>Parámetros!$T$14,IF(R16>Parámetros!$T$13,IF(R16>Parámetros!$T$12,IF(R16>Parámetros!$T$11,"Muy Alta","Alta"),"Media"),"Baja"),"Muy Baja")) -> Media | R16: 0.05 | T16: =IF(U16="","",IF(U16>Parámetros!$T$7,IF(U16>Parámetros!$T$6,IF(U16>Parámetros!$T$5,IF(U16>Parámetros!$T$4,"Catastrófico","Mayor"),"Moderado"),"Menor"),"Insignificante")) -> Moderado | U16: =100*4050 -> 405000 | V16: 100 UIT | W16: =IF(Q16="","",INDEX(Parámetros!$Y$13:$AC$17,VLOOKUP(Q16,Parámetros!$W$13:$X$17,2,FALSE),HLOOKUP(T16,Parámetros!$Y$11:$AC$12,2,FALSE))) -> Medio | AA16: Validación mensual de cruce de listas negativas | AB16: Manual de registro, carga y cruce de lista negativas | AC16: Informe a Oficial de Cumplimiento | AE16: Periódico | AF16: Manual | AG16: Detectivo | AH16: Misma área | AI16: Nivel 2 | AJ16: SI | AK16: SI | AM16: =IF(AE16="","",VLOOKUP(AE16,Parámetros!$AE$3:$AF$5,2,FALSE)) -> 0.7 | AN16: =IF(AF16="","",VLOOKUP(AF16,Parámetros!$AH$3:$AI$5,2,FALSE)) -> 0.3 | AO16: =IF(AG16="","",VLOOKUP(AG16,Parámetros!$AK$3:$AL$4,2,FALSE)) -> 0.5 | AP16: =IF(AH16="","",VLOOKUP(AH16,Parámetros!$AN$3:$AO$5,2,FALSE)) -> 0.5 | AQ16: =IF(AI16="","",VLOOKUP(AI16,Parámetros!$AQ$3:$AR$5,2,FALSE)) -> 0.7 | AR16: =IF(AJ16="","",VLOOKUP(AJ16,Parámetros!$AT$3:$AU$4,2,FALSE)) -> 1 | AS16: =IF(AK16="","",VLOOKUP(AK16,Parámetros!$AT$3:$AU$4,2,FALSE)) -> 1 | AT16: =IF(R16="","",VLOOKUP(Q16,Parámetros!$R$10:$T$14,3,FALSE)) -> 0.11 | AU16: =+(AM16*0.2+AN16*0.2+AO16*0.2+AP16*0.2+AQ16*0.2)*(AR16*0.5+AS16*0.5) -> 0.54 | AV16: =+IF(AU16<0.9,IF(AU16<0.6,IF(AU16>0.3,"Moderado","Insastisfactorio"),"Bueno"),"Excelente") -> Moderado | AY16: =IF(AZ16="","",IF(AZ16<=Parámetros!$T$11,IF(AZ16<=Parámetros!$T$12,IF(AZ16<=Parámetros!$T$13,IF(AZ16<=Parámetros!$T$14,"Muy Baja","Baja"),"Media"),"Alta"),"Muy Alta")) -> Media | AZ16: =IF(AT16="","",IF(AW16="",AT16,(AT16*(1-AW16)))) -> 0.11 | BA16: =IF(BB16="","",IF(BB16>Parámetros!$T$7,IF(BB16>Parámetros!$T$6,IF(BB16>Parámetros!$T$5,IF(BB16>Parámetros!$T$4,"Catastrófico","Mayor"),"Moderado"),"Menor"),"Insignificante")) -> Moderado | BB16: =IF(U16="","",IF(AX16="",U16,ROUND(U16*(1-AX16),1))) -> 405000 | BC16: =IF(BB16="","",IF(AZ16*BB16=0,"",AZ16*BB16)) -> 44550 | BD16: =IF(BC16="","",INDEX(Parámetros!$Y$13:$AC$17,VLOOKUP(AY16,Parámetros!$W$13:$X$17,2,FALSE),HLOOKUP(BA16,Parámetros!$Y$11:$AC$12,2,FALSE))) -> Medio | BI16: =IF(BH16="","",VLOOKUP(BH16,Parámetros!$AW$3:$AX$6,2,FALSE)) | BO16: =IF(BE16="Aceptar",BC16,IF(BI16="","",(BC16*(1-BI16)))) | BP16: =IF(BO16="","",IF(BO16<=Parámetros!R43,Parámetros!S43,IF(BO16<=Parámetros!R42,Parámetros!S42,IF(BO16>=Parámetros!R41,Parámetros!S41,IF(BO16>=Parámetros!R40,Parámetros!S40,Parámetros!S39)))))
AA17: Sistema Assit, tiene una regla que revisa los clientes que se encuentran en lista negras y emite alerta | AB17: Manual de registro, carga y cruce de lista negativas | AC17: Informe a Oficial de Cumplimiento | AE17: Periódico | AF17: Automático | AG17: Detectivo | AH17: Misma área | AI17: Nivel 3 | AJ17: SI | AK17: SI | AM17: =IF(AE17="","",VLOOKUP(AE17,Parámetros!$AE$3:$AF$5,2,FALSE)) -> 0.7 | AN17: =IF(AF17="","",VLOOKUP(AF17,Parámetros!$AH$3:$AI$5,2,FALSE)) -> 1 | AO17: =IF(AG17="","",VLOOKUP(AG17,Parámetros!$AK$3:$AL$4,2,FALSE)) -> 0.5 | AP17: =IF(AH17="","",VLOOKUP(AH17,Parámetros!$AN$3:$AO$5,2,FALSE)) -> 0.5 | AQ17: =IF(AI17="","",VLOOKUP(AI17,Parámetros!$AQ$3:$AR$5,2,FALSE)) -> 1 | AR17: =IF(AJ17="","",VLOOKUP(AJ17,Parámetros!$AT$3:$AU$4,2,FALSE)) -> 1 | AS17: =IF(AK17="","",VLOOKUP(AK17,Parámetros!$AT$3:$AU$4,2,FALSE)) -> 1 | AT17: =IF(R17="","",VLOOKUP(Q17,Parámetros!$R$10:$T$14,3,FALSE)) | AU17: =+(AM17*0.2+AN17*0.2+AO17*0.2+AP17*0.2+AQ17*0.2)*(AR17*0.5+AS17*0.5) -> 0.74 | AV17: =+IF(AU17<0.9,IF(AU17<0.6,IF(AU17>0.3,"Moderado","Insastisfactorio"),"Bueno"),"Excelente") -> Bueno | BC17: =IF(BB17="","",IF(AZ17*BB17=0,"",AZ17*BB17)) | BI17: =IF(BH17="","",VLOOKUP(BH17,Parámetros!$AW$3:$AX$6,2,FALSE)) | BO17: =IF(BE17="Aceptar",BC17,IF(BI17="","",(BC17*(1-BI17))))
BI18: =IF(BH18="","",VLOOKUP(BH18,Parámetros!$AW$3:$AX$6,2,FALSE))
BI19: =IF(BH19="","",VLOOKUP(BH19,Parámetros!$AW$3:$AX$6,2,FALSE))
BC20: =IF(AZ20*BB20=0,"",AZ20*BB20) | BI20: =IF(BH20="","",VLOOKUP(BH20,Parámetros!$AW$3:$AX$6,2,FALSE)) | BO20: =IF(BM20*#REF!=0,"",BM20*#REF!) -> #REF!
BC21: =IF(AZ21*BB21=0,"",AZ21*BB21) | BI21: =IF(BH21="","",VLOOKUP(BH21,Parámetros!$AW$3:$AX$6,2,FALSE)) | BO21: =IF(BM21*#REF!=0,"",BM21*#REF!) -> #REF!
BC22: =IF(AZ22*BB22=0,"",AZ22*BB22) | BI22: =IF(BH22="","",VLOOKUP(BH22,Parámetros!$AW$3:$AX$6,2,FALSE)) | BO22: =IF(BM22*#REF!=0,"",BM22*#REF!) -> #REF!
BC23: =IF(AZ23*BB23=0,"",AZ23*BB23) | BI23: =IF(BH23="","",VLOOKUP(BH23,Parámetros!$AW$3:$AX$6,2,FALSE)) | BO23: =IF(BM23*#REF!=0,"",BM23*#REF!) -> #REF!
BC24: =IF(AZ24*BB24=0,"",AZ24*BB24) | BI24: =IF(BH24="","",VLOOKUP(BH24,Parámetros!$AW$3:$AX$6,2,FALSE)) | BO24: =IF(BM24*#REF!=0,"",BM24*#REF!) -> #REF!
BC25: =IF(AZ25*BB25=0,"",AZ25*BB25) | BI25: =IF(BH25="","",VLOOKUP(BH25,Parámetros!$AW$3:$AX$6,2,FALSE)) | BO25: =IF(BM25*#REF!=0,"",BM25*#REF!) -> #REF!
BC26: =IF(AZ26*BB26=0,"",AZ26*BB26) | BI26: =IF(BH26="","",VLOOKUP(BH26,Parámetros!$AW$3:$AX$6,2,FALSE)) | BO26: =IF(BM26*#REF!=0,"",BM26*#REF!) -> #REF!
BC27: =IF(AZ27*BB27=0,"",AZ27*BB27) | BI27: =IF(BH27="","",VLOOKUP(BH27,Parámetros!$AW$3:$AX$6,2,FALSE)) | BO27: =IF(BM27*#REF!=0,"",BM27*#REF!) -> #REF!
BC28: =IF(AZ28*BB28=0,"",AZ28*BB28) | BI28: =IF(BH28="","",VLOOKUP(BH28,Parámetros!$AW$3:$AX$6,2,FALSE)) | BO28: =IF(BM28*#REF!=0,"",BM28*#REF!) -> #REF!
BC29: =IF(AZ29*BB29=0,"",AZ29*BB29) | BI29: =IF(BH29="","",VLOOKUP(BH29,Parámetros!$AW$3:$AX$6,2,FALSE)) | BO29: =IF(BM29*#REF!=0,"",BM29*#REF!) -> #REF!
BC30: =IF(AZ30*BB30=0,"",AZ30*BB30) | BI30: =IF(BH30="","",VLOOKUP(BH30,Parámetros!$AW$3:$AX$6,2,FALSE)) | BO30: =IF(BM30*#REF!=0,"",BM30*#REF!) -> #REF!
BC31: =IF(AZ31*BB31=0,"",AZ31*BB31) | BI31: =IF(BH31="","",VLOOKUP(BH31,Parámetros!$AW$3:$AX$6,2,FALSE)) | BO31: =IF(BM31*#REF!=0,"",BM31*#REF!) -> #REF!

Sheet Sustentos
B2: PROBABILIDAD E IMPACTO
B6: IdRiesgo | C6: 1 | H6: Titulo del Riesgo | I6: =IF(C6="","",VLOOKUP(C6,'SARO-02'!$A$5:$H$517,7,FALSE)) -> Fallas en gestión de alertas | L6: IdRiesgo | R6: Titulo del Riesgo | S6: =IF(M6="","",VLOOKUP(M6,'SARO-02'!$A$5:$H$517,7,FALSE))
B7: Riesgo: | C7: =IF(C6="","",VLOOKUP(C6,'SARO-02'!$A$5:$H$517,8,FALSE)) -> Fallas en registro u omisión de reporte de clientes (Funcionario o…) podría ocasionar no reportemos operacions sospechosas o inusuales a SBS generando multa de SBS o UIF | L7: Riesgo: | M7: =IF(M6="","",VLOOKUP(M6,'SARO-02'!$A$5:$H$517,8,FALSE))
B9: - "N" del PROCESO | D9: =90*12 -> 1080 | L9: - "N" del PROCESO
B11: Probabilidad | L11: Probabilidad
B12: Variables consideradas: | F12: Supuestos: | L12: Variables consideradas: | P12: Supuestos:
B13: - xxx | F13: - Supuesto 1: | L13: - xxx | P13: - Supuesto 1:
B14: - xxxx | F14: - Supuesto 2: | L14: - xxxx | P14: - Supuesto 2:
B16: Impacto Estimado: | L16: Impacto Estimado:
B17: Variables consideradas: | F17: Supuestos: | L17: Variables consideradas: | P17: Supuestos:
B18: - xxx | F18: - Supuesto 1: | L18: - xxx | P18: - Supuesto 1:
B19: - xxxx | F19: - Supuesto 2: | L19: - xxxx | P19: - Supuesto 2:
B20: - xxxx | F20: - Supuesto 3: | L20: - xxxx | P20: - Supuesto 3:
B21: - xxxx | F21: - Supuesto 4: | L21: - xxxx | P21: - Supuesto 4:
B24: IdRiesgo | H24: Titulo del Riesgo | I24: =IF(C24="","",VLOOKUP(C24,'SARO-02'!$A$5:$H$517,7,FALSE)) | L24: IdRiesgo | R24: Titulo del Riesgo | S24: =IF(M24="","",VLOOKUP(M24,'SARO-02'!$A$5:$H$517,7,FALSE))
B25: Riesgo: | C25: =IF(C24="","",VLOOKUP(C24,'SARO-02'!$A$5:$H$517,8,FALSE)) | L25: Riesgo: | M25: =IF(M24="","",VLOOKUP(M24,'SARO-02'!$A$5:$H$517,8,FALSE))
B27: - "N" del PROCESO | L27: - "N" del PROCESO
B29: Probabilidad | L29: Probabilidad
B30: Variables consideradas: | F30: Supuestos: | L30: Variables consideradas: | P30: Supuestos:
B31: - xxx | F31: - Supuesto 1: | L31: - xxx | P31: - Supuesto 1:
B32: - xxxx | F32: - Supuesto 2: | L32: - xxxx | P32: - Supuesto 2:
B34: Impacto Estimado: | L34: Impacto Estimado:
B35: Variables consideradas: | F35: Supuestos: | L35: Variables consideradas: | P35: Supuestos:
B36: - xxx | F36: - Supuesto 1: | L36: - xxx | P36: - Supuesto 1:
B37: - xxxx | F37: - Supuesto 2: | L37: - xxxx | P37: - Supuesto 2:
B38: - xxxx | F38: - Supuesto 3: | L38: - xxxx | P38: - Supuesto 3:
B39: - xxxx | F39: - Supuesto 4: | L39: - xxxx | P39: - Supuesto 4:
B42: IdRiesgo | H42: Titulo del Riesgo | I42: =IF(C42="","",VLOOKUP(C42,'SARO-02'!$A$5:$H$517,7,FALSE)) | L42: IdRiesgo | R42: Titulo del Riesgo | S42: =IF(M42="","",VLOOKUP(M42,'SARO-02'!$A$5:$H$517,7,FALSE))
B43: Riesgo: | C43: =IF(C42="","",VLOOKUP(C42,'SARO-02'!$A$5:$H$517,8,FALSE)) | L43: Riesgo: | M43: =IF(M42="","",VLOOKUP(M42,'SARO-02'!$A$5:$H$517,8,FALSE))
B45: - "N" del PROCESO | L45: - "N" del PROCESO
B47: Probabilidad | L47: Probabilidad
B48: Variables consideradas: | F48: Supuestos: | L48: Variables consideradas: | P48: Supuestos:
B49: - xxx | F49: - Supuesto 1: | L49: - xxx | P49: - Supuesto 1:
B50: - xxxx | F50: - Supuesto 2: | L50: - xxxx | P50: - Supuesto 2:
B52: Impacto Estimado: | L52: Impacto Estimado:
B53: Variables consideradas: | F53: Supuestos: | L53: Variables consideradas: | P53: Supuestos:
B54: - xxx | F54: - Supuesto 1: | L54: - xxx | P54: - Supuesto 1:
B55: - xxxx | F55: - Supuesto 2: | L55: - xxxx | P55: - Supuesto 2:
B56: - xxxx | F56: - Supuesto 3: | L56: - xxxx | P56: - Supuesto 3:
B57: - xxxx | F57: - Supuesto 4: | L57: - xxxx | P57: - Supuesto 4:
...

Sheet Riesgo Materializado
B2: IdRiesgo | G2: Nombre Riesgo
B3: Riesgo:
B5: Mes | C5: 2014 | E5: 2015 | G5: 2016 | I5: 2017 | K5: Total general
C6: Monto (S/.)* | D6: Eventos/ Incidentes (Nro.) | E6: Monto (S/.)* | F6: Eventos/ Incidentes (Nro.) | G6: Monto (S/.)* | H6: Eventos/ Incidentes (Nro.) | I6: Monto (S/.)* | J6: Eventos/ Incidentes (Nro.) | K6: Total Monto (S/.)* | L6: Total Eventos/ Incidentes (Nro.)
B7: Enero | K7: =SUM(C7,E7,G7,I7) -> 0 | L7: =SUM(D7,F7,H7,J7) -> 0
B8: Febrero | K8: =SUM(C8,E8,G8,I8) -> 0 | L8: =SUM(D8,F8,H8,J8) -> 0
B9: Marzo | K9: =SUM(C9,E9,G9,I9) -> 0 | L9: =SUM(D9,F9,H9,J9) -> 0
B10: Abril | K10: =SUM(C10,E10,G10,I10) -> 0 | L10: =SUM(D10,F10,H10,J10) -> 0
B11: Mayo | K11: =SUM(C11,E11,G11,I11) -> 0 | L11: =SUM(D11,F11,H11,J11) -> 0
B12: Junio | K12: =SUM(C12,E12,G12,I12) -> 0 | L12: =SUM(D12,F12,H12,J12) -> 0
B13: Julio | K13: =SUM(C13,E13,G13,I13) -> 0 | L13: =SUM(D13,F13,H13,J13) -> 0
B14: Agosto | K14: =SUM(C14,E14,G14,I14) -> 0 | L14: =SUM(D14,F14,H14,J14) -> 0
B15: Septiembre | K15: =SUM(C15,E15,G15,I15) -> 0 | L15: =SUM(D15,F15,H15,J15) -> 0
B16: Octubre | K16: =SUM(C16,E16,G16,I16) -> 0 | L16: =SUM(D16,F16,H16,J16) -> 0
B17: Noviembre | K17: =SUM(C17,E17,G17,I17) -> 0 | L17: =SUM(D17,F17,H17,J17) -> 0
B18: Diciembre | K18: =SUM(C18,E18,G18,I18) -> 0 | L18: =SUM(D18,F18,H18,J18) -> 0
B19: Total general | C19: =SUM(C7:C18) -> 0 | D19: =SUM(D7:D18) -> 0 | E19: =SUM(E7:E18) -> 0 | F19: =SUM(F7:F18) -> 0 | G19: =SUM(G7:G18) -> 0 | H19: =SUM(H7:H18) -> 0 | I19: =SUM(I7:I18) -> 0 | J19: =SUM(J7:J18) -> 0 | ... L19: =SUM(L7:L18) -> 0
B24: IdRiesgo | G24: Nombre Riesgo
B25: Riesgo:
B27: Mes | C27: 2014 | E27: 2015 | G27: 2016 | I27: 2017 | K27: Total general
C28: Monto (S/.)* | D28: Eventos/ Incidentes (Nro.) | E28: Monto (S/.)* | F28: Eventos/ Incidentes (Nro.) | G28: Monto (S/.)* | H28: Eventos/ Incidentes (Nro.) | I28: Monto (S/.)* | J28: Eventos/ Incidentes (Nro.) | K28: Total Monto (S/.)* | L28: Total Eventos/ Incidentes (Nro.)
B29: Enero | K29: =SUM(C29,E29,G29,I29) -> 0 | L29: =SUM(D29,F29,H29,J29) -> 0
B30: Febrero | K30: =SUM(C30,E30,G30,I30) -> 0 | L30: =SUM(D30,F30,H30,J30) -> 0
B31: Marzo | K31: =SUM(C31,E31,G31,I31) -> 0 | L31: =SUM(D31,F31,H31,J31) -> 0
B32: Abril | K32: =SUM(C32,E32,G32,I32) -> 0 | L32: =SUM(D32,F32,H32,J32) -> 0
B33: Mayo | K33: =SUM(C33,E33,G33,I33) -> 0 | L33: =SUM(D33,F33,H33,J33) -> 0
B34: Junio | K34: =SUM(C34,E34,G34,I34) -> 0 | L34: =SUM(D34,F34,H34,J34) -> 0
B35: Julio | K35: =SUM(C35,E35,G35,I35) -> 0 | L35: =SUM(D35,F35,H35,J35) -> 0
B36: Agosto | K36: =SUM(C36,E36,G36,I36) -> 0 | L36: =SUM(D36,F36,H36,J36) -> 0
B37: Septiembre | K37: =SUM(C37,E37,G37,I37) -> 0 | L37: =SUM(D37,F37,H37,J37) -> 0
B38: Octubre | K38: =SUM(C38,E38,G38,I38) -> 0 | L38: =SUM(D38,F38,H38,J38) -> 0
B39: Noviembre | K39: =SUM(C39,E39,G39,I39) -> 0 | L39: =SUM(D39,F39,H39,J39) -> 0
B40: Diciembre | K40: =SUM(C40,E40,G40,I40) -> 0 | L40: =SUM(D40,F40,H40,J40) -> 0
B41: Total general | C41: =SUM(C29:C40) -> 0 | D41: =SUM(D29:D40) -> 0 | E41: =SUM(E29:E40) -> 0 | F41: =SUM(F29:F40) -> 0 | G41: =SUM(G29:G40) -> 0 | H41: =SUM(H29:H40) -> 0 | I41: =SUM(I29:I40) -> 0 | J41: =SUM(J29:J40) -> 0 | ... L41: =SUM(L29:L40) -> 0
B47: IdRiesgo | G47: Nombre Riesgo
B48: Riesgo:
B50: Mes | C50: 2014 | E50: 2015 | G50: 2016 | I50: 2017 | K50: Total general
C51: Monto (S/.)* | D51: Eventos/ Incidentes (Nro.) | E51: Monto (S/.)* | F51: Eventos/ Incidentes (Nro.) | G51: Monto (S/.)* | H51: Eventos/ Incidentes (Nro.) | I51: Monto (S/.)* | J51: Eventos/ Incidentes (Nro.) | K51: Total Monto (S/.)* | L51: Total Eventos/ Incidentes (Nro.)
B52: Enero | K52: =SUM(C52,E52,G52,I52) -> 0 | L52: =SUM(D52,F52,H52,J52) -> 0
B53: Febrero | K53: =SUM(C53,E53,G53,I53) -> 0 | L53: =SUM(D53,F53,H53,J53) -> 0
...

Sheet Parámetros
B1: PROCESOS DE BANCO GNB | N1: TIPO DE EVENTO | R1: Criterio de IMPACTO
B2: ID | C2: Macro Proceso | E2: Proceso | G2: Subproceso | I2: Tipo | J2: Macro Proceso | K2: Proceso | L2: Sub Proceso | N2: NIVEL 1 | P2: NIVEL 2 | R2: Impacto | S2: Límite inferior | T2: Límite superior | AE2: Periodicidad | AF2: Valor | AH2: Operatividad | AI2: Valor | AK2: Tipo de Control | AL2: Valor | AN2: Segregación | AO2: Valor | AQ2: Supervisión | AR2: Valor | AT2: Ejecución | AU2: Valor | AW2: CALIFICACIÓN DEL CONTROL
B3: 1 | C3: Planeamiento y Desarrollo | E3: Gestión de Planeamiento Estratégico | G3: Elaboración y aprobación del Planeamiento Estratégico | I3: E | J3: 1 | K3: 1 | L3: 1 | M3: =CONCATENATE(#REF!,-L3) -> #REF! | N3: Fraude interno | P3: Fraude interno | R3: Catastrófico | S3: 1930000.1 | T3: 5800000 | AE3: Permanente | AF3: 1 | AH3: Automático | AI3: 1 | AK3: Preventivo | AL3: 1 | AN3: Otra área o automático | AO3: 1 | AQ3: Nivel 3 | AR3: 1 | AT3: SI | AU3: 1 | AW3: Insatisfactorio | AX3: 0.2999
B4: 2 | C4: Control Presupuestal | E4: Gestión de Marketing | G4: Desarrollo de Canales, Productos y Servicios | I4: E | J4: 1 | K4: 2 | L4: 1 | M4: =CONCATENATE(#REF!,-L4) -> #REF! | N4: Fraude externo | P4: Actividades no autorizadas | R4: Mayor | S4: 640000.1 | T4: 1930000 | AE4: Periódico | AF4: 0.7 | AH4: Semiautomático | AI4: 0.7 | AK4: Detectivo | AL4: 0.5 | AN4: Misma área | AO4: 0.5 | AQ4: Nivel 2 | AR4: 0.7 | AT4: NO | AU4: 0 | AW4: Moderado | AX4: 0.5999
B5: 3 | C5: Clientes | E5: Desarrollo y Administración del Presupuesto | G5: Desarrollo de Campañas | I5: E | J5: 1 | K5: 2 | L5: 2 | M5: =CONCATENATE(#REF!,-L5) -> #REF! | N5: Relaciones laborales y seguridad en el puesto de trabajo | P5: Robo y fraude | R5: Moderado | S5: 210000.1 | T5: 640000 | AE5: Eventual | AF5: 0.3 | AH5: Manual | AI5: 0.3 | AQ5: Nivel 1 | AR5: 0.3 | AW5: Bueno | AX5: 0.8999
B6: 4 | C6: Fondeo | E6: Vinculación | G6: Desarrollo de Alianzas Comerciales | I6: E | J6: 1 | K6: 2 | L6: 3 | M6: =CONCATENATE(#REF!,-L6) -> #REF! | N6: Clientes, productos y prácticas empresariales | P6: Fraude externo | R6: Menor | S6: 70000.1 | T6: 210000 | AW6: Excelente | AX6: 1
B7: 5 | C7: Inversiones y Mesa de Dinero | E7: Gestión de Calidad y Servicio al Cliente | G7: Desarrollo de la Estrategia Comercial | I7: E | J7: 1 | K7: 2 | L7: 4 | M7: =CONCATENATE(#REF!,-L7) -> #REF! | N7: Daños a activos materiales | P7: Robo y fraude | R7: Insignificante | S7: 0 | T7: 70000
B8: 6 | C8: Colocaciones | E8: Captación de Productos | G8: Gestión de Marca | I8: E | J8: 1 | K8: 2 | L8: 5 | M8: =CONCATENATE(#REF!,-L8) -> #REF! | N8: Interrupción del negocio y fallos en los sistemas | P8: Seguridad de los sistemas
B9: 7 | C9: Servicios Bancarios | E9: Transaccionalidad | G9: Elaboración, aprobación y control del presupuesto | I9: E | J9: 2 | K9: 1 | L9: 1 | M9: =CONCATENATE(#REF!,-L9) -> #REF! | N9: Ejecución, entrega y gestión de procesos | P9: Relaciones laborales y seguridad en el puesto de trabajo | R9: Probabilidad | S9: % Inferior | T9: % Superior
B10: 8 | C10: Gestión de Riesgos | E10: Fondeo de Recursos | G10: Vinculación PJ | I10: C | J10: 1 | K10: 1 | L10: 1 | M10: =CONCATENATE(#REF!,-L10) -> #REF! | P10: Relaciones laborales | R10: Muy Alta | S10: 0.331 | T10: 1 | Y10: IMPACTO
B11: 9 | C11: Gestión Legal | E11: Inversiones Financieras | G11: Vinculación PN | I11: C | J11: 1 | K11: 1 | L11: 2 | M11: =CONCATENATE(#REF!,-L11) -> #REF! | P11: Higiene y seguridad en el trabajo | R11: Alta | S11: 0.111 | T11: 0.33 | Y11: Insignificante | Z11: Menor | AA11: Moderado | AB11: Mayor | AC11: Catastrófico
B12: 10 | C12: Gestión de RRHH | E12: Mesa de Dinero | G12: Mantenimiento de Datos de Clientes | I12: C | J12: 1 | K12: 1 | L12: 3 | M12: =CONCATENATE(#REF!,-L12) -> #REF! | P12: Diversidad y discriminación | R12: Media | S12: 0.041 | T12: 0.11 | Y12: 1 | Z12: 2 | AA12: 3 | AB12: 4 | AC12: 5
B13: 11 | C13: Gestión de Procesos | E13: Otorgamiento de Créditos | G13: Gestión de Atención de Solicitudes, Requerimientos y Reclamos | I13: C | J13: 1 | K13: 2 | L13: 1 | M13: =CONCATENATE(#REF!,-L13) -> #REF! | P13: Clientes, productos y prácticas empresariales | R13: Baja | S13: 0.011 | T13: 0.04 | V13: PROBABILIDAD | W13: Muy Alta | X13: 1 | Y13: Medio | Z13: Medio | AA13: Alto | AB13: Extremo | AC13: Extremo
B14: 12 | C14: Gestión de Administración | E14: Transaccionalidad PostDesembolso | G14: Gestión de Atención al Usuario y Transparencia | I14: C | J14: 1 | K14: 2 | L14: 2 | M14: =CONCATENATE(#REF!,-L14) -> #REF! | P14: Adecuación, divulgación de información y confianza | R14: Muy Baja | S14: 0 | T14: 0.01 | W14: Alta | X14: 2 | Y14: Bajo | Z14: Medio | AA14: Medio | AB14: Alto | AC14: Extremo
B15: 13 | C15: Gestión de Operaciones | E15: Gestión de Garantías | G15: Administración del Call Center (inbound y outbound) | I15: C | J15: 1 | K15: 2 | L15: 3 | M15: =CONCATENATE(#REF!,-L15) -> #REF! | P15: Prácticas empresariales o de mercado improcedentes | W15: Media | X15: 3 | Y15: Muy Bajo | Z15: Bajo | AA15: Medio | AB15: Medio | AC15: Alto
B16: 14 | C16: Gestión de Tecnología de Información | E16: Compra de Cartera | G16: Gestión de Retención de Clientes | I16: C | J16: 1 | K16: 2 | L16: 4 | M16: =CONCATENATE(#REF!,-L16) -> #REF! | P16: Productos defectuosos | W16: Baja | X16: 4 | Y16: Muy Bajo | Z16: Bajo | AA16: Bajo | AB16: Medio | AC16: Medio
B17: 15 | C17: Gestión Financiera y Contable | E17: Banca corresponsal | G17: Gestión del Portafolio de Clientes | I17: C | J17: 1 | K17: 2 | L17: 5 | M17: =CONCATENATE(#REF!,-L17) -> #REF! | P17: Selección, patrocinio y riesgos | W17: Muy Baja | X17: 5 | Y17: Muy Bajo | Z17: Muy Bajo | AA17: Muy Bajo | AB17: Bajo | AC17: Bajo
B18: 16 | C18: Gestión de Cobranzas y Recuperaciones | E18: Gestión de Servicios asociados a la Banca x internet | G18: Propección, venta y afiliación a C Ahorros | I18: C | J18: 2 | K18: 1 | L18: 1 | M18: =CONCATENATE(#REF!,-L18) -> #REF! | P18: Actividades de asesoramiento
B19: 17 | C19: Control Interno | E19: Gestión de Transferencias | G19: Propección, venta y afiliación a C Corriente | I19: C | J19: 2 | K19: 1 | L19: 2 | M19: =CONCATENATE(#REF!,-L19) -> #REF! | P19: Daños a activos materiales
E20: Gestión de Seguros | G20: Propección, venta y afiliación a CTS | I20: C | J20: 2 | K20: 1 | L20: 3 | M20: =CONCATENATE(#REF!,-L20) -> #REF! | P20: Desastres y otros acontecimientos | R20: Niveles de Criticidad | S20: Límite Inferior | T20: Límite Superior
E21: Recaudación | G21: Propección, venta y afiliación a DPF | I21: C | J21: 2 | K21: 1 | L21: 4 | M21: =CONCATENATE(#REF!,-L21) -> #REF! | P21: Interrupción del negocio y fallos en los sistemas | R21: Muy Bajo | S21: 640000.1 | T21: 5800000
E22: Gestión de Riesgo Crediticio y Cambiario | G22: Depósitos | I22: C | J22: 2 | K22: 2 | L22: 1 | M22: =CONCATENATE(#REF!,-L22) -> #REF! | P22: Sistemas | R22: Bajo | S22: 232000.1 | T22: 640000 | Y22: IMPACTO
E23: Gestión del Riesgo de Liquidez | G23: Retiros | I23: C | J23: 2 | K23: 2 | L23: 2 | M23: =CONCATENATE(#REF!,-L23) -> #REF! | P23: Ejecución, entrega y gestión de procesos | R23: Medio | S23: 58000.1 | T23: 232000 | Y23: Insignificante | Z23: Menor | AA23: Moderado | AB23: Mayor | AC23: Catastrófico
E24: Gestión del Riesgo de Mercado | G24: Cierre de Cuentas | I24: C | J24: 2 | K24: 2 | L24: 3 | M24: =CONCATENATE(#REF!,-L24) -> #REF! | P24: Recepción, ejecución y mantenimiento de operaciones | R24: Alto | S24: 7700.1 | T24: 58000 | Y24: 70000 | Z24: 210000 | AA24: 640000 | AB24: 1930000 | AC24: 5800000
E25: Clasificación de Cartera y Gestión de Provisiones | G25: Activación de Cuentas/FSD | I25: C | J25: 2 | K25: 2 | L25: 4 | M25: =CONCATENATE(#REF!,-L25) -> #REF! | P25: Seguimiento y presentación de informes | R25: Extremo | S25: 0 | T25: 7700 | V25: PROBABILIDAD | W25: Muy Alta | X25: 1 | Y25: 70000 | Z25: 210000 | AA25: 640000 | AB25: 1930000 | AC25: 5800000
E26: Gestión de la Continuidad del Negocio | G26: Gestión de Bonos Corporativos | I26: C | J26: 2 | K26: 3 | L26: 1 | M26: =CONCATENATE(#REF!,-L26) -> #REF! | P26: Aceptación de clientes y documentación | W26: Alta | X26: 0.33 | Y26: 23100 | Z26: 69300 | AA26: 211200 | AB26: 636900 | AC26: 1914000
E27: Gestión de Riesgo Operacional | G27: Gestión Líneas de Fondeo | I27: C | J27: 2 | K27: 3 | L27: 2 | M27: =CONCATENATE(#REF!,-L27) -> #REF! | P27: Gestión de cuentas de clientes | W27: Media | X27: 0.11 | Y27: 7700 | Z27: 23100 | AA27: 70400 | AB27: 212300 | AC27: 638000
E28: Gestión de Seguridad de la Información | G28: Gestión de Adeudados | I28: C | J28: 3 | K28: 1 | L28: 1 | M28: =CONCATENATE(#REF!,-L28) -> #REF! | P28: Contrapartes comerciales | W28: Baja | X28: 0.04 | Y28: 2800 | Z28: 8400 | AA28: 25600 | AB28: 77200 | AC28: 232000
E29: Gestión del Riesgo Ambiental | G29: Gestión de Forwards | I29: C | J29: 3 | K29: 1 | L29: 2 | M29: =CONCATENATE(#REF!,-L29) -> #REF! | P29: Distribuidores y proveedores | W29: Muy Baja | X29: 0.01 | Y29: 700 | Z29: 2100 | AA29: 6400 | AB29: 19300 | AC29: 58000
E30: Gestión Secretaría General | G30: Préstamos Interbancarios | I30: C | J30: 3 | K30: 1 | L30: 3 | M30: =CONCATENATE(#REF!,-L30) -> #REF! | R30: Límite inferior | S30: Nivel
E31: Gestión de Contratos | G31: Gestión de Compra y Venta de ME | I31: C | J31: 3 | K31: 2 | L31: 1 | M31: =CONCATENATE(#REF!,-L31) -> #REF! | R31: 5800000 | S31: Extremo
E32: Gestión de Poderes | G32: Operaciones de Mesa de Dinero | I32: C | J32: 3 | K32: 2 | L32: 2 | M32: =CONCATENATE(#REF!,-L32) -> #REF! | R32: 640000 | S32: Alto
C33: Probabilidad | E33: Gestión de Procesos Legales | G33: Otorgamiento de préstamos para personas | I33: C | J33: 4 | K33: 1 | L33: 1 | M33: =CONCATENATE(#REF!,-L33) -> #REF! | R33: 232000 | S33: Medio
C34: Impacto | E34: Gestión de Embargos | G34: Otorgamiento de Préstamos Hipotecarios | I34: C | J34: 4 | K34: 1 | L34: 2 | M34: =CONCATENATE(#REF!,-L34) -> #REF! | R34: 58000 | S34: Bajo
C35: Ambos | E35: Reclutamiento y selección de personal | G35: Otorgamiento de Préstamos Vehicular | I35: C | J35: 4 | K35: 1 | L35: 3 | M35: =CONCATENATE(#REF!,-L35) -> #REF! | R35: 7700 | S35: Muy Bajo
E36: Gestión del Colaborador | G36: Otorgamiento de préstamos CNV | I36: C | J36: 4 | K36: 1 | L36: 4 | M36: =CONCATENATE(#REF!,-L36) -> #REF!
E37: Compensaciones del Colaborador | G37: Otorgamiento de Tarjetas de Crédito | I37: C | J37: 4 | K37: 1 | L37: 5 | M37: =CONCATENATE(#REF!,-L37) -> #REF!
C38: Medidas de Tratamiento | E38: Gestión Normativa | G38: Asignación/Reducción de Linea TC | I38: C | J38: 4 | K38: 1 | L38: 6 | M38: =CONCATENATE(#REF!,-L38) -> #REF!
C39: Evitar | E39: Proceso de atención de proyectos y requerimientos | G39: Otorgamiento de préstamos para empresas | I39: C | J39: 4 | K39: 1 | L39: 7 | M39: =CONCATENATE(#REF!,-L39) -> #REF!
C40: Transferir | E40: Adquisiciones | G40: Otorgamiento de préstamos Leasing | I40: C | J40: 4 | K40: 1 | L40: 8 | M40: =CONCATENATE(#REF!,-L40) -> #REF!
...

Sheet Cálculo Informe
A1: RESIDUAL
B3: Insignificante | C3: Menor | D3: Moderado | E3: Mayor | F3: Catastrófico
A4: Muy Alta | B4: =+COUNTIF('SARO-02'!#REF!,'Cálculo Informe'!$A4&"-"&'Cálculo Informe'!B3) -> #REF! | C4: =+COUNTIF('SARO-02'!#REF!,'Cálculo Informe'!$A4&"-"&'Cálculo Informe'!C3) -> #REF! | D4: =+COUNTIF('SARO-02'!#REF!,'Cálculo Informe'!$A4&"-"&'Cálculo Informe'!D3) -> #REF! | E4: =+COUNTIF('SARO-02'!#REF!,'Cálculo Informe'!$A4&"-"&'Cálculo Informe'!E3) -> #REF! | F4: =+COUNTIF('SARO-02'!#REF!,'Cálculo Informe'!$A4&"-"&'Cálculo Informe'!F3) -> #REF! | G4: =SUM(B4:F4) -> #REF!
A5: Alta | B5: =+COUNTIF('SARO-02'!#REF!,'Cálculo Informe'!$A5&"-"&'Cálculo Informe'!B3) -> #REF! | C5: =+COUNTIF('SARO-02'!#REF!,'Cálculo Informe'!$A5&"-"&'Cálculo Informe'!C3) -> #REF! | D5: =+COUNTIF('SARO-02'!#REF!,'Cálculo Informe'!$A5&"-"&'Cálculo Informe'!D3) -> #REF! | E5: =+COUNTIF('SARO-02'!#REF!,'Cálculo Informe'!$A5&"-"&'Cálculo Informe'!E3) -> #REF! | F5: =+COUNTIF('SARO-02'!#REF!,'Cálculo Informe'!$A5&"-"&'Cálculo Informe'!F3) -> #REF! | G5: =SUM(B5:F5) -> #REF!
A6: Media | B6: =+COUNTIF('SARO-02'!#REF!,'Cálculo Informe'!$A6&"-"&'Cálculo Informe'!B3) -> #REF! | C6: =+COUNTIF('SARO-02'!#REF!,'Cálculo Informe'!$A6&"-"&'Cálculo Informe'!C3) -> #REF! | D6: =+COUNTIF('SARO-02'!#REF!,'Cálculo Informe'!$A6&"-"&'Cálculo Informe'!D3) -> #REF! | E6: =+COUNTIF('SARO-02'!#REF!,'Cálculo Informe'!$A6&"-"&'Cálculo Informe'!E3) -> #REF! | F6: =+COUNTIF('SARO-02'!#REF!,'Cálculo Informe'!$A6&"-"&'Cálculo Informe'!F3) -> #REF! | G6: =SUM(B6:F6) -> #REF!
A7: Baja | B7: =+COUNTIF('SARO-02'!#REF!,'Cálculo Informe'!$A7&"-"&'Cálculo Informe'!B3) -> #REF! | C7: =+COUNTIF('SARO-02'!#REF!,'Cálculo Informe'!$A7&"-"&'Cálculo Informe'!C3) -> #REF! | D7: =+COUNTIF('SARO-02'!#REF!,'Cálculo Informe'!$A7&"-"&'Cálculo Informe'!D3) -> #REF! | E7: =+COUNTIF('SARO-02'!#REF!,'Cálculo Informe'!$A7&"-"&'Cálculo Informe'!E3) -> #REF! | F7: =+COUNTIF('SARO-02'!#REF!,'Cálculo Informe'!$A7&"-"&'Cálculo Informe'!F3) -> #REF! | G7: =SUM(B7:F7) -> #REF!
A8: Muy Baja | B8: =+COUNTIF('SARO-02'!#REF!,'Cálculo Informe'!$A8&"-"&'Cálculo Informe'!B3) -> #REF! | C8: =+COUNTIF('SARO-02'!#REF!,'Cálculo Informe'!$A8&"-"&'Cálculo Informe'!C3) -> #REF! | D8: =+COUNTIF('SARO-02'!#REF!,'Cálculo Informe'!$A8&"-"&'Cálculo Informe'!D3) -> #REF! | E8: =+COUNTIF('SARO-02'!#REF!,'Cálculo Informe'!$A8&"-"&'Cálculo Informe'!E3) -> #REF! | F8: =+COUNTIF('SARO-02'!#REF!,'Cálculo Informe'!$A8&"-"&'Cálculo Informe'!F3) -> #REF! | G8: =SUM(B8:F8) -> #REF!
G9: =SUM(G4:G8) -> #REF!
B12: Insignificante | C12: Menor | D12: Moderado | E12: Mayor | F12: Catastrófico
A13: Muy Alta | B13: =+SUMIF('SARO-02'!#REF!,'Cálculo Informe'!$A$13&"-"&'Cálculo Informe'!B$3,'SARO-02'!$BC:$BC) -> #REF! | C13: =+SUMIF('SARO-02'!#REF!,'Cálculo Informe'!$A$13&"-"&'Cálculo Informe'!C$3,'SARO-02'!$BC:$BC) -> #REF! | D13: =+SUMIF('SARO-02'!#REF!,'Cálculo Informe'!$A$13&"-"&'Cálculo Informe'!D$3,'SARO-02'!$BC:$BC) -> #REF! | E13: =+SUMIF('SARO-02'!#REF!,'Cálculo Informe'!$A$13&"-"&'Cálculo Informe'!E$3,'SARO-02'!$BC:$BC) -> #REF! | F13: =+SUMIF('SARO-02'!#REF!,'Cálculo Informe'!$A$13&"-"&'Cálculo Informe'!F$3,'SARO-02'!$BC:$BC) -> #REF! | G13: =SUM(B13:F13) -> #REF!
A14: Alta | B14: =+SUMIF('SARO-02'!#REF!,'Cálculo Informe'!$A$14&"-"&'Cálculo Informe'!B$3,'SARO-02'!$BC:$BC) -> #REF! | C14: =+SUMIF('SARO-02'!#REF!,'Cálculo Informe'!$A$14&"-"&'Cálculo Informe'!C$3,'SARO-02'!$BC:$BC) -> #REF! | D14: =+SUMIF('SARO-02'!#REF!,'Cálculo Informe'!$A$14&"-"&'Cálculo Informe'!D$3,'SARO-02'!$BC:$BC) -> #REF! | E14: =+SUMIF('SARO-02'!#REF!,'Cálculo Informe'!$A$14&"-"&'Cálculo Informe'!E$3,'SARO-02'!$BC:$BC) -> #REF! | F14: =+SUMIF('SARO-02'!#REF!,'Cálculo Informe'!$A$14&"-"&'Cálculo Informe'!F$3,'SARO-02'!$BC:$BC) -> #REF! | G14: =SUM(B14:F14) -> #REF!
